<?xml version="1.0" ?>
<!--******************************************************************
 ****** File automatically generated by generate_urdf.py script ******
 *********************************************************************-->
<robot xmlns:xacro="http://www.ros.org/wiki/xacro">
	<joint name="HipRoll" type="revolute">
		<parent link="torso"/>
		<child link="Hip"/>
		<origin rpy="0 0 0" xyz="2e-05 0 -0.139"/>
		<axis xyz="1.0 0 0"/>
		<limit effort="10.1884" lower="-0.514872" upper="0.514872" velocity="2.27032"/>
	</joint>
	<link name="Hip">
		<inertial>
			<mass value="1.02338"/>
			<inertia ixx="0.00502422" ixy="0" ixz="-2.54911e-05" iyy="0.00640971" iyz="0.000159449" izz="0.00441082"/>
			<origin rpy="0 0 0" xyz="0.00032 0 -0.06039"/>
		</inertial>
		<xacro:insert_visu_Hip/>
	</link>
	<joint name="HipPitch" type="revolute">
		<parent link="Hip"/>
		<child link="Pelvis"/>
		<origin rpy="0 0 0" xyz="0 0 -0.079"/>
		<axis xyz="0 1.0 0"/>
		<limit effort="19.787" lower="-1.03847" upper="1.03847" velocity="2.93276"/>
	</joint>
	<link name="Pelvis">
		<inertial>
			<mass value="2.45917"/>
			<inertia ixx="0.034351" ixy="0" ixz="0.000223034" iyy="0.0303122" iyz="-8.37542e-05" izz="0.0143771"/>
			<origin rpy="0 0 0" xyz="0.00237 0 -0.09654"/>
		</inertial>
		<xacro:insert_visu_Pelvis/>
	</link>
	<joint name="KneePitch" type="revolute">
		<parent link="Pelvis"/>
		<child link="Tibia"/>
		<origin rpy="0 0 0" xyz="0 0 -0.268"/>
		<axis xyz="0 1.0 0"/>
		<limit effort="27.702" lower="-0.514872" upper="0.514872" velocity="2.93276"/>
	</joint>
	<link name="Tibia">
		<inertial>
			<mass value="11.6015"/>
			<inertia ixx="0.129229" ixy="-0.000401943" ixz="0.00048556" iyy="0.122839" iyz="-1.01666e-08" izz="0.108168"/>
			<origin rpy="0 0 0" xyz="0.00220451 0 -0.185729"/>
		</inertial>
		<xacro:insert_visu_Tibia/>
	</link>
	<joint name="base_footprint_joint" type="fixed">
		<parent link="Tibia"/>
		<child link="base_footprint"/>
		<origin rpy="0 0 0" xyz="0 0 -0.334"/>
	</joint>
	<link name="base_footprint"/>
</robot>
