<?xml version="1.0" ?>
<!--******************************************************************
 ****** File automatically generated by generate_urdf.py script ******
 *********************************************************************-->
<robot name="JulietteY20MP" xmlns:xacro="http://www.ros.org/wiki/xacro">
	<link name="RFinger41_link">
		<inertial>
			<mass value="2e-06"/>
			<inertia ixx="1.1e-09" ixy="0" ixz="0" iyy="1.1e-09" iyz="0" izz="1.1e-09"/>
		</inertial>
		<xacro:insert_visu_RFinger41_link/>
	</link>
	<joint name="RFinger41" type="continuous">
		<parent link="r_wrist"/>
		<child link="RFinger41_link"/>
		<origin rpy="1.74402 1.04064 -0.0683394" xyz="0.074 -0.0309 0"/>
		<axis xyz="0 0 1.0"/>
		<mimic joint="RHand" multiplier="0.872665" offset="0"/>
	</joint>
	<link name="LFinger42_link">
		<inertial>
			<mass value="2e-06"/>
			<inertia ixx="1.1e-09" ixy="0" ixz="0" iyy="1.1e-09" iyz="0" izz="1.1e-09"/>
		</inertial>
		<xacro:insert_visu_LFinger42_link/>
	</link>
	<joint name="LFinger42" type="continuous">
		<parent link="LFinger41_link"/>
		<child link="LFinger42_link"/>
		<origin rpy="0 0 -1.0472" xyz="0.018 0 0"/>
		<axis xyz="0 0 1.0"/>
		<mimic joint="LHand" multiplier="0.872665" offset="0"/>
	</joint>
	<link name="RFinger12_link">
		<inertial>
			<mass value="2e-06"/>
			<inertia ixx="1.1e-09" ixy="0" ixz="0" iyy="1.1e-09" iyz="0" izz="1.1e-09"/>
		</inertial>
		<xacro:insert_visu_RFinger12_link/>
	</link>
	<joint name="RFinger12" type="continuous">
		<parent link="RFinger11_link"/>
		<child link="RFinger12_link"/>
		<origin rpy="0 0 -1.0472" xyz="0.018 0 0"/>
		<axis xyz="0 0 1.0"/>
		<mimic joint="RHand" multiplier="0.872665" offset="0"/>
	</joint>
	<link name="LFinger33_link">
		<inertial>
			<mass value="2e-06"/>
			<inertia ixx="1.1e-09" ixy="0" ixz="0" iyy="1.1e-09" iyz="0" izz="1.1e-09"/>
		</inertial>
		<xacro:insert_visu_LFinger33_link/>
	</link>
	<joint name="LFinger33" type="continuous">
		<parent link="LFinger32_link"/>
		<child link="LFinger33_link"/>
		<origin rpy="0 0 -1.0472" xyz="0.018 0 0"/>
		<axis xyz="0 0 1.0"/>
		<mimic joint="LHand" multiplier="0.872665" offset="0"/>
	</joint>
	<link name="RFinger31_link">
		<inertial>
			<mass value="2e-06"/>
			<inertia ixx="1.1e-09" ixy="0" ixz="0" iyy="1.1e-09" iyz="0" izz="1.1e-09"/>
		</inertial>
		<xacro:insert_visu_RFinger31_link/>
	</link>
	<joint name="RFinger31" type="continuous">
		<parent link="r_wrist"/>
		<child link="RFinger31_link"/>
		<origin rpy="1.67523 1.04483 0.029316" xyz="0.0833 -0.0123 0.004"/>
		<axis xyz="0 0 1.0"/>
		<mimic joint="RHand" multiplier="0.872665" offset="0"/>
	</joint>
	<link name="LFinger21_link">
		<inertial>
			<mass value="2e-06"/>
			<inertia ixx="1.1e-09" ixy="0" ixz="0" iyy="1.1e-09" iyz="0" izz="1.1e-09"/>
		</inertial>
		<xacro:insert_visu_LFinger21_link/>
	</link>
	<joint name="LFinger21" type="continuous">
		<parent link="l_wrist"/>
		<child link="LFinger21_link"/>
		<origin rpy="1.5708 1.0472 -0.061086" xyz="0.0873 -0.0073 0.006"/>
		<axis xyz="0 0 1.0"/>
		<mimic joint="LHand" multiplier="0.872665" offset="0"/>
	</joint>
	<link name="RFinger32_link">
		<inertial>
			<mass value="2e-06"/>
			<inertia ixx="1.1e-09" ixy="0" ixz="0" iyy="1.1e-09" iyz="0" izz="1.1e-09"/>
		</inertial>
		<xacro:insert_visu_RFinger32_link/>
	</link>
	<joint name="RFinger32" type="continuous">
		<parent link="RFinger31_link"/>
		<child link="RFinger32_link"/>
		<origin rpy="0 0 -1.0472" xyz="0.018 0 0"/>
		<axis xyz="0 0 1.0"/>
		<mimic joint="RHand" multiplier="0.872665" offset="0"/>
	</joint>
	<link name="LFinger13_link">
		<inertial>
			<mass value="2e-06"/>
			<inertia ixx="1.1e-09" ixy="0" ixz="0" iyy="1.1e-09" iyz="0" izz="1.1e-09"/>
		</inertial>
		<xacro:insert_visu_LFinger13_link/>
	</link>
	<joint name="LFinger13" type="continuous">
		<parent link="LFinger12_link"/>
		<child link="LFinger13_link"/>
		<origin rpy="0 0 -1.0472" xyz="0.018 0 0"/>
		<axis xyz="0 0 1.0"/>
		<mimic joint="LHand" multiplier="0.872665" offset="0"/>
	</joint>
	<link name="LFinger32_link">
		<inertial>
			<mass value="2e-06"/>
			<inertia ixx="1.1e-09" ixy="0" ixz="0" iyy="1.1e-09" iyz="0" izz="1.1e-09"/>
		</inertial>
		<xacro:insert_visu_LFinger32_link/>
	</link>
	<joint name="LFinger32" type="continuous">
		<parent link="LFinger31_link"/>
		<child link="LFinger32_link"/>
		<origin rpy="0 0 -1.0472" xyz="0.018 0 0"/>
		<axis xyz="0 0 1.0"/>
		<mimic joint="LHand" multiplier="0.872665" offset="0"/>
	</joint>
	<link name="LFinger11_link">
		<inertial>
			<mass value="2e-06"/>
			<inertia ixx="1.1e-09" ixy="0" ixz="0" iyy="1.1e-09" iyz="0" izz="1.1e-09"/>
		</inertial>
		<xacro:insert_visu_LFinger11_link/>
	</link>
	<joint name="LFinger11" type="continuous">
		<parent link="l_wrist"/>
		<child link="LFinger11_link"/>
		<origin rpy="1.74402 1.04064 -0.0334335" xyz="0.0821 -0.0268 0.004"/>
		<axis xyz="0 0 1.0"/>
		<mimic joint="LHand" multiplier="0.872665" offset="0"/>
	</joint>
	<link name="RFinger22_link">
		<inertial>
			<mass value="2e-06"/>
			<inertia ixx="1.1e-09" ixy="0" ixz="0" iyy="1.1e-09" iyz="0" izz="1.1e-09"/>
		</inertial>
		<xacro:insert_visu_RFinger22_link/>
	</link>
	<joint name="RFinger22" type="continuous">
		<parent link="RFinger21_link"/>
		<child link="RFinger22_link"/>
		<origin rpy="0 0 -1.0472" xyz="0.018 0 0"/>
		<axis xyz="0 0 1.0"/>
		<mimic joint="RHand" multiplier="0.872665" offset="0"/>
	</joint>
	<link name="RFinger13_link">
		<inertial>
			<mass value="2e-06"/>
			<inertia ixx="1.1e-09" ixy="0" ixz="0" iyy="1.1e-09" iyz="0" izz="1.1e-09"/>
		</inertial>
		<xacro:insert_visu_RFinger13_link/>
	</link>
	<joint name="RFinger13" type="continuous">
		<parent link="RFinger12_link"/>
		<child link="RFinger13_link"/>
		<origin rpy="0 0 -1.0472" xyz="0.018 0 0"/>
		<axis xyz="0 0 1.0"/>
		<mimic joint="RHand" multiplier="0.872665" offset="0"/>
	</joint>
	<link name="LFinger22_link">
		<inertial>
			<mass value="2e-06"/>
			<inertia ixx="1.1e-09" ixy="0" ixz="0" iyy="1.1e-09" iyz="0" izz="1.1e-09"/>
		</inertial>
		<xacro:insert_visu_LFinger22_link/>
	</link>
	<joint name="LFinger22" type="continuous">
		<parent link="LFinger21_link"/>
		<child link="LFinger22_link"/>
		<origin rpy="0 0 -1.0472" xyz="0.018 0 0"/>
		<axis xyz="0 0 1.0"/>
		<mimic joint="LHand" multiplier="0.872665" offset="0"/>
	</joint>
	<link name="RFinger21_link">
		<inertial>
			<mass value="2e-06"/>
			<inertia ixx="1.1e-09" ixy="0" ixz="0" iyy="1.1e-09" iyz="0" izz="1.1e-09"/>
		</inertial>
		<xacro:insert_visu_RFinger21_link/>
	</link>
	<joint name="RFinger21" type="continuous">
		<parent link="r_wrist"/>
		<child link="RFinger21_link"/>
		<origin rpy="1.5708 1.0472 0.061086" xyz="0.0873 0.0073 0.006"/>
		<axis xyz="0 0 1.0"/>
		<mimic joint="RHand" multiplier="0.872665" offset="0"/>
	</joint>
	<link name="LFinger41_link">
		<inertial>
			<mass value="2e-06"/>
			<inertia ixx="1.1e-09" ixy="0" ixz="0" iyy="1.1e-09" iyz="0" izz="1.1e-09"/>
		</inertial>
		<xacro:insert_visu_LFinger41_link/>
	</link>
	<joint name="LFinger41" type="continuous">
		<parent link="l_wrist"/>
		<child link="LFinger41_link"/>
		<origin rpy="1.39757 1.04064 0.0683394" xyz="0.074 0.0309 0"/>
		<axis xyz="0 0 1.0"/>
		<mimic joint="LHand" multiplier="0.872665" offset="0"/>
	</joint>
	<link name="LFinger12_link">
		<inertial>
			<mass value="2e-06"/>
			<inertia ixx="1.1e-09" ixy="0" ixz="0" iyy="1.1e-09" iyz="0" izz="1.1e-09"/>
		</inertial>
		<xacro:insert_visu_LFinger12_link/>
	</link>
	<joint name="LFinger12" type="continuous">
		<parent link="LFinger11_link"/>
		<child link="LFinger12_link"/>
		<origin rpy="0 0 -1.0472" xyz="0.018 0 0"/>
		<axis xyz="0 0 1.0"/>
		<mimic joint="LHand" multiplier="0.872665" offset="0"/>
	</joint>
	<link name="RFinger23_link">
		<inertial>
			<mass value="2e-06"/>
			<inertia ixx="1.1e-09" ixy="0" ixz="0" iyy="1.1e-09" iyz="0" izz="1.1e-09"/>
		</inertial>
		<xacro:insert_visu_RFinger23_link/>
	</link>
	<joint name="RFinger23" type="continuous">
		<parent link="RFinger22_link"/>
		<child link="RFinger23_link"/>
		<origin rpy="0 0 -1.0472" xyz="0.018 0 0"/>
		<axis xyz="0 0 1.0"/>
		<mimic joint="RHand" multiplier="0.872665" offset="0"/>
	</joint>
	<link name="RFinger11_link">
		<inertial>
			<mass value="2e-06"/>
			<inertia ixx="1.1e-09" ixy="0" ixz="0" iyy="1.1e-09" iyz="0" izz="1.1e-09"/>
		</inertial>
		<xacro:insert_visu_RFinger11_link/>
	</link>
	<joint name="RFinger11" type="continuous">
		<parent link="r_wrist"/>
		<child link="RFinger11_link"/>
		<origin rpy="1.39757 1.04064 0.0334335" xyz="0.0821 0.0268 0.004"/>
		<axis xyz="0 0 1.0"/>
		<mimic joint="RHand" multiplier="0.872665" offset="0"/>
	</joint>
	<link name="LFinger23_link">
		<inertial>
			<mass value="2e-06"/>
			<inertia ixx="1.1e-09" ixy="0" ixz="0" iyy="1.1e-09" iyz="0" izz="1.1e-09"/>
		</inertial>
		<xacro:insert_visu_LFinger23_link/>
	</link>
	<joint name="LFinger23" type="continuous">
		<parent link="LFinger22_link"/>
		<child link="LFinger23_link"/>
		<origin rpy="0 0 -1.0472" xyz="0.018 0 0"/>
		<axis xyz="0 0 1.0"/>
		<mimic joint="LHand" multiplier="0.872665" offset="0"/>
	</joint>
	<link name="LFinger43_link">
		<inertial>
			<mass value="2e-06"/>
			<inertia ixx="1.1e-09" ixy="0" ixz="0" iyy="1.1e-09" iyz="0" izz="1.1e-09"/>
		</inertial>
		<xacro:insert_visu_LFinger43_link/>
	</link>
	<joint name="LFinger43" type="continuous">
		<parent link="LFinger42_link"/>
		<child link="LFinger43_link"/>
		<origin rpy="0 0 -1.0472" xyz="0.018 0 0"/>
		<axis xyz="0 0 1.0"/>
		<mimic joint="LHand" multiplier="0.872665" offset="0"/>
	</joint>
	<link name="RFinger43_link">
		<inertial>
			<mass value="2e-06"/>
			<inertia ixx="1.1e-09" ixy="0" ixz="0" iyy="1.1e-09" iyz="0" izz="1.1e-09"/>
		</inertial>
		<xacro:insert_visu_RFinger43_link/>
	</link>
	<joint name="RFinger43" type="continuous">
		<parent link="RFinger42_link"/>
		<child link="RFinger43_link"/>
		<origin rpy="0 0 -1.0472" xyz="0.018 0 0"/>
		<axis xyz="0 0 1.0"/>
		<mimic joint="RHand" multiplier="0.872665" offset="0"/>
	</joint>
	<link name="RFinger42_link">
		<inertial>
			<mass value="2e-06"/>
			<inertia ixx="1.1e-09" ixy="0" ixz="0" iyy="1.1e-09" iyz="0" izz="1.1e-09"/>
		</inertial>
		<xacro:insert_visu_RFinger42_link/>
	</link>
	<joint name="RFinger42" type="continuous">
		<parent link="RFinger41_link"/>
		<child link="RFinger42_link"/>
		<origin rpy="0 0 -1.0472" xyz="0.018 0 0"/>
		<axis xyz="0 0 1.0"/>
		<mimic joint="RHand" multiplier="0.872665" offset="0"/>
	</joint>
	<link name="LFinger31_link">
		<inertial>
			<mass value="2e-06"/>
			<inertia ixx="1.1e-09" ixy="0" ixz="0" iyy="1.1e-09" iyz="0" izz="1.1e-09"/>
		</inertial>
		<xacro:insert_visu_LFinger31_link/>
	</link>
	<joint name="LFinger31" type="continuous">
		<parent link="l_wrist"/>
		<child link="LFinger31_link"/>
		<origin rpy="1.46636 1.04483 -0.029314" xyz="0.0833 0.0123 0.004"/>
		<axis xyz="0 0 1.0"/>
		<mimic joint="LHand" multiplier="0.872665" offset="0"/>
	</joint>
	<link name="RFinger33_link">
		<inertial>
			<mass value="2e-06"/>
			<inertia ixx="1.1e-09" ixy="0" ixz="0" iyy="1.1e-09" iyz="0" izz="1.1e-09"/>
		</inertial>
		<xacro:insert_visu_RFinger33_link/>
	</link>
	<joint name="RFinger33" type="continuous">
		<parent link="RFinger32_link"/>
		<child link="RFinger33_link"/>
		<origin rpy="0 0 -1.0472" xyz="0.018 0 0"/>
		<axis xyz="0 0 1.0"/>
		<mimic joint="RHand" multiplier="0.872665" offset="0"/>
	</joint>
	<link name="LThumb1_link">
		<inertial>
			<mass value="2e-06"/>
			<inertia ixx="1.1e-09" ixy="0" ixz="0" iyy="1.1e-09" iyz="0" izz="1.1e-09"/>
		</inertial>
		<xacro:insert_visu_LThumb1_link/>
	</link>
	<joint name="LThumb1" type="continuous">
		<parent link="l_wrist"/>
		<child link="LThumb1_link"/>
		<origin rpy="-1.95836 0.60626 0.533978" xyz="0.0482 -0.0357 -0.0199"/>
		<axis xyz="0 0 1.0"/>
		<mimic joint="LHand" multiplier="0.872665" offset="0"/>
	</joint>
	<link name="RThumb2_link">
		<inertial>
			<mass value="2e-06"/>
			<inertia ixx="1.1e-09" ixy="0" ixz="0" iyy="1.1e-09" iyz="0" izz="1.1e-09"/>
		</inertial>
		<xacro:insert_visu_RThumb2_link/>
	</link>
	<joint name="RThumb2" type="continuous">
		<parent link="RThumb1_link"/>
		<child link="RThumb2_link"/>
		<origin rpy="0 0 -1.0472" xyz="0.022 0 0"/>
		<axis xyz="0 0 1.0"/>
		<mimic joint="RHand" multiplier="0.872665" offset="0"/>
	</joint>
	<link name="RThumb1_link">
		<inertial>
			<mass value="2e-06"/>
			<inertia ixx="1.1e-09" ixy="0" ixz="0" iyy="1.1e-09" iyz="0" izz="1.1e-09"/>
		</inertial>
		<xacro:insert_visu_RThumb1_link/>
	</link>
	<joint name="RThumb1" type="continuous">
		<parent link="r_wrist"/>
		<child link="RThumb1_link"/>
		<origin rpy="-1.18323 0.60626 -0.533978" xyz="0.0482 0.0357 -0.0199"/>
		<axis xyz="0 0 1.0"/>
		<mimic joint="RHand" multiplier="0.872665" offset="0"/>
	</joint>
	<link name="LThumb2_link">
		<inertial>
			<mass value="2e-06"/>
			<inertia ixx="1.1e-09" ixy="0" ixz="0" iyy="1.1e-09" iyz="0" izz="1.1e-09"/>
		</inertial>
		<xacro:insert_visu_LThumb2_link/>
	</link>
	<joint name="LThumb2" type="continuous">
		<parent link="LThumb1_link"/>
		<child link="LThumb2_link"/>
		<origin rpy="0 0 -1.0472" xyz="0.022 0 0"/>
		<axis xyz="0 0 1.0"/>
		<mimic joint="LHand" multiplier="0.872665" offset="0"/>
	</joint>
</robot>
