<?xml version="1.0" ?>
<!--******************************************************************
 ****** File automatically generated by generate_urdf.py script ******
 *********************************************************************-->
<robot name="JulietteY20MP" xmlns:xacro="http://www.ros.org/wiki/xacro">
	<link name="WheelFL_link">
		<inertial>
			<mass value="1.58028"/>
			<inertia ixx="0.00299756" ixy="6.3068e-07" ixz="5.56903e-06" iyy="0.00303229" iyz="-9.0408e-07" izz="0.00296585"/>
			<origin rpy="0 0 0" xyz="0 0 0"/>
		</inertial>
		<xacro:insert_visu_WheelFL_link/>
	</link>
	<joint name="WheelFL" type="continuous">
		<parent link="Tibia"/>
		<child link="WheelFL_link"/>
		<origin rpy="0 0 1.07517" xyz="0.09 0.155 -0.264"/>
		<axis xyz="1.0 0 0"/>
		<limit effort="3.25" lower="0" upper="0" velocity="6.28319"/>
	</joint>
	<link name="WheelB_link">
		<inertial>
			<mass value="1.58028"/>
			<inertia ixx="0.00299756" ixy="6.3068e-07" ixz="5.56903e-06" iyy="0.00303229" iyz="-9.0408e-07" izz="0.00296585"/>
			<origin rpy="0 0 0" xyz="0 0 0"/>
		</inertial>
		<xacro:insert_visu_WheelB_link/>
	</link>
	<joint name="WheelB" type="continuous">
		<parent link="Tibia"/>
		<child link="WheelB_link"/>
		<origin rpy="0 0 -3.14159" xyz="-0.17 0 -0.264"/>
		<axis xyz="1.0 0 0"/>
		<limit effort="3.25" lower="0" upper="0" velocity="6.28319"/>
	</joint>
	<link name="WheelFR_link">
		<inertial>
			<mass value="1.58028"/>
			<inertia ixx="0.00299756" ixy="6.3068e-07" ixz="5.56903e-06" iyy="0.00303229" iyz="-9.0408e-07" izz="0.00296585"/>
			<origin rpy="0 0 0" xyz="0 0 0"/>
		</inertial>
		<xacro:insert_visu_WheelFR_link/>
	</link>
	<joint name="WheelFR" type="continuous">
		<parent link="Tibia"/>
		<child link="WheelFR_link"/>
		<origin rpy="0 0 -1.07517" xyz="0.09 -0.155 -0.264"/>
		<axis xyz="1.0 0 0"/>
		<limit effort="3.25" lower="0" upper="0" velocity="6.28319"/>
	</joint>
</robot>
