<?xml version="1.0" ?>
<!--******************************************************************
 ****** File automatically generated by generate_urdf.py script ******
 *********************************************************************-->
<robot xmlns:xacro="http://www.ros.org/wiki/xacro">
	<joint name="HeadYaw" type="revolute">
		<parent link="torso"/>
		<child link="Neck"/>
		<origin rpy="0 0 0" xyz="-0.038 0 0.1699"/>
		<axis xyz="0 0 1.0"/>
		<limit effort="5.428" lower="-2.08567" upper="2.08567" velocity="7.33998"/>
	</joint>
	<link name="Neck">
		<inertial>
			<mass value="0.27391"/>
			<inertia ixx="0.000343501" ixy="0" ixz="-1.88563e-05" iyy="0.000493898" iyz="2.09863e-06" izz="0.000215252"/>
			<origin rpy="0 0 0" xyz="-0.00207 0 -0.02636"/>
		</inertial>
		<xacro:insert_visu_Neck/>
	</link>
	<joint name="HeadPitch" type="revolute">
		<parent link="Neck"/>
		<child link="Head"/>
		<origin rpy="0 0 0" xyz="0 0 0"/>
		<axis xyz="0 1.0 0"/>
		<limit effort="2.666" lower="-0.706858" upper="0.637045" velocity="9.22756"/>
	</joint>
	<link name="Head">
		<inertial>
			<mass value="1.51893"/>
			<inertia ixx="0.00597209" ixy="0" ixz="0.000125138" iyy="0.0059054" iyz="4.3428e-07" izz="0.00570374"/>
			<origin rpy="0 0 0" xyz="0.00312 0 0.11152"/>
		</inertial>
		<xacro:insert_visu_Head/>
	</link>
</robot>
