<?xml version="1.0" ?>
<!-- =================================================================================== -->
<!-- |    This document was autogenerated by xacro from romeo_robot.xacro              | -->
<!-- |    EDITING THIS FILE BY HAND IS NOT RECOMMENDED                                 | -->
<!-- =================================================================================== -->
<!--******************************************************************
 ****** File automatically generated by generate_urdf.py script ******
 *********************************************************************-->
<robot name="RomeoH37" xmlns:xacro="http://www.ros.org/wiki/xacro">
  <joint name="NeckYaw" type="revolute">
    <parent link="torso"/>
    <child link="NeckYaw_link"/>
    <origin rpy="0 -2.98023e-08 0" xyz="0.0548 0 0.1675"/>
    <axis xyz="0.173651 0 0.984807"/>
    <limit effort="27.72" lower="-2.0595" upper="2.0595" velocity="4.0"/>
  </joint>
  <link name="NeckYaw_link">
    <inertial>
      <mass value="0.377845"/>
      <inertia ixx="0.000279258" ixy="-3.10908e-07" ixz="-1.49231e-05" iyy="0.000260188" iyz="-8.07538e-07" izz="8.41479e-05"/>
      <origin rpy="0 0 0" xyz="-0.00635646 0 -0.030002"/>
    </inertial>
  </link>
  <joint name="NeckPitch" type="revolute">
    <parent link="NeckYaw_link"/>
    <child link="NeckPitch_link"/>
    <origin rpy="0 -2.98023e-08 0" xyz="0 0 0"/>
    <axis xyz="0 1.0 0"/>
    <limit effort="35.0" lower="-0.3142" upper="0.6632" velocity="2.2"/>
  </joint>
  <link name="NeckPitch_link">
    <inertial>
      <mass value="0.345282"/>
      <inertia ixx="0.000476367" ixy="-1.93678e-06" ixz="0.000128915" iyy="0.000443007" iyz="5.81865e-05" izz="0.000304636"/>
      <origin rpy="0 0 0" xyz="0.00372 0 0.04811"/>
    </inertial>
    <visual>
      <geometry>
        <mesh filename="meshes/NeckPitch.obj" scale="1 1 1"/>
      </geometry>
      <origin rpy="0 0 0" xyz="0 0 0"/>
    </visual>
    <collision>
      <geometry>
        <mesh filename="meshes/NeckPitch_0.10.stl" scale="1 1 1"/>
      </geometry>
      <origin rpy="0 0 0" xyz="0 0 0"/>
    </collision>
  </link>
  <joint name="HeadPitch" type="revolute">
    <parent link="NeckPitch_link"/>
    <child link="HeadPitch_link"/>
    <origin rpy="0 0 0" xyz="0 0 0.0951"/>
    <axis xyz="0 1.0 0"/>
    <limit effort="9.40" lower="-0.2571" upper="0.2971" velocity="1.9"/>
  </joint>
  <link name="HeadPitch_link">
    <inertial>
      <mass value="0.158407"/>
      <inertia ixx="2.57346e-05" ixy="1.51196e-07" ixz="-1.52238e-05" iyy="7.43865e-05" iyz="-4.91562e-09" izz="6.6769e-05"/>
      <origin rpy="0 0 0" xyz="0.0014 0 -0.00462"/>
    </inertial>
  </link>

  <!-- Head Roll and additional texture links -->
  <joint name="HeadRoll" type="revolute">
    <parent link="HeadPitch_link"/>
    <child link="HeadRoll_link"/>
    <origin rpy="0 0 0" xyz="0 0 0"/>
    <axis xyz="1.0 0 0"/>
    <limit effort="14.46" lower="-0.4887" upper="0.4887" velocity="1.5"/>
  </joint>
  <link name="HeadRoll_link">
    <inertial>
      <mass value="2.07047"/>
      <inertia ixx="0.00933153" ixy="-3.87986e-05" ixz="0.002764" iyy="0.0110877" iyz="0.000300351" izz="0.00918888"/>
      <origin rpy="0 0 0" xyz="0.01263 0 0.07498"/>
    </inertial>
    <visual>
      <geometry>
        <mesh filename="meshes/HeadRoll_mainskin.obj" scale="1 1 1"/>
      </geometry>
      <origin rpy="0 0 0" xyz="0 0 0"/>
    </visual>
    <collision>
      <geometry>
        <mesh filename="meshes/HeadRoll_0.10.stl" scale="1 1 1"/>
      </geometry>
      <origin rpy="0 0 0" xyz="0 0 0"/>
    </collision>
  </link>
  <joint name="HeadRoll_logo_joint" type="fixed">
    <parent link="HeadRoll_link"/>
    <child link="HeadRoll_logo"/>
    <origin rpy="0 0 0" xyz="0 0 0"/>
  </joint>
  <link name="HeadRoll_logo">
    <inertial>
      <mass value="0"/>
      <inertia ixx="0" ixy="0" ixz="0" iyy="0" iyz="0" izz="0"/>
      <origin rpy="0 0 0" xyz="0 0 0"/>
    </inertial>
    <visual>
      <geometry>
        <mesh filename="meshes/HeadRoll_logo.obj" scale="1 1 1"/>
      </geometry>
      <origin rpy="0 0 0" xyz="0 0 0"/>
    </visual>
  </link>
  <joint name="HeadRoll_shell_joint" type="fixed">
    <parent link="HeadRoll_link"/>
    <child link="HeadRoll_shell"/>
    <origin rpy="0 0 0" xyz="0 0 0"/>
  </joint>
  <link name="HeadRoll_shell">
    <inertial>
      <mass value="0"/>
      <inertia ixx="0" ixy="0" ixz="0" iyy="0" iyz="0" izz="0"/>
      <origin rpy="0 0 0" xyz="0 0 0"/>
    </inertial>
    <visual>
      <geometry>
        <mesh filename="meshes/HeadRoll_shell.obj" scale="1 1 1"/>
      </geometry>
      <origin rpy="0 0 0" xyz="0 0 0"/>
    </visual>
  </link>

  <joint name="gaze_joint" type="fixed">
    <parent link="HeadRoll_link"/>
    <child link="gaze"/>
    <origin rpy="0 0 0" xyz="0.10247 0 0.05425"/>
  </joint>
  <link name="gaze">
    <inertial>
      <mass value="0"/>
      <inertia ixx="0" ixy="0" ixz="0" iyy="0" iyz="0" izz="0"/>
      <origin rpy="0 0 0" xyz="0 0 0"/>
    </inertial>
  </link>
  <joint name="LHipYaw" type="revolute">
    <parent link="body"/>
    <child link="LHipYaw_link"/>
    <origin rpy="0 0 0" xyz="0.05 0.096 -0.3375"/>
    <axis xyz="0 0 1.0"/>
    <limit effort="103.03" lower="-0.2618" upper="0.2618" velocity="1.045"/>
  </joint>
  <link name="LHipYaw_link">
    <inertial>
      <mass value="0.559188"/>
      <inertia ixx="0.000865336" ixy="-1.1052e-06" ixz="-0.000251445" iyy="0.00143007" iyz="4.25093e-06" izz="0.000851928"/>
      <origin rpy="0 0 0" xyz="-0.00922 -0.00167 0.042"/>
    </inertial>
  </link>
  <joint name="LHipRoll" type="revolute">
    <parent link="LHipYaw_link"/>
    <child link="LHip"/>
    <origin rpy="0 0 0" xyz="0 0 0"/>
    <axis xyz="1.0 0 0"/>
    <limit effort="213.15" lower="-0.2618" upper="0.5236" velocity="2.09"/>
  </joint>
  <link name="LHip">
    <inertial>
      <mass value="0.714778"/>
      <inertia ixx="0.000937272" ixy="-6.73228e-06" ixz="-2.02714e-06" iyy="0.000548117" iyz="1.34974e-06" izz="0.00101855"/>
      <origin rpy="0 0 0" xyz="0.00249 -0.00205 -0.00147"/>
    </inertial>
  </link>

  <!-- LHipPitch joints and links -->
  <joint name="LHipPitch" type="revolute">
    <parent link="LHip"/>
    <child link="LThigh"/>
    <origin rpy="0 0 0" xyz="0 0 0"/>
    <axis xyz="0 1.0 0"/>
    <limit effort="213.15" lower="-1.6581" upper="0.4014" velocity="2.09"/>
  </joint>
  <link name="LThigh">
    <inertial>
      <mass value="4.71096"/>
      <inertia ixx="0.0390706" ixy="-2.41786e-05" ixz="0.0250104" iyy="0.0395116" iyz="0.000712271" izz="0.0122599"/>
      <origin rpy="0 0 0" xyz="-0.02138 -0.00255 -0.14577"/>
    </inertial>
    <visual>
      <geometry>
        <mesh filename="meshes/LHipPitch_mainskin.obj" scale="1 1 1"/>
      </geometry>
      <origin rpy="0 0 0" xyz="0 0 0"/>
    </visual>
    <collision>
      <geometry>
        <mesh filename="meshes/LHipPitch_0.10.stl" scale="1 1 1"/>
      </geometry>
      <origin rpy="0 0 0" xyz="0 0 0"/>
    </collision>
  </link>
  <joint name="LHipPitch_shell_joint" type="fixed">
    <parent link="LThigh"/>
    <child link="LHipPitch_shell"/>
    <origin rpy="0 0 0" xyz="0 0 0"/>
  </joint>
  <link name="LHipPitch_shell">
    <inertial>
      <mass value="0"/>
      <inertia ixx="0" ixy="0" ixz="0" iyy="0" iyz="0" izz="0"/>
      <origin rpy="0 0 0" xyz="0 0 0"/>
    </inertial>
    <visual>
      <geometry>
        <mesh filename="meshes/LHipPitch_shell.obj" scale="1 1 1"/>
      </geometry>
      <origin rpy="0 0 0" xyz="0 0 0"/>
    </visual>
  </link>
  <joint name="LHipPitch_flexibleskin_joint" type="fixed">
    <parent link="LThigh"/>
    <child link="LHipPitch_flexibleskin"/>
    <origin rpy="0 0 0" xyz="0 0 0"/>
  </joint>
  <link name="LHipPitch_flexibleskin">
    <inertial>
      <mass value="0"/>
      <inertia ixx="0" ixy="0" ixz="0" iyy="0" iyz="0" izz="0"/>
      <origin rpy="0 0 0" xyz="0 0 0"/>
    </inertial>
    <visual>
      <geometry>
        <mesh filename="meshes/LHipPitch_flexibleskin.obj" scale="1 1 1"/>
      </geometry>
      <origin rpy="0 0 0" xyz="0 0 0"/>
    </visual>
  </link>
  <joint name="LHipPitch_secondaryskin_joint" type="fixed">
    <parent link="LThigh"/>
    <child link="LHipPitch_secondaryskin"/>
    <origin rpy="0 0 0" xyz="0 0 0"/>
  </joint>
  <link name="LHipPitch_secondaryskin">
    <inertial>
      <mass value="0"/>
      <inertia ixx="0" ixy="0" ixz="0" iyy="0" iyz="0" izz="0"/>
      <origin rpy="0 0 0" xyz="0 0 0"/>
    </inertial>
    <visual>
      <geometry>
        <mesh filename="meshes/LHipPitch_secondaryskin.obj" scale="1 1 1"/>
      </geometry>
      <origin rpy="0 0 0" xyz="0 0 0"/>
    </visual>
  </link>

  <!-- LKneePitch joints and links -->
  <joint name="LKneePitch" type="revolute">
    <parent link="LThigh"/>
    <child link="LTibia"/>
    <origin rpy="0 0 0" xyz="0 0 -0.322"/>
    <axis xyz="0 1.0 0"/>
    <limit effort="292.50" lower="-0.0218" upper="1.9722" velocity="6.0"/>
  </joint>
  <link name="LTibia">
    <inertial>
      <mass value="2.72291"/>
      <inertia ixx="0.0159124" ixy="5.49385e-08" ixz="0.00301963" iyy="0.0158076" iyz="-6.1473e-06" izz="0.00369233"/>
      <origin rpy="0 0 0" xyz="-0.00415 -0.00054 -0.11011"/>
    </inertial>
    <visual>
      <geometry>
        <mesh filename="meshes/LKneePitch_mainskin.obj" scale="1 1 1"/>
      </geometry>
      <origin rpy="0 0 0" xyz="0 0 0"/>
    </visual>
    <collision>
      <geometry>
        <mesh filename="meshes/LKneePitch_0.10.stl" scale="1 1 1"/>
      </geometry>
      <origin rpy="0 0 0" xyz="0 0 0"/>
    </collision>
  </link>
  <joint name="LKneePitch_secondaryskin_joint" type="fixed">
    <parent link="LTibia"/>
    <child link="LKneePitch_secondaryskin"/>
    <origin rpy="0 0 0" xyz="0 0 0"/>
  </joint>
  <link name="LKneePitch_secondaryskin">
    <inertial>
      <mass value="0"/>
      <inertia ixx="0" ixy="0" ixz="0" iyy="0" iyz="0" izz="0"/>
      <origin rpy="0 0 0" xyz="0 0 0"/>
    </inertial>
    <visual>
      <geometry>
        <mesh filename="meshes/LKneePitch_secondaryskin.obj" scale="1 1 1"/>
      </geometry>
      <origin rpy="0 0 0" xyz="0 0 0"/>
    </visual>
  </link>
  <joint name="LKneePitch_shell_joint" type="fixed">
    <parent link="LTibia"/>
    <child link="LKneePitch_shell"/>
    <origin rpy="0 0 0" xyz="0 0 0"/>
  </joint>
  <link name="LKneePitch_shell">
    <inertial>
      <mass value="0"/>
      <inertia ixx="0" ixy="0" ixz="0" iyy="0" iyz="0" izz="0"/>
      <origin rpy="0 0 0" xyz="0 0 0"/>
    </inertial>
    <visual>
      <geometry>
        <mesh filename="meshes/LKneePitch_shell.obj" scale="1 1 1"/>
      </geometry>
      <origin rpy="0 0 0" xyz="0 0 0"/>
    </visual>
  </link>
  <joint name="LKneePitch_secondaryskin2_joint" type="fixed">
    <parent link="LTibia"/>
    <child link="LKneePitch_secondaryskin2"/>
    <origin rpy="0 0 0" xyz="0 0 0"/>
  </joint>
  <link name="LKneePitch_secondaryskin2">
    <inertial>
      <mass value="0"/>
      <inertia ixx="0" ixy="0" ixz="0" iyy="0" iyz="0" izz="0"/>
      <origin rpy="0 0 0" xyz="0 0 0"/>
    </inertial>
    <visual>
      <geometry>
        <mesh filename="meshes/LKneePitch_secondaryskin2.obj" scale="1 1 1"/>
      </geometry>
      <origin rpy="0 0 0" xyz="0 0 0"/>
    </visual>
  </link>
  <joint name="LKneePitch_secondaryskin3_joint" type="fixed">
    <parent link="LTibia"/>
    <child link="LKneePitch_secondaryskin3"/>
    <origin rpy="0 0 0" xyz="0 0 0"/>
  </joint>
  <link name="LKneePitch_secondaryskin3">
    <inertial>
      <mass value="0"/>
      <inertia ixx="0" ixy="0" ixz="0" iyy="0" iyz="0" izz="0"/>
      <origin rpy="0 0 0" xyz="0 0 0"/>
    </inertial>
    <visual>
      <geometry>
        <mesh filename="meshes/LKneePitch_secondaryskin3.obj" scale="1 1 1"/>
      </geometry>
      <origin rpy="0 0 0" xyz="0 0 0"/>
    </visual>
  </link>

  <joint name="LAnklePitch" type="revolute">
    <parent link="LTibia"/>
    <child link="LAnklePitch_link"/>
    <origin rpy="0 0 0" xyz="0 0 -0.29"/>
    <axis xyz="0 1.0 0"/>
    <limit effort="213.15" lower="-0.5149" upper="0.7505" velocity="2.1"/>
  </joint>
  <link name="LAnklePitch_link">
    <inertial>
      <mass value="0.464512"/>
      <inertia ixx="0.000367336" ixy="-1.174e-07" ixz="1.0441e-07" iyy="0.000239298" iyz="-1.23189e-06" izz="0.000425531"/>
      <origin rpy="0 0 0" xyz="0.00132 -0.00117 0.00015"/>
    </inertial>
  </link>

  <!-- LAnkleRoll joints and links -->
  <joint name="LAnkleRoll" type="revolute">
    <parent link="LAnklePitch_link"/>
    <child link="l_ankle"/>
    <origin rpy="0 0 0" xyz="0 0 0"/>
    <axis xyz="1.0 0 0"/>
    <limit effort="213.15" lower="-0.3491" upper="0.3491" velocity="2.1"/>
  </joint>
  <link name="l_ankle">
    <inertial>
      <mass value="1.06764"/>
      <inertia ixx="0.000978167" ixy="-4.97135e-05" ixz="-0.000879138" iyy="0.00586633" iyz="6.13291e-05" izz="0.00589599"/>
      <origin rpy="0 0 0" xyz="0.0483878 0.00120158 -0.0367645"/>
    </inertial>
    <visual>
      <geometry>
        <mesh filename="meshes/LAnkleRoll_mainskin.obj" scale="1 1 1"/>
      </geometry>
      <origin rpy="0 0 0" xyz="0 0 0"/>
    </visual>
    <collision>
      <geometry>
        <mesh filename="meshes/LAnkleRoll_0.10.stl" scale="1 1 1"/>
      </geometry>
      <origin rpy="0 0 0" xyz="0 0 0"/>
    </collision>
  </link>
  <joint name="LAnkleRoll_secondaryskin_joint" type="fixed">
    <parent link="l_ankle"/>
    <child link="LAnkleRoll_secondaryskin"/>
    <origin rpy="0 0 0" xyz="0 0 0"/>
  </joint>
  <link name="LAnkleRoll_secondaryskin">
    <inertial>
      <mass value="0"/>
      <inertia ixx="0" ixy="0" ixz="0" iyy="0" iyz="0" izz="0"/>
      <origin rpy="0 0 0" xyz="0 0 0"/>
    </inertial>
    <visual>
      <geometry>
        <mesh filename="meshes/LAnkleRoll_secondaryskin.obj" scale="1 1 1"/>
      </geometry>
      <origin rpy="0 0 0" xyz="0 0 0"/>
    </visual>
  </link>
  <joint name="LAnkleRoll_secondaryskin2_joint" type="fixed">
    <parent link="l_ankle"/>
    <child link="LAnkleRoll_secondaryskin2"/>
    <origin rpy="0 0 0" xyz="0 0 0"/>
  </joint>
  <link name="LAnkleRoll_secondaryskin2">
    <inertial>
      <mass value="0"/>
      <inertia ixx="0" ixy="0" ixz="0" iyy="0" iyz="0" izz="0"/>
      <origin rpy="0 0 0" xyz="0 0 0"/>
    </inertial>
    <visual>
      <geometry>
        <mesh filename="meshes/LAnkleRoll_secondaryskin2.obj" scale="1 1 1"/>
      </geometry>
      <origin rpy="0 0 0" xyz="0 0 0"/>
    </visual>
  </link>


  <joint name="LLeg_effector_fixedjoint" type="fixed">
    <parent link="l_ankle"/>
    <child link="l_sole"/>
    <origin rpy="0 0 0" xyz="0 0 -0.0651"/>
    <axis xyz="0 0 0"/>
  </joint>
  <link name="l_sole">
    <inertial>
      <mass value="0"/>
      <inertia ixx="0" ixy="0" ixz="0" iyy="0" iyz="0" izz="0"/>
      <origin rpy="0 0 0" xyz="0 0 0"/>
    </inertial>
  </link>
  <joint name="RHipYaw" type="revolute">
    <parent link="body"/>
    <child link="RHipYaw_link"/>
    <origin rpy="0 0 0" xyz="0.05 -0.096 -0.3375"/>
    <axis xyz="0 0 1.0"/>
    <limit effort="103.03" lower="-0.2618" upper="0.2618" velocity="1.045"/>
  </joint>
  <link name="RHipYaw_link">
    <inertial>
      <mass value="0.559188"/>
      <inertia ixx="0.000865336" ixy="-1.83253e-05" ixz="-0.000251445" iyy="0.00143007" iyz="8.26938e-05" izz="0.000851928"/>
      <origin rpy="0 0 0" xyz="-0.00922 0.00167 0.042"/>
    </inertial>
  </link>
  <joint name="RHipRoll" type="revolute">
    <parent link="RHipYaw_link"/>
    <child link="RHip"/>
    <origin rpy="0 0 0" xyz="0 0 0"/>
    <axis xyz="1.0 0 0"/>
    <limit effort="213.15" lower="-0.5236" upper="0.2618" velocity="2.09"/>
  </joint>
  <link name="RHip">
    <inertial>
      <mass value="0.714778"/>
      <inertia ixx="0.000937272" ixy="5.64884e-07" ixz="-2.02714e-06" iyy="0.000548117" iyz="-2.95823e-06" izz="0.00101855"/>
      <origin rpy="0 0 0" xyz="0.00249 0.00205 -0.00147"/>
    </inertial>
  </link>

  <!-- RHipPitch joints and links -->
  <joint name="RHipPitch" type="revolute">
    <parent link="RHip"/>
    <child link="RThigh"/>
    <origin rpy="0 0 0" xyz="0 0 0"/>
    <axis xyz="0 1.0 0"/>
    <limit effort="213.15" lower="-1.6581" upper="0.4014" velocity="2.09"/>
  </joint>
  <link name="RThigh">
    <inertial>
      <mass value="4.71096"/>
      <inertia ixx="0.0390706" ixy="-0.000537853" ixz="0.0250104" iyy="0.0395116" iyz="-0.00278999" izz="0.0122599"/>
      <origin rpy="0 0 0" xyz="-0.02138 0.00255 -0.14577"/>
    </inertial>
    <visual>
      <geometry>
        <mesh filename="meshes/RHipPitch_mainskin.obj" scale="1 1 1"/>
      </geometry>
      <origin rpy="0 0 0" xyz="0 0 0"/>
    </visual>
    <collision>
      <geometry>
        <mesh filename="meshes/RHipPitch_0.10.stl" scale="1 1 1"/>
      </geometry>
      <origin rpy="0 0 0" xyz="0 0 0"/>
    </collision>
  </link>
  <joint name="RHipPitch_shell_joint" type="fixed">
    <parent link="RThigh"/>
    <child link="RHipPitch_shell"/>
    <origin rpy="0 0 0" xyz="0 0 0"/>
  </joint>
  <link name="RHipPitch_shell">
    <inertial>
      <mass value="0"/>
      <inertia ixx="0" ixy="0" ixz="0" iyy="0" iyz="0" izz="0"/>
      <origin rpy="0 0 0" xyz="0 0 0"/>
    </inertial>
    <visual>
      <geometry>
        <mesh filename="meshes/RHipPitch_shell.obj" scale="1 1 1"/>
      </geometry>
      <origin rpy="0 0 0" xyz="0 0 0"/>
    </visual>
  </link>
  <joint name="RHipPitch_flexibleskin_joint" type="fixed">
    <parent link="RThigh"/>
    <child link="RHipPitch_flexibleskin"/>
    <origin rpy="0 0 0" xyz="0 0 0"/>
  </joint>
  <link name="RHipPitch_flexibleskin">
    <inertial>
      <mass value="0"/>
      <inertia ixx="0" ixy="0" ixz="0" iyy="0" iyz="0" izz="0"/>
      <origin rpy="0 0 0" xyz="0 0 0"/>
    </inertial>
    <visual>
      <geometry>
        <mesh filename="meshes/RHipPitch_flexibleskin.obj" scale="1 1 1"/>
      </geometry>
      <origin rpy="0 0 0" xyz="0 0 0"/>
    </visual>
  </link>
  <joint name="RHipPitch_secondaryskin_joint" type="fixed">
    <parent link="RThigh"/>
    <child link="RHipPitch_secondaryskin"/>
    <origin rpy="0 0 0" xyz="0 0 0"/>
  </joint>
  <link name="RHipPitch_secondaryskin">
    <inertial>
      <mass value="0"/>
      <inertia ixx="0" ixy="0" ixz="0" iyy="0" iyz="0" izz="0"/>
      <origin rpy="0 0 0" xyz="0 0 0"/>
    </inertial>
    <visual>
      <geometry>
        <mesh filename="meshes/RHipPitch_secondaryskin.obj" scale="1 1 1"/>
      </geometry>
      <origin rpy="0 0 0" xyz="0 0 0"/>
    </visual>
  </link>

  <!-- RKneePitch joints and links -->
  <joint name="RKneePitch" type="revolute">
    <parent link="RThigh"/>
    <child link="RTibia"/>
    <origin rpy="0 0 0" xyz="0 0 -0.322"/>
    <axis xyz="0 1.0 0"/>
    <limit effort="292.50" lower="-0.0218" upper="1.9722" velocity="6.0"/>
  </joint>
  <link name="RTibia">
    <inertial>
      <mass value="2.72291"/>
      <inertia ixx="0.0159124" ixy="-1.21492e-05" ixz="0.00301963" iyy="0.0158076" iyz="-0.000329953" izz="0.00369233"/>
      <origin rpy="0 0 0" xyz="-0.00415 0.00054 -0.11011"/>
    </inertial>
    <visual>
      <geometry>
        <mesh filename="meshes/RKneePitch_mainskin.obj" scale="1 1 1"/>
      </geometry>
      <origin rpy="0 0 0" xyz="0 0 0"/>
    </visual>
    <collision>
      <geometry>
        <mesh filename="meshes/RKneePitch_0.10.stl" scale="1 1 1"/>
      </geometry>
      <origin rpy="0 0 0" xyz="0 0 0"/>
    </collision>
  </link>
  <joint name="RKneePitch_secondaryskin_joint" type="fixed">
    <parent link="RTibia"/>
    <child link="RKneePitch_secondaryskin"/>
    <origin rpy="0 0 0" xyz="0 0 0"/>
  </joint>
  <link name="RKneePitch_secondaryskin">
    <inertial>
      <mass value="0"/>
      <inertia ixx="0" ixy="0" ixz="0" iyy="0" iyz="0" izz="0"/>
      <origin rpy="0 0 0" xyz="0 0 0"/>
    </inertial>
    <visual>
      <geometry>
        <mesh filename="meshes/RKneePitch_secondaryskin.obj" scale="1 1 1"/>
      </geometry>
      <origin rpy="0 0 0" xyz="0 0 0"/>
    </visual>
  </link>
  <joint name="RKneePitch_shell_joint" type="fixed">
    <parent link="RTibia"/>
    <child link="RKneePitch_shell"/>
    <origin rpy="0 0 0" xyz="0 0 0"/>
  </joint>
  <link name="RKneePitch_shell">
    <inertial>
      <mass value="0"/>
      <inertia ixx="0" ixy="0" ixz="0" iyy="0" iyz="0" izz="0"/>
      <origin rpy="0 0 0" xyz="0 0 0"/>
    </inertial>
    <visual>
      <geometry>
        <mesh filename="meshes/RKneePitch_shell.obj" scale="1 1 1"/>
      </geometry>
      <origin rpy="0 0 0" xyz="0 0 0"/>
    </visual>
  </link>
  <joint name="RKneePitch_secondaryskin2_joint" type="fixed">
    <parent link="RTibia"/>
    <child link="RKneePitch_secondaryskin2"/>
    <origin rpy="0 0 0" xyz="0 0 0"/>
  </joint>
  <link name="RKneePitch_secondaryskin2">
    <inertial>
      <mass value="0"/>
      <inertia ixx="0" ixy="0" ixz="0" iyy="0" iyz="0" izz="0"/>
      <origin rpy="0 0 0" xyz="0 0 0"/>
    </inertial>
    <visual>
      <geometry>
        <mesh filename="meshes/RKneePitch_secondaryskin2.obj" scale="1 1 1"/>
      </geometry>
      <origin rpy="0 0 0" xyz="0 0 0"/>
    </visual>
  </link>
  <joint name="RKneePitch_secondaryskin3_joint" type="fixed">
    <parent link="RTibia"/>
    <child link="RKneePitch_secondaryskin3"/>
    <origin rpy="0 0 0" xyz="0 0 0"/>
  </joint>
  <link name="RKneePitch_secondaryskin3">
    <inertial>
      <mass value="0"/>
      <inertia ixx="0" ixy="0" ixz="0" iyy="0" iyz="0" izz="0"/>
      <origin rpy="0 0 0" xyz="0 0 0"/>
    </inertial>
    <visual>
      <geometry>
        <mesh filename="meshes/RKneePitch_secondaryskin3.obj" scale="1 1 1"/>
      </geometry>
      <origin rpy="0 0 0" xyz="0 0 0"/>
    </visual>
  </link>

  <joint name="RAnklePitch" type="revolute">
    <parent link="RTibia"/>
    <child link="RAnklePitch_link"/>
    <origin rpy="0 0 0" xyz="0 0 -0.29"/>
    <axis xyz="0 1.0 0"/>
    <limit effort="213.15" lower="-0.5149" upper="0.7505" velocity="2.1"/>
  </joint>
  <link name="RAnklePitch_link">
    <inertial>
      <mass value="0.464512"/>
      <inertia ixx="0.000367336" ixy="1.31739e-06" ixz="1.0441e-07" iyy="0.000239298" iyz="-1.06885e-06" izz="0.000425531"/>
      <origin rpy="0 0 0" xyz="0.00132 0.00117 0.00015"/>
    </inertial>
  </link>

  <!-- RAnkleRoll joints and links -->
  <joint name="RAnkleRoll" type="revolute">
    <parent link="RAnklePitch_link"/>
    <child link="r_ankle"/>
    <origin rpy="0 0 0" xyz="0 0 0"/>
    <axis xyz="1.0 0 0"/>
    <limit effort="213.15" lower="-0.3491" upper="0.3491" velocity="2.1"/>
  </joint>
  <link name="r_ankle">
    <inertial>
      <mass value="1.06764"/>
      <inertia ixx="0.000978167" ixy="-0.000173863" ixz="-0.000879138" iyy="0.00586633" iyz="0.000155656" izz="0.00589599"/>
      <origin rpy="0 0 0" xyz="0.0483878 -0.00120158 -0.0367645"/>
    </inertial>
    <visual>
      <geometry>
        <mesh filename="meshes/RAnkleRoll_mainskin.obj" scale="1 1 1"/>
      </geometry>
      <origin rpy="0 0 0" xyz="0 0 0"/>
    </visual>
    <collision>
      <geometry>
        <mesh filename="meshes/RAnkleRoll_0.10.stl" scale="1 1 1"/>
      </geometry>
      <origin rpy="0 0 0" xyz="0 0 0"/>
    </collision>
  </link>
  <joint name="RAnkleRoll_secondaryskin_joint" type="fixed">
    <parent link="r_ankle"/>
    <child link="RAnkleRoll_secondaryskin"/>
    <origin rpy="0 0 0" xyz="0 0 0"/>
  </joint>
  <link name="RAnkleRoll_secondaryskin">
    <inertial>
      <mass value="0"/>
      <inertia ixx="0" ixy="0" ixz="0" iyy="0" iyz="0" izz="0"/>
      <origin rpy="0 0 0" xyz="0 0 0"/>
    </inertial>
    <visual>
      <geometry>
        <mesh filename="meshes/RAnkleRoll_secondaryskin.obj" scale="1 1 1"/>
      </geometry>
      <origin rpy="0 0 0" xyz="0 0 0"/>
    </visual>
  </link>
  <joint name="RAnkleRoll_secondaryskin2_joint" type="fixed">
    <parent link="r_ankle"/>
    <child link="RAnkleRoll_secondaryskin2"/>
    <origin rpy="0 0 0" xyz="0 0 0"/>
  </joint>
  <link name="RAnkleRoll_secondaryskin2">
    <inertial>
      <mass value="0"/>
      <inertia ixx="0" ixy="0" ixz="0" iyy="0" iyz="0" izz="0"/>
      <origin rpy="0 0 0" xyz="0 0 0"/>
    </inertial>
    <visual>
      <geometry>
        <mesh filename="meshes/RAnkleRoll_secondaryskin2.obj" scale="1 1 1"/>
      </geometry>
      <origin rpy="0 0 0" xyz="0 0 0"/>
    </visual>
  </link>

  <joint name="RLeg_effector_fixedjoint" type="fixed">
    <parent link="r_ankle"/>
    <child link="r_sole"/>
    <origin rpy="0 0 0" xyz="0 0 -0.0651"/>
    <axis xyz="0 0 0"/>
  </joint>
  <link name="r_sole">
    <inertial>
      <mass value="0"/>
      <inertia ixx="0" ixy="0" ixz="0" iyy="0" iyz="0" izz="0"/>
      <origin rpy="0 0 0" xyz="0 0 0"/>
    </inertial>
  </link>
  <link name="base_link">
    <inertial>
      <mass value="0.00000001"/>
      <!-- <inertia ixx="0" ixy="0" ixz="0" iyy="0" iyz="0" izz="0"/> -->
      <inertia ixx="1" ixy="0" ixz="0" iyy="1" iyz="0" izz="1"/>
      <origin rpy="0 0 0" xyz="0 0 0"/>
    </inertial>
  </link>

  <!-- torso joints and links -->
  <joint name="base_link_fixedjoint" type="fixed">
    <parent link="base_link"/>
    <child link="torso"/>
    <origin rpy="0 0 0" xyz="0 0 0"/>
    <axis xyz="0 0 0"/>
  </joint>
  <link name="torso">
    <inertial>
      <mass value="5.85463"/>
      <inertia ixx="0.0587116" ixy="-3.02711e-06" ixz="0.0101426" iyy="0.0326812" iyz="-0.000132541" izz="0.0637705"/>
      <origin rpy="0 0 0" xyz="0.01512 0 0.06743"/>
    </inertial>
    <visual>
      <geometry>
        <mesh filename="meshes/Torso_logo.obj" scale="1 1 1"/>
      </geometry>
      <origin rpy="0 0 0" xyz="0 0 0"/>
    </visual>
    <collision>
      <geometry>
        <mesh filename="meshes/Torso_0.10.stl" scale="1 1 1"/>
      </geometry>
      <origin rpy="0 0 0" xyz="0 0 0"/>
    </collision>
  </link>
  <joint name="torso_secondaryskin_joint" type="fixed">
    <parent link="torso"/>
    <child link="torso_secondaryskin"/>
    <origin rpy="0 0 0" xyz="0 0 0"/>
  </joint>
  <link name="torso_secondaryskin">
    <inertial>
      <mass value="0"/>
      <inertia ixx="0" ixy="0" ixz="0" iyy="0" iyz="0" izz="0"/>
      <origin rpy="0 0 0" xyz="0 0 0"/>
    </inertial>
    <visual>
      <geometry>
        <mesh filename="meshes/Torso_secondaryskin.obj" scale="1 1 1"/>
      </geometry>
      <origin rpy="0 0 0" xyz="0 0 0"/>
    </visual>
  </link>
  <joint name="torso_emergencybutton_joint" type="fixed">
    <parent link="torso"/>
    <child link="torso_emergencybutton"/>
    <origin rpy="0 0 0" xyz="0 0 0"/>
  </joint>
  <link name="torso_emergencybutton">
    <inertial>
      <mass value="0"/>
      <inertia ixx="0" ixy="0" ixz="0" iyy="0" iyz="0" izz="0"/>
      <origin rpy="0 0 0" xyz="0 0 0"/>
    </inertial>
    <visual>
      <geometry>
        <mesh filename="meshes/Torso_emergencybutton.obj" scale="1 1 1"/>
      </geometry>
      <origin rpy="0 0 0" xyz="0 0 0"/>
    </visual>
  </link>
  <joint name="torso_flexibleskin_joint" type="fixed">
    <parent link="torso"/>
    <child link="torso_flexibleskin"/>
    <origin rpy="0 0 0" xyz="0 0 0"/>
  </joint>
  <link name="torso_flexibleskin">
    <inertial>
      <mass value="0"/>
      <inertia ixx="0" ixy="0" ixz="0" iyy="0" iyz="0" izz="0"/>
      <origin rpy="0 0 0" xyz="0 0 0"/>
    </inertial>
    <visual>
      <geometry>
        <mesh filename="meshes/Torso_flexibleskin.obj" scale="1 1 1"/>
      </geometry>
      <origin rpy="0 0 0" xyz="0 0 0"/>
    </visual>
  </link>
  <joint name="torso_mainskin_joint" type="fixed">
    <parent link="torso"/>
    <child link="torso_mainskin"/>
    <origin rpy="0 0 0" xyz="0 0 0"/>
  </joint>
  <link name="torso_mainskin">
    <inertial>
      <mass value="0"/>
      <inertia ixx="0" ixy="0" ixz="0" iyy="0" iyz="0" izz="0"/>
      <origin rpy="0 0 0" xyz="0 0 0"/>
    </inertial>
    <visual>
      <geometry>
        <mesh filename="meshes/Torso_mainskin.obj" scale="1 1 1"/>
      </geometry>
      <origin rpy="0 0 0" xyz="0 0 0"/>
    </visual>
  </link>
  <joint name="torso_shell_joint" type="fixed">
    <parent link="torso"/>
    <child link="torso_shell"/>
    <origin rpy="0 0 0" xyz="0 0 0"/>
  </joint>
  <link name="torso_shell">
    <inertial>
      <mass value="0"/>
      <inertia ixx="0" ixy="0" ixz="0" iyy="0" iyz="0" izz="0"/>
      <origin rpy="0 0 0" xyz="0 0 0"/>
    </inertial>
    <visual>
      <geometry>
        <mesh filename="meshes/Torso_shell.obj" scale="1 1 1"/>
      </geometry>
      <origin rpy="0 0 0" xyz="0 0 0"/>
    </visual>
  </link>

  <!-- TrunkYaw joints and links -->
  <joint name="TrunkYaw" type="revolute">
    <parent link="torso"/>
    <child link="body"/>
    <origin rpy="0 0 0" xyz="0 0 0"/>
    <axis xyz="0 0 1.0"/>
    <limit effort="49.93" lower="-0.7575" upper="0.7575" velocity="1.5"/>
  </joint>
  <link name="body">
    <inertial>
      <mass value="5.11337"/>
      <inertia ixx="0.0564204" ixy="7.26322e-05" ixz="-0.0575115" iyy="0.0521042" iyz="-3.39086e-05" izz="0.021185"/>
      <origin rpy="0 0 0" xyz="0.02825 0 -0.16653"/>
    </inertial>
    <visual>
      <geometry>
        <mesh filename="meshes/TrunkYaw_flexibleskin.obj" scale="1 1 1"/>
      </geometry>
      <origin rpy="0 0 0" xyz="0 0 0"/>
    </visual>
    <collision>
      <geometry>
        <mesh filename="meshes/TrunkYaw_0.10.stl" scale="1 1 1"/>
      </geometry>
      <origin rpy="0 0 0" xyz="0 0 0"/>
    </collision>
  </link>
  <joint name="TrunkYaw_shell_joint" type="fixed">
    <parent link="body"/>
    <child link="TrunkYaw_shell"/>
    <origin rpy="0 0 0" xyz="0 0 0"/>
  </joint>
  <link name="TrunkYaw_shell">
    <inertial>
      <mass value="0"/>
      <inertia ixx="0" ixy="0" ixz="0" iyy="0" iyz="0" izz="0"/>
      <origin rpy="0 0 0" xyz="0 0 0"/>
    </inertial>
    <visual>
      <geometry>
        <mesh filename="meshes/TrunkYaw_shell.obj" scale="1 1 1"/>
      </geometry>
      <origin rpy="0 0 0" xyz="0 0 0"/>
    </visual>
  </link>
  <joint name="TrunkYaw_mainskin_joint" type="fixed">
    <parent link="body"/>
    <child link="TrunkYaw_mainskin"/>
    <origin rpy="0 0 0" xyz="0 0 0"/>
  </joint>
  <link name="TrunkYaw_mainskin">
    <inertial>
      <mass value="0"/>
      <inertia ixx="0" ixy="0" ixz="0" iyy="0" iyz="0" izz="0"/>
      <origin rpy="0 0 0" xyz="0 0 0"/>
    </inertial>
    <visual>
      <geometry>
        <mesh filename="meshes/TrunkYaw_mainskin.obj" scale="1 1 1"/>
      </geometry>
      <origin rpy="0 0 0" xyz="0 0 0"/>
    </visual>
  </link>

  <joint name="LShoulderPitch" type="revolute">
    <parent link="torso"/>
    <child link="LShoulder"/>
    <origin rpy="1.49012e-08 7.45058e-09 0" xyz="0.049862 0.19 0.073851"/>
    <axis xyz="0.417025 0.895055 -0.15801"/>
    <limit effort="21.94" lower="-1.3491" upper="2.2462" velocity="2.2"/>
  </joint>
  <link name="LShoulder">
    <inertial>
      <mass value="0.541429"/>
      <inertia ixx="0.00033428" ixy="-9.92972e-05" ixz="9.98217e-06" iyy="0.000188073" iyz="2.14339e-05" izz="0.000360929"/>
      <origin rpy="0 0 0" xyz="-0.0112798 -0.0260712 0.00468882"/>
    </inertial>
  </link>

  <!-- LShoulderYaw links and joints -->
  <joint name="LShoulderYaw" type="revolute">
    <parent link="LShoulder"/>
    <child link="LShoulderYaw_link"/>
    <origin rpy="2.98023e-08 1.11759e-08 -5.58793e-08" xyz="0 0 0"/>
    <axis xyz="0.0401398 0.155542 0.987013"/>
    <limit effort="15.16" lower="-0.5768" upper="0.9242" velocity="4.0"/>
  </joint>
  <link name="LShoulderYaw_link">
    <inertial>
      <mass value="0.861545"/>
      <inertia ixx="0.00118557" ixy="0.000596133" ixz="0.0011173" iyy="0.00312162" iyz="-2.05919e-05" izz="0.00289955"/>
      <origin rpy="0 0 0" xyz="0.0965281 0.00465308 0.00168775"/>
    </inertial>
    <visual>
      <geometry>
        <mesh filename="meshes/LShoulderYaw_mainskin.obj" scale="1 1 1"/>
      </geometry>
      <origin rpy="0 0 0" xyz="0 0 0"/>
    </visual>
    <collision>
      <geometry>
        <mesh filename="meshes/LShoulderYaw_0.10.stl" scale="1 1 1"/>
      </geometry>
      <origin rpy="0 0 0" xyz="0 0 0"/>
    </collision>
  </link>
  <joint name="LShoulderYaw_shell_joint" type="fixed">
    <parent link="LShoulderYaw_link"/>
    <child link="LShoulderYaw_shell"/>
    <origin rpy="0 0 0" xyz="0 0 0"/>
  </joint>
  <link name="LShoulderYaw_shell">
    <inertial>
      <mass value="0"/>
      <inertia ixx="0" ixy="0" ixz="0" iyy="0" iyz="0" izz="0"/>
      <origin rpy="0 0 0" xyz="0 0 0"/>
    </inertial>
    <visual>
      <geometry>
        <mesh filename="meshes/LShoulderYaw_shell.obj" scale="1 1 1"/>
      </geometry>
      <origin rpy="0 0 0" xyz="0 0 0"/>
    </visual>
  </link>

  <joint name="LElbowRoll" type="revolute">
    <parent link="LShoulderYaw_link"/>
    <child link="LForeArm"/>
    <origin rpy="-2.56114e-09 0 -9.31322e-09" xyz="0.210824 7.40511e-09 -0.008631"/>
    <axis xyz="0.998889 0.0139984 0.044995"/>
    <limit effort="13.86" lower="-2.2148" upper="1.9042" velocity="3.7"/>
  </joint>
  <link name="LForeArm">
    <inertial>
      <mass value="0.600439"/>
      <inertia ixx="0.000207598" ixy="1.2053e-05" ixz="-1.86312e-05" iyy="0.000507683" iyz="1.56171e-06" izz="0.000456309"/>
      <origin rpy="0 0 0" xyz="-0.0348859 -0.0011589 -0.00148134"/>
    </inertial>
  </link>

  <!-- LElbowYaw joints and links -->
  <joint name="LElbowYaw" type="revolute">
    <parent link="LForeArm"/>
    <child link="LElbow"/>
    <origin rpy="-1.49504e-08 -1.86264e-08 2.12577e-09" xyz="0 0 0"/>
    <axis xyz="-0.0449994 0 0.998987"/>
    <limit effort="15.16" lower="-1.5228" upper="0.0044" velocity="4.0"/>
  </joint>
  <link name="LElbow">
    <inertial>
      <mass value="0.460203"/>
      <inertia ixx="0.000503576" ixy="0.000585803" ixz="3.19975e-05" iyy="0.00127777" iyz="3.67296e-05" izz="0.00122813"/>
      <origin rpy="0 0 0" xyz="0.068523 0.0097 0.00458766"/>
    </inertial>
    <visual>
      <geometry>
        <mesh filename="meshes/LElbowYaw_mainskin.obj" scale="1 1 1"/>
      </geometry>
      <origin rpy="0 0 0" xyz="0 0 0"/>
    </visual>
    <collision>
      <geometry>
        <mesh filename="meshes/LElbowYaw_0.10.stl" scale="1 1 1"/>
      </geometry>
      <origin rpy="0 0 0" xyz="0 0 0"/>
    </collision>
  </link>
  <joint name="LElbowYaw_shell_joint" type="fixed">
    <parent link="LElbow"/>
    <child link="LElbowYaw_shell"/>
    <origin rpy="0 0 0" xyz="0 0 0"/>
  </joint>
  <link name="LElbowYaw_shell">
    <inertial>
      <mass value="0"/>
      <inertia ixx="0" ixy="0" ixz="0" iyy="0" iyz="0" izz="0"/>
      <origin rpy="0 0 0" xyz="0 0 0"/>
    </inertial>
    <visual>
      <geometry>
        <mesh filename="meshes/LElbowYaw_shell.obj" scale="1 1 1"/>
      </geometry>
      <origin rpy="0 0 0" xyz="0 0 0"/>
    </visual>
  </link>

  <joint name="LWristRoll" type="revolute">
    <parent link="LElbow"/>
    <child link="LWristRoll_link"/>
    <origin rpy="0 -7.45058e-09 0" xyz="0.190404 0 0.008631"/>
    <axis xyz="0.998987 0 0.0449994"/>
    <limit effort="7.23" lower="-3.6303" upper="0.4887" velocity="1.1"/>
  </joint>
  <link name="LWristRoll_link">
    <inertial>
      <mass value="0.218316"/>
      <inertia ixx="0.000100812" ixy="-1.81881e-06" ixz="-4.56681e-05" iyy="0.000384336" iyz="-1.11019e-07" izz="0.000366084"/>
      <origin rpy="0 0 0" xyz="-0.0592449 6e-05 -0.00144745"/>
    </inertial>
    <visual>
      <geometry>
        <mesh filename="meshes/LWristRoll.obj" scale="1 1 1"/>
      </geometry>
      <origin rpy="0 0 0" xyz="0 0 0"/>
    </visual>
    <collision>
      <geometry>
        <mesh filename="meshes/LWristRoll_0.10.stl" scale="1 1 1"/>
      </geometry>
      <origin rpy="0 0 0" xyz="0 0 0"/>
    </collision>
  </link>
  <joint name="LWristYaw" type="revolute">
    <parent link="LWristRoll_link"/>
    <child link="LWristYaw_link"/>
    <origin rpy="0 0 0" xyz="0 0 0"/>
    <axis xyz="-0.0449994 0 0.998987"/>
    <limit effort="2.01" lower="-0.4014" upper="0.4014" velocity="2.26"/>
  </joint>
  <link name="LWristYaw_link">
    <inertial>
      <mass value="0.0758774"/>
      <inertia ixx="1.55687e-05" ixy="-5.1829e-08" ixz="-8.72923e-07" iyy="3.52487e-05" iyz="1.94513e-08" izz="3.4791e-05"/>
      <origin rpy="0 0 0" xyz="-0.00657144 0.00017 -0.000115829"/>
    </inertial>
    <visual>
      <geometry>
        <mesh filename="meshes/LWristYaw.obj" scale="1 1 1"/>
      </geometry>
      <origin rpy="0 0 0" xyz="0 0 0"/>
    </visual>
    <collision>
      <geometry>
        <mesh filename="meshes/LWristYaw_0.10.stl" scale="1 1 1"/>
      </geometry>
      <origin rpy="0 0 0" xyz="0 0 0"/>
    </collision>
  </link>
  <joint name="LWristPitch" type="revolute">
    <parent link="LWristYaw_link"/>
    <child link="l_wrist"/>
    <origin rpy="0 0 0" xyz="0 0 0"/>
    <axis xyz="0 1.0 0"/>
    <limit effort="1.39" lower="-0.988" upper="0.8969" velocity="3.75"/>
  </joint>
  <link name="l_wrist">
    <inertial>
      <mass value="0.442191"/>
      <inertia ixx="0.000404603" ixy="-0.000404247" ixz="1.89685e-05" iyy="0.000829354" iyz="7.81042e-05" izz="0.00102014"/>
      <origin rpy="0 0 0" xyz="0.07358 -0.00628 -0.00098"/>
    </inertial>
    <visual>
      <geometry>
        <mesh filename="meshes/LWristPitch.obj" scale="1 1 1"/>
      </geometry>
      <origin rpy="0 0 0" xyz="0 0 0"/>
    </visual>
    <collision>
      <geometry>
        <mesh filename="meshes/LWristPitch_0.10.stl" scale="1 1 1"/>
      </geometry>
      <origin rpy="0 0 0" xyz="0 0 0"/>
    </collision>
  </link>
  <joint name="LHand" type="revolute">
    <parent link="l_wrist"/>
    <child link="l_gripper"/>
    <origin rpy="1.5708 0.0450146 -3.14159" xyz="-0.0579412 -0.0159 -0.00260997"/>
    <axis xyz="1.0 0 0"/>
    <limit effort="0.649997" lower="0" upper="1.0" velocity="59.8925"/>
  </joint>
  <link name="l_gripper">
    <inertial>
      <mass value="2e-06"/>
      <inertia ixx="1.1e-09" ixy="0" ixz="0" iyy="1.1e-09" iyz="0" izz="1.1e-09"/>
    </inertial>
  </link>
  <joint name="RShoulderPitch" type="revolute">
    <parent link="torso"/>
    <child link="RShoulder"/>
    <origin rpy="-1.49012e-08 7.45058e-09 0" xyz="0.049862 -0.19 0.073851"/>
    <axis xyz="-0.417025 0.895055 0.15801"/>
    <limit effort="21.94" lower="-1.4554" upper="2.1399" velocity="2.2"/>
  </joint>
  <link name="RShoulder">
    <inertial>
      <mass value="0.541429"/>
      <inertia ixx="0.00032868" ixy="0.000102539" ixz="1.9336e-05" iyy="0.000199958" iyz="-3.81835e-05" izz="0.000354645"/>
      <origin rpy="0 0 0" xyz="-0.0112798 0.0260712 0.00468882"/>
    </inertial>
  </link>

  <!-- RShoulderYaw joints and links -->
  <joint name="RShoulderYaw" type="revolute">
    <parent link="RShoulder"/>
    <child link="RShoulderYaw_link"/>
    <origin rpy="-2.98023e-08 1.49012e-08 -6.42613e-08" xyz="0 0 0"/>
    <axis xyz="0.0401398 -0.155542 0.987014"/>
    <limit effort="15.16" lower="-1.0985" upper="0.4025" velocity="4.0"/>
  </joint>
  <link name="RShoulderYaw_link">
    <inertial>
      <mass value="0.861545"/>
      <inertia ixx="0.00118857" ixy="-0.00036285" ixz="0.001154" iyy="0.00311916" iyz="1.86519e-05" izz="0.002899"/>
      <origin rpy="0 0 0" xyz="0.0965281 -0.00465308 0.00168775"/>
    </inertial>
    <visual>
      <geometry>
        <mesh filename="meshes/RShoulderYaw_mainskin.obj" scale="1 1 1"/>
      </geometry>
      <origin rpy="0 0 0" xyz="0 0 0"/>
    </visual>
    <collision>
      <geometry>
        <mesh filename="meshes/RShoulderYaw_0.10.stl" scale="1 1 1"/>
      </geometry>
      <origin rpy="0 0 0" xyz="0 0 0"/>
    </collision>
  </link>
  <joint name="RShoulderYaw_shell_joint" type="fixed">
    <parent link="RShoulderYaw_link"/>
    <child link="RShoulderYaw_shell"/>
    <origin rpy="0 0 0" xyz="0 0 0"/>
  </joint>
  <link name="RShoulderYaw_shell">
    <inertial>
      <mass value="0"/>
      <inertia ixx="0" ixy="0" ixz="0" iyy="0" iyz="0" izz="0"/>
      <origin rpy="0 0 0" xyz="0 0 0"/>
    </inertial>
    <visual>
      <geometry>
        <mesh filename="meshes/RShoulderYaw_shell.obj" scale="1 1 1"/>
      </geometry>
      <origin rpy="0 0 0" xyz="0 0 0"/>
    </visual>
  </link>

  <joint name="RElbowRoll" type="revolute">
    <parent link="RShoulderYaw_link"/>
    <child link="RForeArm"/>
    <origin rpy="6.69388e-09 7.45058e-09 -7.91624e-08" xyz="0.210824 -1.48548e-08 -0.008631"/>
    <axis xyz="0.998889 -0.0139984 0.044995"/>
    <limit effort="13.86" lower="-1.9047" upper="2.2143" velocity="3.7"/>
  </joint>
  <link name="RForeArm">
    <inertial>
      <mass value="0.600439"/>
      <inertia ixx="0.000207722" ixy="-7.62167e-06" ixz="-1.85932e-05" iyy="0.000507556" iyz="9.54211e-07" izz="0.000456313"/>
      <origin rpy="0 0 0" xyz="-0.0348859 0.0011589 -0.00148134"/>
    </inertial>
  </link>

  <!-- RElbowYaw joints and links -->
  <joint name="RElbowYaw" type="revolute">
    <parent link="RForeArm"/>
    <child link="RElbow"/>
    <origin rpy="1.49504e-08 -1.86264e-08 -2.12577e-09" xyz="0 0 0"/>
    <axis xyz="-0.0449994 0 0.998987"/>
    <limit effort="15.16" lower="-0.0047" upper="1.5225" velocity="4.0"/>
  </joint>
  <link name="RElbow">
    <inertial>
      <mass value="0.460203"/>
      <inertia ixx="0.000503576" ixy="-2.59661e-05" ixz="3.19975e-05" iyy="0.00127777" iyz="-4.2287e-06" izz="0.00122813"/>
      <origin rpy="0 0 0" xyz="0.068523 -0.0097 0.00458766"/>
    </inertial>
    <visual>
      <geometry>
        <mesh filename="meshes/RElbowYaw_mainskin.obj" scale="1 1 1"/>
      </geometry>
      <origin rpy="0 0 0" xyz="0 0 0"/>
    </visual>
    <collision>
      <geometry>
        <mesh filename="meshes/RElbowYaw_0.10.stl" scale="1 1 1"/>
      </geometry>
      <origin rpy="0 0 0" xyz="0 0 0"/>
    </collision>
  </link>
  <joint name="RElbowYaw_shell_joint" type="fixed">
    <parent link="RElbow"/>
    <child link="RElbowYaw_shell"/>
    <origin rpy="0 0 0" xyz="0 0 0"/>
  </joint>
  <link name="RElbowYaw_shell">
    <inertial>
      <mass value="0"/>
      <inertia ixx="0" ixy="0" ixz="0" iyy="0" iyz="0" izz="0"/>
      <origin rpy="0 0 0" xyz="0 0 0"/>
    </inertial>
    <visual>
      <geometry>
        <mesh filename="meshes/RElbowYaw_shell.obj" scale="1 1 1"/>
      </geometry>
      <origin rpy="0 0 0" xyz="0 0 0"/>
    </visual>
  </link>

  <joint name="RWristRoll" type="revolute">
    <parent link="RElbow"/>
    <child link="RWristRoll_link"/>
    <origin rpy="0 -7.45058e-09 0" xyz="0.190404 0 0.008631"/>
    <axis xyz="0.998987 0 0.0449994"/>
    <limit effort="7.23" lower="-0.4887" upper="3.6303" velocity="1.1"/>
  </joint>
  <link name="RWristRoll_link">
    <inertial>
      <mass value="0.218316"/>
      <inertia ixx="0.000100812" ixy="-2.66721e-07" ixz="-4.56681e-05" iyy="0.000384336" iyz="-7.30984e-08" izz="0.000366084"/>
      <origin rpy="0 0 0" xyz="-0.0592449 -6e-05 -0.00144745"/>
    </inertial>
    <visual>
      <geometry>
        <mesh filename="meshes/RWristRoll.obj" scale="1 1 1"/>
      </geometry>
      <origin rpy="0 0 0" xyz="0 0 0"/>
    </visual>
    <collision>
      <geometry>
        <mesh filename="meshes/RWristRoll_0.10.stl" scale="1 1 1"/>
      </geometry>
      <origin rpy="0 0 0" xyz="0 0 0"/>
    </collision>
  </link>
  <joint name="RWristYaw" type="revolute">
    <parent link="RWristRoll_link"/>
    <child link="RWristYaw_link"/>
    <origin rpy="0 0 0" xyz="0 0 0"/>
    <axis xyz="-0.0449994 0 0.998987"/>
    <limit effort="2.01" lower="-0.4014" upper="0.4014" velocity="2.26"/>
  </joint>
  <link name="RWristYaw_link">
    <inertial>
      <mass value="0.0758774"/>
      <inertia ixx="1.55687e-05" ixy="1.17703e-07" ixz="-8.72923e-07" iyy="3.52487e-05" iyz="2.24395e-08" izz="3.4791e-05"/>
      <origin rpy="0 0 0" xyz="-0.00657144 -0.00017 -0.000115829"/>
    </inertial>
    <visual>
      <geometry>
        <mesh filename="meshes/RWristYaw.obj" scale="1 1 1"/>
      </geometry>
      <origin rpy="0 0 0" xyz="0 0 0"/>
    </visual>
    <collision>
      <geometry>
        <mesh filename="meshes/RWristYaw_0.10.stl" scale="1 1 1"/>
      </geometry>
      <origin rpy="0 0 0" xyz="0 0 0"/>
    </collision>
  </link>
  <joint name="RWristPitch" type="revolute">
    <parent link="RWristYaw_link"/>
    <child link="r_wrist"/>
    <origin rpy="0 0 0" xyz="0 0 0"/>
    <axis xyz="0 1.0 0"/>
    <limit effort="1.39" lower="-0.9868" upper="0.8981" velocity="3.75"/>
  </joint>
  <link name="r_wrist">
    <inertial>
      <mass value="0.442191"/>
      <inertia ixx="0.000404603" ixy="4.4107e-06" ixz="1.89685e-05" iyy="0.000829354" iyz="7.26613e-05" izz="0.00102014"/>
      <origin rpy="0 0 0" xyz="0.07358 0.00628 -0.00098"/>
    </inertial>
    <visual>
      <geometry>
        <mesh filename="meshes/RWristPitch.obj" scale="1 1 1"/>
      </geometry>
      <origin rpy="0 0 0" xyz="0 0 0"/>
    </visual>
    <collision>
      <geometry>
        <mesh filename="meshes/RWristPitch_0.10.stl" scale="1 1 1"/>
      </geometry>
      <origin rpy="0 0 0" xyz="0 0 0"/>
    </collision>
  </link>
  <joint name="RHand" type="revolute">
    <parent link="r_wrist"/>
    <child link="r_gripper"/>
    <origin rpy="1.5708 0.0450146 -3.14159" xyz="-0.0579412 -0.0159 -0.00260997"/>
    <axis xyz="1.0 0 0"/>
    <limit effort="0.649997" lower="0" upper="1.0" velocity="59.8925"/>
  </joint>
  <link name="r_gripper">
    <inertial>
      <mass value="2e-06"/>
      <inertia ixx="1.1e-09" ixy="0" ixz="0" iyy="1.1e-09" iyz="0" izz="1.1e-09"/>
    </inertial>
  </link>
  <joint name="LEyeYaw" type="revolute">
    <parent link="HeadRoll_link"/>
    <child link="LEyeYaw_link"/>
    <origin rpy="0 0 0" xyz="0.08948 0.03192 0.05425"/>
    <axis xyz="0 0 1.0"/>
    <limit effort="1.752" lower="-0.523599" upper="0.523599" velocity="293.215"/>
  </joint>
  <link name="LEyeYaw_link">
    <inertial>
      <mass value="0.01"/>
      <inertia ixx="1e-09" ixy="0" ixz="0" iyy="1e-09" iyz="0" izz="1e-09"/>
      <origin rpy="0 -0 1.5708" xyz="0 0 0"/>
    </inertial>
  </link>
  <joint name="LEyePitch" type="revolute">
    <parent link="LEyeYaw_link"/>
    <child link="LEye"/>
    <origin rpy="0 0 0" xyz="0 0 0"/>
    <axis xyz="0 1.0 0"/>
    <limit effort="1.752" lower="-0.349066" upper="0.349066" velocity="293.215"/>
  </joint>
  <link name="LEye">
    <inertial>
      <mass value="0.01"/>
      <inertia ixx="1e-09" ixy="0" ixz="0" iyy="1e-09" iyz="0" izz="1e-09"/>
      <origin rpy="1.5708 -0 -3.14159" xyz="0 0 0"/>
    </inertial>
    <visual>
      <geometry>
        <mesh filename="meshes/LEyePitch.obj" scale="1 1 1"/>
      </geometry>
      <origin rpy="0 0 0" xyz="0 0 0"/>
    </visual>
    <collision>
      <geometry>
        <mesh filename="meshes/LEyePitch_0.10.stl" scale="1 1 1"/>
      </geometry>
      <origin rpy="0 0 0" xyz="0 0 0"/>
    </collision>
  </link>
  <joint name="REyeYaw" type="revolute">
    <parent link="HeadRoll_link"/>
    <child link="REyeYaw_link"/>
    <origin rpy="0 0 0" xyz="0.08948 -0.03192 0.05425"/>
    <axis xyz="0 0 1.0"/>
    <limit effort="1.752" lower="-0.523599" upper="0.523599" velocity="293.215"/>
  </joint>
  <link name="REyeYaw_link">
    <inertial>
      <mass value="0.01"/>
      <inertia ixx="1e-09" ixy="0" ixz="0" iyy="1e-09" iyz="0" izz="1e-09"/>
      <origin rpy="0 -0 1.5708" xyz="0 0 0"/>
    </inertial>
  </link>
  <joint name="REyePitch" type="revolute">
    <parent link="REyeYaw_link"/>
    <child link="REye"/>
    <origin rpy="0 0 0" xyz="0 0 0"/>
    <axis xyz="0 1.0 0"/>
    <limit effort="1.752" lower="-0.349066" upper="0.349066" velocity="293.215"/>
  </joint>
  <link name="REye">
    <inertial>
      <mass value="0.01"/>
      <inertia ixx="1e-09" ixy="0" ixz="0" iyy="1e-09" iyz="0" izz="1e-09"/>
      <origin rpy="1.5708 -0 -3.14159" xyz="0 0 0"/>
    </inertial>
    <visual>
      <geometry>
        <mesh filename="meshes/REyePitch.obj" scale="1 1 1"/>
      </geometry>
      <origin rpy="0 0 0" xyz="0 0 0"/>
    </visual>
    <collision>
      <geometry>
        <mesh filename="meshes/REyePitch_0.10.stl" scale="1 1 1"/>
      </geometry>
      <origin rpy="0 0 0" xyz="0 0 0"/>
    </collision>
  </link>
  <!-- <link name="RFsrFToeRearRight_frame">
    <collision>
      <geometry>
        <box size="0.01 0.01 0.005"/>
      </geometry>
      <origin rpy="0 0 0" xyz="0 0 0"/>
    </collision>
    <inertial>
      <mass value="2e-06"/>
      <inertia ixx="1.1e-09" ixy="0" ixz="0" iyy="1.1e-09" iyz="0" izz="1.1e-09"/>
    </inertial>
  </link>
  <joint name="RFoot/FSR/ToeRearRight_sensor_fixedjoint" type="fixed">
    <parent link="r_ankle"/>
    <child link="RFsrFToeRearRight_frame"/>
    <origin rpy="0 0 0" xyz="0.11898 -0.0335 -0.06226"/>
    <axis xyz="0 0 0"/>
  </joint> -->
  <link name="CameraLeftEye_frame">
    <inertial>
      <mass value="0"/>
      <inertia ixx="0" ixy="0" ixz="0" iyy="0" iyz="0" izz="0"/>
      <origin rpy="0 0 0" xyz="0 0 0"/>
    </inertial>
  </link>
  <joint name="CameraLeftEye_sensor_fixedjoint" type="fixed">
    <parent link="LEye"/>
    <child link="CameraLeftEye_frame"/>
    <origin rpy="0 0 0" xyz="0.01299 0 0"/>
    <axis xyz="0 0 0"/>
  </joint>
  <link name="ImuHeadGyrometer_frame">
    <inertial>
      <mass value="0"/>
      <inertia ixx="0" ixy="0" ixz="0" iyy="0" iyz="0" izz="0"/>
      <origin rpy="0 0 0" xyz="0 0 0"/>
    </inertial>
  </link>
  <joint name="GyrometerHead_sensor_fixedjoint" type="fixed">
    <parent link="HeadRoll_link"/>
    <child link="ImuHeadGyrometer_frame"/>
    <origin rpy="0 0 1.5708" xyz="-0.01135 -0.04225 0.16011"/>
    <axis xyz="0 0 0"/>
  </joint>
  <!-- <link name="RFsrRearCenter_frame">
    <collision>
      <geometry>
        <box size="0.01 0.01 0.005"/>
      </geometry>
      <origin rpy="0 0 0" xyz="0 0 0"/>
    </collision>
    <inertial>
      <mass value="2e-06"/>
      <inertia ixx="1.1e-09" ixy="0" ixz="0" iyy="1.1e-09" iyz="0" izz="1.1e-09"/>
    </inertial>
  </link>
  <joint name="RFoot/FSR/CenterRear_sensor_fixedjoint" type="fixed">
    <parent link="r_ankle"/>
    <child link="RFsrRearCenter_frame"/>
    <origin rpy="0 0 0" xyz="0.01448 -0.0145 -0.06226"/>
    <axis xyz="0 0 0"/>
  </joint> -->
  <!-- <link name="RFsrFrontCenter_frame">
    <collision>
      <geometry>
        <box size="0.01 0.01 0.005"/>
      </geometry>
      <origin rpy="0 0 0" xyz="0 0 0"/>
    </collision>
    <inertial>
      <mass value="2e-06"/>
      <inertia ixx="1.1e-09" ixy="0" ixz="0" iyy="1.1e-09" iyz="0" izz="1.1e-09"/>
    </inertial>
  </link>
  <joint name="RFoot/FSR/CenterFront_sensor_fixedjoint" type="fixed">
    <parent link="r_ankle"/>
    <child link="RFsrFrontCenter_frame"/>
    <origin rpy="0 0 0" xyz="0.07498 -0.01275 -0.06226"/>
    <axis xyz="0 0 0"/>
  </joint> -->
  <link name="CameraLeftEye_optical_frame">
    <inertial>
      <mass value="0"/>
      <inertia ixx="0" ixy="0" ixz="0" iyy="0" iyz="0" izz="0"/>
      <origin rpy="0 0 0" xyz="0 0 0"/>
    </inertial>
  </link>
  <joint name="CameraLeftEye_optical_frame_fixedjoint" type="fixed">
    <parent link="CameraLeftEye_frame"/>
    <child link="CameraLeftEye_optical_frame"/>
    <origin rpy="-1.57079632679 0 -1.57079632679" xyz="0 0 0"/>
  </joint>
  <!-- <link name="LFsrHeelRight_frame">
    <collision>
      <geometry>
        <box size="0.01 0.01 0.005"/>
      </geometry>
      <origin rpy="0 0 0" xyz="0 0 0"/>
    </collision>
    <inertial>
      <mass value="2e-06"/>
      <inertia ixx="1.1e-09" ixy="0" ixz="0" iyy="1.1e-09" iyz="0" izz="1.1e-09"/>
    </inertial>
  </link>
  <joint name="LFoot/FSR/HeelRight_sensor_fixedjoint" type="fixed">
    <parent link="l_ankle"/>
    <child link="LFsrHeelRight_frame"/>
    <origin rpy="0 0 0" xyz="-0.04602 -0.017 -0.06226"/>
    <axis xyz="0 0 0"/>
  </joint> -->
  <link name="CameraRightEye_frame">
    <inertial>
      <mass value="0"/>
      <inertia ixx="0" ixy="0" ixz="0" iyy="0" iyz="0" izz="0"/>
      <origin rpy="0 0 0" xyz="0 0 0"/>
    </inertial>
  </link>
  <joint name="CameraRightEye_sensor_fixedjoint" type="fixed">
    <parent link="REye"/>
    <child link="CameraRightEye_frame"/>
    <origin rpy="0 0 0" xyz="0.01299 0 0"/>
    <axis xyz="0 0 0"/>
  </joint>
  <link name="CameraRight_optical_frame">
    <inertial>
      <mass value="0"/>
      <inertia ixx="0" ixy="0" ixz="0" iyy="0" iyz="0" izz="0"/>
      <origin rpy="0 0 0" xyz="0 0 0"/>
    </inertial>
  </link>
  <joint name="CameraRight_optical_frame_fixedjoint" type="fixed">
    <parent link="CameraRight_frame"/>
    <child link="CameraRight_optical_frame"/>
    <origin rpy="-1.57079632679 0 -1.57079632679" xyz="0 0 0"/>
  </joint>
  <link name="CameraRightEye_optical_frame">
    <inertial>
      <mass value="0"/>
      <inertia ixx="0" ixy="0" ixz="0" iyy="0" iyz="0" izz="0"/>
      <origin rpy="0 0 0" xyz="0 0 0"/>
    </inertial>
  </link>
  <joint name="CameraRightEye_optical_frame_fixedjoint" type="fixed">
    <parent link="CameraRightEye_frame"/>
    <child link="CameraRightEye_optical_frame"/>
    <origin rpy="-1.57079632679 0 -1.57079632679" xyz="0 0 0"/>
  </joint>
  <!-- <link name="RFsrFToeFrontRight_frame">
    <collision>
      <geometry>
        <box size="0.01 0.01 0.005"/>
      </geometry>
      <origin rpy="0 0 0" xyz="0 0 0"/>
    </collision>
    <inertial>
      <mass value="2e-06"/>
      <inertia ixx="1.1e-09" ixy="0" ixz="0" iyy="1.1e-09" iyz="0" izz="1.1e-09"/>
    </inertial>
  </link>
  <joint name="RFoot/FSR/ToeFrontRight_sensor_fixedjoint" type="fixed">
    <parent link="r_ankle"/>
    <child link="RFsrFToeFrontRight_frame"/>
    <origin rpy="0 0 0" xyz="0.16098 -0.024 -0.06226"/>
    <axis xyz="0 0 0"/>
  </joint> -->
  <!-- <link name="RFsrHeelRight_frame">
    <collision>
      <geometry>
        <box size="0.01 0.01 0.005"/>
      </geometry>
      <origin rpy="0 0 0" xyz="0 0 0"/>
    </collision>
    <inertial>
      <mass value="2e-06"/>
      <inertia ixx="1.1e-09" ixy="0" ixz="0" iyy="1.1e-09" iyz="0" izz="1.1e-09"/>
    </inertial>
  </link>
  <joint name="RFoot/FSR/HeelRight_sensor_fixedjoint" type="fixed">
    <parent link="r_ankle"/>
    <child link="RFsrHeelRight_frame"/>
    <origin rpy="0 0 0" xyz="-0.04602 -0.017 -0.06226"/>
    <axis xyz="0 0 0"/>
  </joint> -->
  <!-- <link name="RFsrFToeRearLeft_frame">
    <collision>
      <geometry>
        <box size="0.01 0.01 0.005"/>
      </geometry>
      <origin rpy="0 0 0" xyz="0 0 0"/>
    </collision>
    <inertial>
      <mass value="2e-06"/>
      <inertia ixx="1.1e-09" ixy="0" ixz="0" iyy="1.1e-09" iyz="0" izz="1.1e-09"/>
    </inertial>
  </link>
  <joint name="RFoot/FSR/ToeRearLeft_sensor_fixedjoint" type="fixed">
    <parent link="r_ankle"/>
    <child link="RFsrFToeRearLeft_frame"/>
    <origin rpy="0 0 0" xyz="0.12698 0.0315 -0.06226"/>
    <axis xyz="0 0 0"/>
  </joint> -->
  <link name="ImuTorsoAccelerometer_frame">
    <inertial>
      <mass value="0"/>
      <inertia ixx="0" ixy="0" ixz="0" iyy="0" iyz="0" izz="0"/>
      <origin rpy="0 0 0" xyz="0 0 0"/>
    </inertial>
  </link>
  <joint name="AccelerometerDownTorso_sensor_fixedjoint" type="fixed">
    <parent link="body"/>
    <child link="ImuTorsoAccelerometer_frame"/>
    <origin rpy="0 0 0" xyz="0.06185 0.0087 -0.1582"/>
    <axis xyz="0 0 0"/>
  </joint>
  <!-- <link name="LFsrFToeRearRight_frame">
    <collision>
      <geometry>
        <box size="0.01 0.01 0.005"/>
      </geometry>
      <origin rpy="0 0 0" xyz="0 0 0"/>
    </collision>
    <inertial>
      <mass value="2e-06"/>
      <inertia ixx="1.1e-09" ixy="0" ixz="0" iyy="1.1e-09" iyz="0" izz="1.1e-09"/>
    </inertial>
  </link>
  <joint name="LFoot/FSR/ToeRearRight_sensor_fixedjoint" type="fixed">
    <parent link="l_ankle"/>
    <child link="LFsrFToeRearRight_frame"/>
    <origin rpy="0 0 0" xyz="0.12698 -0.0315 -0.06226"/>
    <axis xyz="0 0 0"/>
  </joint> -->
  <!-- <link name="LFsrHeelLeft_frame">
    <collision>
      <geometry>
        <box size="0.01 0.01 0.005"/>
      </geometry>
      <origin rpy="0 0 0" xyz="0 0 0"/>
    </collision>
    <inertial>
      <mass value="2e-06"/>
      <inertia ixx="1.1e-09" ixy="0" ixz="0" iyy="1.1e-09" iyz="0" izz="1.1e-09"/>
    </inertial>
  </link>
  <joint name="LFoot/FSR/HeelLeft_sensor_fixedjoint" type="fixed">
    <parent link="l_ankle"/>
    <child link="LFsrHeelLeft_frame"/>
    <origin rpy="0 0 0" xyz="-0.04602 0.017 -0.06226"/>
    <axis xyz="0 0 0"/>
  </joint> -->
  <link name="CameraRight_frame">
    <inertial>
      <mass value="0"/>
      <inertia ixx="0" ixy="0" ixz="0" iyy="0" iyz="0" izz="0"/>
      <origin rpy="0 0 0" xyz="0 0 0"/>
    </inertial>
  </link>
  <joint name="CameraRight_sensor_fixedjoint" type="fixed">
    <parent link="HeadRoll_link"/>
    <child link="CameraRight_frame"/>
    <origin rpy="0 0 0" xyz="0.11229 -0.04 0.09938"/>
    <axis xyz="0 0 0"/>
  </joint>
  <link name="ImuTorsoGyrometer_frame">
    <inertial>
      <mass value="0"/>
      <inertia ixx="0" ixy="0" ixz="0" iyy="0" iyz="0" izz="0"/>
      <origin rpy="0 0 0" xyz="0 0 0"/>
    </inertial>
  </link>
  <joint name="GyrometerDownTorso_sensor_fixedjoint" type="fixed">
    <parent link="body"/>
    <child link="ImuTorsoGyrometer_frame"/>
    <origin rpy="0 0 0" xyz="0.06185 0.0087 -0.1582"/>
    <axis xyz="0 0 0"/>
  </joint>
  <!-- <link name="LFsrFToeRearLeft_frame">
    <collision>
      <geometry>
        <box size="0.01 0.01 0.005"/>
      </geometry>
      <origin rpy="0 0 0" xyz="0 0 0"/>
    </collision>
    <inertial>
      <mass value="2e-06"/>
      <inertia ixx="1.1e-09" ixy="0" ixz="0" iyy="1.1e-09" iyz="0" izz="1.1e-09"/>
    </inertial>
  </link>
  <joint name="LFoot/FSR/ToeRearLeft_sensor_fixedjoint" type="fixed">
    <parent link="l_ankle"/>
    <child link="LFsrFToeRearLeft_frame"/>
    <origin rpy="0 0 0" xyz="0.11898 0.0335 -0.06226"/>
    <axis xyz="0 0 0"/>
  </joint> -->
  <!-- <link name="LFsrRearCenter_frame">
    <collision>
      <geometry>
        <box size="0.01 0.01 0.005"/>
      </geometry>
      <origin rpy="0 0 0" xyz="0 0 0"/>
    </collision>
    <inertial>
      <mass value="2e-06"/>
      <inertia ixx="1.1e-09" ixy="0" ixz="0" iyy="1.1e-09" iyz="0" izz="1.1e-09"/>
    </inertial>
  </link>
  <joint name="LFoot/FSR/CenterRear_sensor_fixedjoint" type="fixed">
    <parent link="l_ankle"/>
    <child link="LFsrRearCenter_frame"/>
    <origin rpy="0 0 0" xyz="0.01448 0.0145 -0.06226"/>
    <axis xyz="0 0 0"/>
  </joint> -->
  <link name="CameraLeft_frame">
    <inertial>
      <mass value="0"/>
      <inertia ixx="0" ixy="0" ixz="0" iyy="0" iyz="0" izz="0"/>
      <origin rpy="0 0 0" xyz="0 0 0"/>
    </inertial>
  </link>
  <joint name="CameraLeft_sensor_fixedjoint" type="fixed">
    <parent link="HeadRoll_link"/>
    <child link="CameraLeft_frame"/>
    <origin rpy="0 0 0" xyz="0.11229 0.04 0.09938"/>
    <axis xyz="0 0 0"/>
  </joint>
  <link name="CameraLeft_optical_frame">
    <inertial>
      <mass value="0"/>
      <inertia ixx="0" ixy="0" ixz="0" iyy="0" iyz="0" izz="0"/>
      <origin rpy="0 0 0" xyz="0 0 0"/>
    </inertial>
  </link>
  <joint name="CameraLeft_optical_frame_fixedjoint" type="fixed">
    <parent link="CameraLeft_frame"/>
    <child link="CameraLeft_optical_frame"/>
    <origin rpy="-1.57079632679 0 -1.57079632679" xyz="0 0 0"/>
  </joint>
  <!-- <link name="LFsrFToeFrontRight_frame">
    <collision>
      <geometry>
        <box size="0.01 0.01 0.005"/>
      </geometry>
      <origin rpy="0 0 0" xyz="0 0 0"/>
    </collision>
    <inertial>
      <mass value="2e-06"/>
      <inertia ixx="1.1e-09" ixy="0" ixz="0" iyy="1.1e-09" iyz="0" izz="1.1e-09"/>
    </inertial>
  </link>
  <joint name="LFoot/FSR/ToeFrontRight_sensor_fixedjoint" type="fixed">
    <parent link="l_ankle"/>
    <child link="LFsrFToeFrontRight_frame"/>
    <origin rpy="0 0 0" xyz="0.17298 -0.023 -0.06226"/>
    <axis xyz="0 0 0"/>
  </joint> -->
  <!-- <link name="RFsrHeelLeft_frame">
    <collision>
      <geometry>
        <box size="0.01 0.01 0.005"/>
      </geometry>
      <origin rpy="0 0 0" xyz="0 0 0"/>
    </collision>
    <inertial>
      <mass value="2e-06"/>
      <inertia ixx="1.1e-09" ixy="0" ixz="0" iyy="1.1e-09" iyz="0" izz="1.1e-09"/>
    </inertial>
  </link>
  <joint name="RFoot/FSR/HeelLeft_sensor_fixedjoint" type="fixed">
    <parent link="r_ankle"/>
    <child link="RFsrHeelLeft_frame"/>
    <origin rpy="0 0 0" xyz="-0.04602 0.017 -0.06226"/>
    <axis xyz="0 0 0"/>
  </joint> -->
  <link name="ImuHeadAccelerometer_frame">
    <inertial>
      <mass value="0"/>
      <inertia ixx="0" ixy="0" ixz="0" iyy="0" iyz="0" izz="0"/>
      <origin rpy="0 0 0" xyz="0 0 0"/>
    </inertial>
  </link>
  <joint name="AccelerometerHead_sensor_fixedjoint" type="fixed">
    <parent link="HeadRoll_link"/>
    <child link="ImuHeadAccelerometer_frame"/>
    <origin rpy="0 0 1.5708" xyz="-0.01135 -0.04225 0.16011"/>
    <axis xyz="0 0 0"/>
  </joint>
  <!-- <link name="LFsrFrontCenter_frame">
    <collision>
      <geometry>
        <box size="0.01 0.01 0.005"/>
      </geometry>
      <origin rpy="0 0 0" xyz="0 0 0"/>
    </collision>
    <inertial>
      <mass value="2e-06"/>
      <inertia ixx="1.1e-09" ixy="0" ixz="0" iyy="1.1e-09" iyz="0" izz="1.1e-09"/>
    </inertial>
  </link>
  <joint name="LFoot/FSR/CenterFront_sensor_fixedjoint" type="fixed">
    <parent link="l_ankle"/>
    <child link="LFsrFrontCenter_frame"/>
    <origin rpy="0 0 0" xyz="0.07498 0.01275 -0.06226"/>
    <axis xyz="0 0 0"/>
  </joint> -->
  <!-- <link name="RFsrFToeFrontLeft_frame">
    <collision>
      <geometry>
        <box size="0.01 0.01 0.005"/>
      </geometry>
      <origin rpy="0 0 0" xyz="0 0 0"/>
    </collision>
    <inertial>
      <mass value="2e-06"/>
      <inertia ixx="1.1e-09" ixy="0" ixz="0" iyy="1.1e-09" iyz="0" izz="1.1e-09"/>
    </inertial>
  </link>
  <joint name="RFoot/FSR/ToeFrontLeft_sensor_fixedjoint" type="fixed">
    <parent link="r_ankle"/>
    <child link="RFsrFToeFrontLeft_frame"/>
    <origin rpy="0 0 0" xyz="0.17298 0.023 -0.06226"/>
    <axis xyz="0 0 0"/>
  </joint> -->
  <!-- <link name="LFsrFToeFrontLeft_frame">
    <collision>
      <geometry>
        <box size="0.01 0.01 0.005"/>
      </geometry>
      <origin rpy="0 0 0" xyz="0 0 0"/>
    </collision>
    <inertial>
      <mass value="2e-06"/>
      <inertia ixx="1.1e-09" ixy="0" ixz="0" iyy="1.1e-09" iyz="0" izz="1.1e-09"/>
    </inertial>
  </link>
  <joint name="LFoot/FSR/ToeFrontLeft_sensor_fixedjoint" type="fixed">
    <parent link="l_ankle"/>
    <child link="LFsrFToeFrontLeft_frame"/>
    <origin rpy="0 0 0" xyz="0.16098 0.024 -0.06226"/>
    <axis xyz="0 0 0"/>
  </joint> -->
  <link name="RFinger13_link">
    <inertial>
      <mass value="2e-06"/>
      <inertia ixx="1.1e-09" ixy="0" ixz="0" iyy="1.1e-09" iyz="0" izz="1.1e-09"/>
    </inertial>
    <visual>
      <geometry>
        <mesh filename="meshes/RFinger13.obj" scale="1 1 1"/>
      </geometry>
      <origin rpy="0 0 0" xyz="0 0 0"/>
    </visual>
    <collision>
      <geometry>
        <mesh filename="meshes/RFinger13_0.10.stl" scale="1 1 1"/>
      </geometry>
      <origin rpy="0 0 0" xyz="0 0 0"/>
    </collision>
  </link>
  <joint name="RFinger13" type="revolute">
    <parent link="RFinger12_link"/>
    <child link="RFinger13_link"/>
    <origin rpy="0 0 0" xyz="0 0.0230916 -5.90086e-06"/>
    <axis xyz="0 0 1.0"/>
    <mimic joint="RHand" multiplier="0.988205" offset="0"/>
    <limit effort="0.91" lower="0.0" upper="0.988205" velocity="59.8925"/>
  </joint>
  <link name="RFinger12_link">
    <inertial>
      <mass value="2e-06"/>
      <inertia ixx="1.1e-09" ixy="0" ixz="0" iyy="1.1e-09" iyz="0" izz="1.1e-09"/>
    </inertial>
    <visual>
      <geometry>
        <mesh filename="meshes/RFinger12.obj" scale="1 1 1"/>
      </geometry>
      <origin rpy="0 0 0" xyz="0 0 0"/>
    </visual>
    <collision>
      <geometry>
        <mesh filename="meshes/RFinger12_0.10.stl" scale="1 1 1"/>
      </geometry>
      <origin rpy="0 0 0" xyz="0 0 0"/>
    </collision>
  </link>
  <joint name="RFinger12" type="revolute">
    <parent link="RFinger11_link"/>
    <child link="RFinger12_link"/>
    <origin rpy="0 0 0" xyz="0 0.0230929 4.02331e-06"/>
    <axis xyz="0 0 1.0"/>
    <mimic joint="RHand" multiplier="0.988205" offset="0"/>
    <limit effort="0.91" lower="0.0" upper="0.988205" velocity="59.8925"/>
  </joint>
  <link name="LFinger33_link">
    <inertial>
      <mass value="2e-06"/>
      <inertia ixx="1.1e-09" ixy="0" ixz="0" iyy="1.1e-09" iyz="0" izz="1.1e-09"/>
    </inertial>
    <visual>
      <geometry>
        <mesh filename="meshes/LFinger33.obj" scale="1 1 1"/>
      </geometry>
      <origin rpy="0 0 0" xyz="0 0 0"/>
    </visual>
    <collision>
      <geometry>
        <mesh filename="meshes/LFinger33_0.10.stl" scale="1 1 1"/>
      </geometry>
      <origin rpy="0 0 0" xyz="0 0 0"/>
    </collision>
  </link>
  <joint name="LFinger33" type="revolute">
    <parent link="LFinger32_link"/>
    <child link="LFinger33_link"/>
    <origin rpy="0 0 0" xyz="0 0.0230916 -5.91576e-06"/>
    <axis xyz="0 0 1.0"/>
    <mimic joint="LHand" multiplier="0.988205" offset="0"/>
    <limit effort="0.91" lower="0.0" upper="0.988205" velocity="59.8925"/>
  </joint>
  <link name="RFinger31_link">
    <inertial>
      <mass value="2e-06"/>
      <inertia ixx="1.1e-09" ixy="0" ixz="0" iyy="1.1e-09" iyz="0" izz="1.1e-09"/>
    </inertial>
    <visual>
      <geometry>
        <mesh filename="meshes/RFinger31.obj" scale="1 1 1"/>
      </geometry>
      <origin rpy="0 0 0" xyz="0 0 0"/>
    </visual>
    <collision>
      <geometry>
        <mesh filename="meshes/RFinger31_0.10.stl" scale="1 1 1"/>
      </geometry>
      <origin rpy="0 0 0" xyz="0 0 0"/>
    </collision>
  </link>
  <joint name="RFinger31" type="revolute">
    <parent link="r_wrist"/>
    <child link="RFinger31_link"/>
    <origin rpy="1.69304 1.5708 3.14159" xyz="0.11215 -0.03024 0.00999"/>
    <axis xyz="0 0 1.0"/>
    <mimic joint="RHand" multiplier="0.988205" offset="0"/>
    <limit effort="0.91" lower="0.0" upper="0.988205" velocity="59.8925"/>
  </joint>
  <link name="RFinger32_link">
    <inertial>
      <mass value="2e-06"/>
      <inertia ixx="1.1e-09" ixy="0" ixz="0" iyy="1.1e-09" iyz="0" izz="1.1e-09"/>
    </inertial>
    <visual>
      <geometry>
        <mesh filename="meshes/RFinger32.obj" scale="1 1 1"/>
      </geometry>
      <origin rpy="0 0 0" xyz="0 0 0"/>
    </visual>
    <collision>
      <geometry>
        <mesh filename="meshes/RFinger32_0.10.stl" scale="1 1 1"/>
      </geometry>
      <origin rpy="0 0 0" xyz="0 0 0"/>
    </collision>
  </link>
  <joint name="RFinger32" type="revolute">
    <parent link="RFinger31_link"/>
    <child link="RFinger32_link"/>
    <origin rpy="0 0 0" xyz="0 -0.0230929 -4.02331e-06"/>
    <axis xyz="0 0 1.0"/>
    <mimic joint="RHand" multiplier="0.988205" offset="0"/>
    <limit effort="0.91" lower="0.0" upper="0.988205" velocity="59.8925"/>
  </joint>
  <link name="LFinger21_link">
    <inertial>
      <mass value="2e-06"/>
      <inertia ixx="1.1e-09" ixy="0" ixz="0" iyy="1.1e-09" iyz="0" izz="1.1e-09"/>
    </inertial>
    <visual>
      <geometry>
        <mesh filename="meshes/LFinger21.obj" scale="1 1 1"/>
      </geometry>
      <origin rpy="0 0 0" xyz="0 0 0"/>
    </visual>
    <collision>
      <geometry>
        <mesh filename="meshes/LFinger21_0.10.stl" scale="1 1 1"/>
      </geometry>
      <origin rpy="0 0 0" xyz="0 0 0"/>
    </collision>
  </link>
  <joint name="LFinger21" type="revolute">
    <parent link="l_wrist"/>
    <child link="LFinger21_link"/>
    <origin rpy="1.5708 1.5708 3.14159" xyz="0.12934 0 0.01499"/>
    <axis xyz="0 0 1.0"/>
    <mimic joint="LHand" multiplier="0.988205" offset="0"/>
    <limit effort="0.91" lower="0.0" upper="0.988205" velocity="59.8925"/>
  </joint>
  <link name="LFinger13_link">
    <inertial>
      <mass value="2e-06"/>
      <inertia ixx="1.1e-09" ixy="0" ixz="0" iyy="1.1e-09" iyz="0" izz="1.1e-09"/>
    </inertial>
    <visual>
      <geometry>
        <mesh filename="meshes/LFinger13.obj" scale="1 1 1"/>
      </geometry>
      <origin rpy="0 0 0" xyz="0 0 0"/>
    </visual>
    <collision>
      <geometry>
        <mesh filename="meshes/LFinger13_0.10.stl" scale="1 1 1"/>
      </geometry>
      <origin rpy="0 0 0" xyz="0 0 0"/>
    </collision>
  </link>
  <joint name="LFinger13" type="revolute">
    <parent link="LFinger12_link"/>
    <child link="LFinger13_link"/>
    <origin rpy="0 0 0" xyz="0 -0.0230916 5.90086e-06"/>
    <axis xyz="0 0 1.0"/>
    <mimic joint="LHand" multiplier="0.988205" offset="0"/>
    <limit effort="0.91" lower="0.0" upper="0.988205" velocity="59.8925"/>
  </joint>
  <link name="LFinger32_link">
    <inertial>
      <mass value="2e-06"/>
      <inertia ixx="1.1e-09" ixy="0" ixz="0" iyy="1.1e-09" iyz="0" izz="1.1e-09"/>
    </inertial>
    <visual>
      <geometry>
        <mesh filename="meshes/LFinger32.obj" scale="1 1 1"/>
      </geometry>
      <origin rpy="0 0 0" xyz="0 0 0"/>
    </visual>
    <collision>
      <geometry>
        <mesh filename="meshes/LFinger32_0.10.stl" scale="1 1 1"/>
      </geometry>
      <origin rpy="0 0 0" xyz="0 0 0"/>
    </collision>
  </link>
  <joint name="LFinger32" type="revolute">
    <parent link="LFinger31_link"/>
    <child link="LFinger32_link"/>
    <origin rpy="0 0 0" xyz="0 0.0230928 4.02331e-06"/>
    <axis xyz="0 0 1.0"/>
    <mimic joint="LHand" multiplier="0.988205" offset="0"/>
    <limit effort="0.91" lower="0.0" upper="0.988205" velocity="59.8925"/>
  </joint>
  <link name="LFinger11_link">
    <inertial>
      <mass value="2e-06"/>
      <inertia ixx="1.1e-09" ixy="0" ixz="0" iyy="1.1e-09" iyz="0" izz="1.1e-09"/>
    </inertial>
    <visual>
      <geometry>
        <mesh filename="meshes/LFinger11.obj" scale="1 1 1"/>
      </geometry>
      <origin rpy="0 0 0" xyz="0 0 0"/>
    </visual>
    <collision>
      <geometry>
        <mesh filename="meshes/LFinger11_0.10.stl" scale="1 1 1"/>
      </geometry>
      <origin rpy="0 0 0" xyz="0 0 0"/>
    </collision>
  </link>
  <joint name="LFinger11" type="revolute">
    <parent link="l_wrist"/>
    <child link="LFinger11_link"/>
    <origin rpy="1.69304 1.5708 3.14159" xyz="0.12385 -0.03024 0.00999"/>
    <axis xyz="0 0 1.0"/>
    <mimic joint="LHand" multiplier="0.988205" offset="0"/>
    <limit effort="0.91" lower="0.0" upper="0.988205" velocity="59.8925"/>
  </joint>
  <link name="RFinger22_link">
    <inertial>
      <mass value="2e-06"/>
      <inertia ixx="1.1e-09" ixy="0" ixz="0" iyy="1.1e-09" iyz="0" izz="1.1e-09"/>
    </inertial>
    <visual>
      <geometry>
        <mesh filename="meshes/RFinger22.obj" scale="1 1 1"/>
      </geometry>
      <origin rpy="0 0 0" xyz="0 0 0"/>
    </visual>
    <collision>
      <geometry>
        <mesh filename="meshes/RFinger22_0.10.stl" scale="1 1 1"/>
      </geometry>
      <origin rpy="0 0 0" xyz="0 0 0"/>
    </collision>
  </link>
  <joint name="RFinger22" type="revolute">
    <parent link="RFinger21_link"/>
    <child link="RFinger22_link"/>
    <origin rpy="0 0 0" xyz="0 0.02309 0"/>
    <axis xyz="0 0 1.0"/>
    <mimic joint="RHand" multiplier="0.988205" offset="0"/>
    <limit effort="0.91" lower="0.0" upper="0.988205" velocity="59.8925"/>
  </joint>
  <link name="LFinger22_link">
    <inertial>
      <mass value="2e-06"/>
      <inertia ixx="1.1e-09" ixy="0" ixz="0" iyy="1.1e-09" iyz="0" izz="1.1e-09"/>
    </inertial>
    <visual>
      <geometry>
        <mesh filename="meshes/LFinger22.obj" scale="1 1 1"/>
      </geometry>
      <origin rpy="0 0 0" xyz="0 0 0"/>
    </visual>
    <collision>
      <geometry>
        <mesh filename="meshes/LFinger22_0.10.stl" scale="1 1 1"/>
      </geometry>
      <origin rpy="0 0 0" xyz="0 0 0"/>
    </collision>
  </link>
  <joint name="LFinger22" type="revolute">
    <parent link="LFinger21_link"/>
    <child link="LFinger22_link"/>
    <origin rpy="0 0 0" xyz="0 -0.02309 0"/>
    <axis xyz="0 0 1.0"/>
    <mimic joint="LHand" multiplier="0.988205" offset="0"/>
    <limit effort="0.91" lower="0.0" upper="0.988205" velocity="59.8925"/>
  </joint>
  <link name="RFinger21_link">
    <inertial>
      <mass value="2e-06"/>
      <inertia ixx="1.1e-09" ixy="0" ixz="0" iyy="1.1e-09" iyz="0" izz="1.1e-09"/>
    </inertial>
    <visual>
      <geometry>
        <mesh filename="meshes/RFinger21.obj" scale="1 1 1"/>
      </geometry>
      <origin rpy="0 0 0" xyz="0 0 0"/>
    </visual>
    <collision>
      <geometry>
        <mesh filename="meshes/RFinger21_0.10.stl" scale="1 1 1"/>
      </geometry>
      <origin rpy="0 0 0" xyz="0 0 0"/>
    </collision>
  </link>
  <joint name="RFinger21" type="revolute">
    <parent link="r_wrist"/>
    <child link="RFinger21_link"/>
    <origin rpy="1.5708 -1.5708 -3.14159" xyz="0.12934 0 0.01499"/>
    <axis xyz="0 0 1.0"/>
    <mimic joint="RHand" multiplier="0.988205" offset="0"/>
    <limit effort="0.91" lower="0.0" upper="0.988205" velocity="59.8925"/>
  </joint>
  <link name="LFinger12_link">
    <inertial>
      <mass value="2e-06"/>
      <inertia ixx="1.1e-09" ixy="0" ixz="0" iyy="1.1e-09" iyz="0" izz="1.1e-09"/>
    </inertial>
    <visual>
      <geometry>
        <mesh filename="meshes/LFinger12.obj" scale="1 1 1"/>
      </geometry>
      <origin rpy="0 0 0" xyz="0 0 0"/>
    </visual>
    <collision>
      <geometry>
        <mesh filename="meshes/LFinger12_0.10.stl" scale="1 1 1"/>
      </geometry>
      <origin rpy="0 0 0" xyz="0 0 0"/>
    </collision>
  </link>
  <joint name="LFinger12" type="revolute">
    <parent link="LFinger11_link"/>
    <child link="LFinger12_link"/>
    <origin rpy="0 0 0" xyz="0 -0.0230929 -4.02331e-06"/>
    <axis xyz="0 0 1.0"/>
    <mimic joint="LHand" multiplier="0.988205" offset="0"/>
    <limit effort="0.91" lower="0.0" upper="0.988205" velocity="59.8925"/>
  </joint>
  <link name="RFinger23_link">
    <inertial>
      <mass value="2e-06"/>
      <inertia ixx="1.1e-09" ixy="0" ixz="0" iyy="1.1e-09" iyz="0" izz="1.1e-09"/>
    </inertial>
    <visual>
      <geometry>
        <mesh filename="meshes/RFinger23.obj" scale="1 1 1"/>
      </geometry>
      <origin rpy="0 0 0" xyz="0 0 0"/>
    </visual>
    <collision>
      <geometry>
        <mesh filename="meshes/RFinger23_0.10.stl" scale="1 1 1"/>
      </geometry>
      <origin rpy="0 0 0" xyz="0 0 0"/>
    </collision>
  </link>
  <joint name="RFinger23" type="revolute">
    <parent link="RFinger22_link"/>
    <child link="RFinger23_link"/>
    <origin rpy="0 0 0" xyz="0 0.02309 0"/>
    <axis xyz="0 0 1.0"/>
    <mimic joint="RHand" multiplier="0.988205" offset="0"/>
    <limit effort="0.91" lower="0.0" upper="0.988205" velocity="59.8925"/>
  </joint>
  <link name="RFinger11_link">
    <inertial>
      <mass value="2e-06"/>
      <inertia ixx="1.1e-09" ixy="0" ixz="0" iyy="1.1e-09" iyz="0" izz="1.1e-09"/>
    </inertial>
    <visual>
      <geometry>
        <mesh filename="meshes/RFinger11.obj" scale="1 1 1"/>
      </geometry>
      <origin rpy="0 0 0" xyz="0 0 0"/>
    </visual>
    <collision>
      <geometry>
        <mesh filename="meshes/RFinger11_0.10.stl" scale="1 1 1"/>
      </geometry>
      <origin rpy="0 0 0" xyz="0 0 0"/>
    </collision>
  </link>
  <joint name="RFinger11" type="revolute">
    <parent link="r_wrist"/>
    <child link="RFinger11_link"/>
    <origin rpy="1.69304 -1.5708 3.14159" xyz="0.12385 0.03024 0.00999"/>
    <axis xyz="0 0 1.0"/>
    <mimic joint="RHand" multiplier="0.988205" offset="0"/>
    <limit effort="0.91" lower="0.0" upper="0.988205" velocity="59.8925"/>
  </joint>
  <link name="LFinger23_link">
    <inertial>
      <mass value="2e-06"/>
      <inertia ixx="1.1e-09" ixy="0" ixz="0" iyy="1.1e-09" iyz="0" izz="1.1e-09"/>
    </inertial>
    <visual>
      <geometry>
        <mesh filename="meshes/LFinger23.obj" scale="1 1 1"/>
      </geometry>
      <origin rpy="0 0 0" xyz="0 0 0"/>
    </visual>
    <collision>
      <geometry>
        <mesh filename="meshes/LFinger23_0.10.stl" scale="1 1 1"/>
      </geometry>
      <origin rpy="0 0 0" xyz="0 0 0"/>
    </collision>
  </link>
  <joint name="LFinger23" type="revolute">
    <parent link="LFinger22_link"/>
    <child link="LFinger23_link"/>
    <origin rpy="0 0 0" xyz="0 -0.02309 0"/>
    <axis xyz="0 0 1.0"/>
    <mimic joint="LHand" multiplier="0.988205" offset="0"/>
    <limit effort="0.91" lower="0.0" upper="0.988205" velocity="59.8925"/>
  </joint>
  <link name="LFinger31_link">
    <inertial>
      <mass value="2e-06"/>
      <inertia ixx="1.1e-09" ixy="0" ixz="0" iyy="1.1e-09" iyz="0" izz="1.1e-09"/>
    </inertial>
    <visual>
      <geometry>
        <mesh filename="meshes/LFinger31.obj" scale="1 1 1"/>
      </geometry>
      <origin rpy="0 0 0" xyz="0 0 0"/>
    </visual>
    <collision>
      <geometry>
        <mesh filename="meshes/LFinger31_0.10.stl" scale="1 1 1"/>
      </geometry>
      <origin rpy="0 0 0" xyz="0 0 0"/>
    </collision>
  </link>
  <joint name="LFinger31" type="revolute">
    <parent link="l_wrist"/>
    <child link="LFinger31_link"/>
    <origin rpy="1.69304 -1.5708 3.14159" xyz="0.11215 0.03024 0.00999"/>
    <axis xyz="0 0 1.0"/>
    <mimic joint="LHand" multiplier="0.988205" offset="0"/>
    <limit effort="0.91" lower="0.0" upper="0.988205" velocity="59.8925"/>
  </joint>
  <link name="RFinger33_link">
    <inertial>
      <mass value="2e-06"/>
      <inertia ixx="1.1e-09" ixy="0" ixz="0" iyy="1.1e-09" iyz="0" izz="1.1e-09"/>
    </inertial>
    <visual>
      <geometry>
        <mesh filename="meshes/RFinger33.obj" scale="1 1 1"/>
      </geometry>
      <origin rpy="0 0 0" xyz="0 0 0"/>
    </visual>
    <collision>
      <geometry>
        <mesh filename="meshes/RFinger33_0.10.stl" scale="1 1 1"/>
      </geometry>
      <origin rpy="0 0 0" xyz="0 0 0"/>
    </collision>
  </link>
  <joint name="RFinger33" type="revolute">
    <parent link="RFinger32_link"/>
    <child link="RFinger33_link"/>
    <origin rpy="0 0 0" xyz="0 -0.0230916 5.90086e-06"/>
    <axis xyz="0 0 1.0"/>
    <mimic joint="RHand" multiplier="0.988205" offset="0"/>
    <limit effort="0.91" lower="0.0" upper="0.988205" velocity="59.8925"/>
  </joint>
  <link name="LThumb3_link">
    <inertial>
      <mass value="2e-06"/>
      <inertia ixx="1.1e-09" ixy="0" ixz="0" iyy="1.1e-09" iyz="0" izz="1.1e-09"/>
    </inertial>
    <visual>
      <geometry>
        <mesh filename="meshes/LThumb3.obj" scale="1 1 1"/>
      </geometry>
      <origin rpy="0 0 0" xyz="0 0 0"/>
    </visual>
    <collision>
      <geometry>
        <mesh filename="meshes/LThumb3_0.10.stl" scale="1 1 1"/>
      </geometry>
      <origin rpy="0 0 0" xyz="0 0 0"/>
    </collision>
  </link>
  <joint name="LThumb3" type="revolute">
    <parent link="LThumb2_link"/>
    <child link="LThumb3_link"/>
    <origin rpy="-5.96047e-08 0 1.49012e-08" xyz="0.0187362 0.0135152 5.21541e-06"/>
    <axis xyz="0 0 1.0"/>
    <mimic joint="LHand" multiplier="0.988205" offset="0"/>
    <limit effort="0.91" lower="0.0" upper="0.988205" velocity="59.8925"/>
  </joint>
  <link name="LThumb1_link">
    <inertial>
      <mass value="2e-06"/>
      <inertia ixx="1.1e-09" ixy="0" ixz="0" iyy="1.1e-09" iyz="0" izz="1.1e-09"/>
    </inertial>
    <visual>
      <geometry>
        <mesh filename="meshes/LThumb1.obj" scale="1 1 1"/>
      </geometry>
      <origin rpy="0 0 0" xyz="0 0 0"/>
    </visual>
    <collision>
      <geometry>
        <mesh filename="meshes/LThumb1_0.10.stl" scale="1 1 1"/>
      </geometry>
      <origin rpy="0 0 0" xyz="0 0 0"/>
    </collision>
  </link>
  <joint name="LThumb1" type="revolute">
    <parent link="l_wrist"/>
    <child link="LThumb1_link"/>
    <origin rpy="-2.97779 1.21665 -3.14159" xyz="0.0624 -0.03131 -0.00574"/>
    <axis xyz="0 0 1.0"/>
    <mimic joint="LHand" multiplier="1.74533" offset="0"/>
    <limit effort="0.91" lower="0.0" upper="1.74533" velocity="59.8925"/>
  </joint>
  <link name="RThumb1_link">
    <inertial>
      <mass value="2e-06"/>
      <inertia ixx="1.1e-09" ixy="0" ixz="0" iyy="1.1e-09" iyz="0" izz="1.1e-09"/>
    </inertial>
    <visual>
      <geometry>
        <mesh filename="meshes/RThumb1.obj" scale="1 1 1"/>
      </geometry>
      <origin rpy="0 0 0" xyz="0 0 0"/>
    </visual>
    <collision>
      <geometry>
        <mesh filename="meshes/RThumb1_0.10.stl" scale="1 1 1"/>
      </geometry>
      <origin rpy="0 0 0" xyz="0 0 0"/>
    </collision>
  </link>
  <joint name="RThumb1" type="revolute">
    <parent link="r_wrist"/>
    <child link="RThumb1_link"/>
    <origin rpy="0.1638 -1.21665 0" xyz="0.0624 0.03131 -0.00574"/>
    <axis xyz="0 0 1.0"/>
    <mimic joint="RHand" multiplier="1.74533" offset="0"/>
    <limit effort="0.91" lower="0.0" upper="1.74533" velocity="59.8925"/>
  </joint>
  <link name="RThumb2_link">
    <inertial>
      <mass value="2e-06"/>
      <inertia ixx="1.1e-09" ixy="0" ixz="0" iyy="1.1e-09" iyz="0" izz="1.1e-09"/>
    </inertial>
    <visual>
      <geometry>
        <mesh filename="meshes/RThumb2.obj" scale="1 1 1"/>
      </geometry>
      <origin rpy="0 0 0" xyz="0 0 0"/>
    </visual>
    <collision>
      <geometry>
        <mesh filename="meshes/RThumb2_0.10.stl" scale="1 1 1"/>
      </geometry>
      <origin rpy="0 0 0" xyz="0 0 0"/>
    </collision>
  </link>
  <joint name="RThumb2" type="revolute">
    <parent link="RThumb1_link"/>
    <child link="RThumb2_link"/>
    <origin rpy="1.13316 0 -1.80698" xyz="-0.000329241 0.0388865 -0.017011"/>
    <axis xyz="0 0 1.0"/>
    <mimic joint="RHand" multiplier="0.988205" offset="0"/>
    <limit effort="0.91" lower="0.0" upper="0.988205" velocity="59.8925"/>
  </joint>
  <link name="LThumb2_link">
    <inertial>
      <mass value="2e-06"/>
      <inertia ixx="1.1e-09" ixy="0" ixz="0" iyy="1.1e-09" iyz="0" izz="1.1e-09"/>
    </inertial>
    <visual>
      <geometry>
        <mesh filename="meshes/LThumb2.obj" scale="1 1 1"/>
      </geometry>
      <origin rpy="0 0 0" xyz="0 0 0"/>
    </visual>
    <collision>
      <geometry>
        <mesh filename="meshes/LThumb2_0.10.stl" scale="1 1 1"/>
      </geometry>
      <origin rpy="0 0 0" xyz="0 0 0"/>
    </collision>
  </link>
  <joint name="LThumb2" type="revolute">
    <parent link="LThumb1_link"/>
    <child link="LThumb2_link"/>
    <origin rpy="1.13316 7.45058e-09 -1.80698" xyz="0.000329241 -0.0388865 0.017011"/>
    <axis xyz="0 0 1.0"/>
    <mimic joint="LHand" multiplier="0.988205" offset="0"/>
    <limit effort="0.91" lower="0.0" upper="0.988205" velocity="59.8925"/>
  </joint>
  <link name="RThumb3_link">
    <inertial>
      <mass value="2e-06"/>
      <inertia ixx="1.1e-09" ixy="0" ixz="0" iyy="1.1e-09" iyz="0" izz="1.1e-09"/>
    </inertial>
    <visual>
      <geometry>
        <mesh filename="meshes/RThumb3.obj" scale="1 1 1"/>
      </geometry>
      <origin rpy="0 0 0" xyz="0 0 0"/>
    </visual>
    <collision>
      <geometry>
        <mesh filename="meshes/RThumb3_0.10.stl" scale="1 1 1"/>
      </geometry>
      <origin rpy="0 0 0" xyz="0 0 0"/>
    </collision>
  </link>
  <joint name="RThumb3" type="revolute">
    <parent link="RThumb2_link"/>
    <child link="RThumb3_link"/>
    <origin rpy="-5.96047e-08 -1.49012e-08 1.49012e-08" xyz="-0.0187362 -0.0135152 -5.21541e-06"/>
    <axis xyz="0 0 1.0"/>
    <mimic joint="RHand" multiplier="0.988205" offset="0"/>
    <limit effort="0.91" lower="0.0" upper="0.988205" velocity="59.8925"/>
  </joint>
  <link name="CameraDepth_frame">
    <inertial>
      <mass value="0"/>
      <inertia ixx="0" ixy="0" ixz="0" iyy="0" iyz="0" izz="0"/>
      <origin rpy="0 0 0" xyz="0 0 0"/>
    </inertial>
  </link>
  <joint name="CameraDepth_joint" type="fixed">
    <parent link="HeadRoll_link"/>
    <child link="CameraDepth_frame"/>
    <origin rpy="0 0 0" xyz="0.1403 -0.04708 0.14655"/>
  </joint>
  <link name="CameraDepth_optical_frame">
    <inertial>
      <mass value="0"/>
      <inertia ixx="0" ixy="0" ixz="0" iyy="0" iyz="0" izz="0"/>
      <origin rpy="0 0 0" xyz="0 0 0"/>
    </inertial>
  </link>
  <joint name="CameraDepth_optical_frame_fixedjoint" type="fixed">
    <parent link="CameraDepth_frame"/>
    <child link="CameraDepth_optical_frame"/>
    <origin rpy="2.0043951 0 1.57079632679" xyz="0 0 0"/>
  </joint>
  <!-- <link name="Cap">
    <inertial>
      <mass value="0.29923"/>
      <inertia ixx="0.000412832" ixy="-1.67846e-06" ixz="0.000111721" iyy="0.000383921" iyz="5.04259e-05" izz="0.000264006"/>
      <origin rpy="0 0 0" xyz="0 0 0"/>
    </inertial>
    <visual>
      <geometry>
        <mesh filename="meshes/Cap.dae" scale="1 1 1"/>
      </geometry>
      <origin rpy="0 0 0" xyz="0 0 0"/>
    </visual>
  </link>
  <joint name="Cap_joint" type="fixed">
    <parent link="HeadRoll_link"/>
    <child link="Cap"/>
    <origin rpy="0 0 0" xyz="0 0 0"/>
  </joint> -->
  <!-- MACROS FOR DISABLE LINKS -->
  <!-- MACROS FOR MIMIC JOINTS -->
  <!-- Fingers -->
  <!-- Thumbs -->
  <!-- GAZEBO ROS CONTROL AND IMU PLUGIN -->
  <gazebo>
    <plugin filename="libgazebo_ros_control.so" name="gazebo_ros_control">
      <robotNamespace/>
      <robotSimType>gazebo_ros_control/DefaultRobotHWSim</robotSimType>
    </plugin>
    <plugin filename="libroboticsgroup_gazebo_mimic_joint_plugin.so" name="mimic_LFinger11">
      <joint>LHand</joint>
      <mimicJoint>LFinger11</mimicJoint>
      <multiplier>-0.785398163398</multiplier>
      <offset>0.785398163398</offset>
    </plugin>
    <plugin filename="libroboticsgroup_gazebo_mimic_joint_plugin.so" name="mimic_LFinger12">
      <joint>LHand</joint>
      <mimicJoint>LFinger12</mimicJoint>
      <multiplier>-0.785398163398</multiplier>
      <offset>0.785398163398</offset>
    </plugin>
    <plugin filename="libroboticsgroup_gazebo_mimic_joint_plugin.so" name="mimic_LFinger13">
      <joint>LHand</joint>
      <mimicJoint>LFinger13</mimicJoint>
      <multiplier>-0.785398163398</multiplier>
      <offset>0.785398163398</offset>
    </plugin>
    <plugin filename="libroboticsgroup_gazebo_mimic_joint_plugin.so" name="mimic_LFinger21">
      <joint>LHand</joint>
      <mimicJoint>LFinger21</mimicJoint>
      <multiplier>-0.785398163398</multiplier>
      <offset>0.785398163398</offset>
    </plugin>
    <plugin filename="libroboticsgroup_gazebo_mimic_joint_plugin.so" name="mimic_LFinger22">
      <joint>LHand</joint>
      <mimicJoint>LFinger22</mimicJoint>
      <multiplier>-0.785398163398</multiplier>
      <offset>0.785398163398</offset>
    </plugin>
    <plugin filename="libroboticsgroup_gazebo_mimic_joint_plugin.so" name="mimic_LFinger23">
      <joint>LHand</joint>
      <mimicJoint>LFinger23</mimicJoint>
      <multiplier>-0.785398163398</multiplier>
      <offset>0.785398163398</offset>
    </plugin>
    <plugin filename="libroboticsgroup_gazebo_mimic_joint_plugin.so" name="mimic_LFinger31">
      <joint>LHand</joint>
      <mimicJoint>LFinger31</mimicJoint>
      <multiplier>-0.785398163398</multiplier>
      <offset>0.785398163398</offset>
    </plugin>
    <plugin filename="libroboticsgroup_gazebo_mimic_joint_plugin.so" name="mimic_LFinger32">
      <joint>LHand</joint>
      <mimicJoint>LFinger32</mimicJoint>
      <multiplier>-0.785398163398</multiplier>
      <offset>0.785398163398</offset>
    </plugin>
    <plugin filename="libroboticsgroup_gazebo_mimic_joint_plugin.so" name="mimic_LFinger33">
      <joint>LHand</joint>
      <mimicJoint>LFinger33</mimicJoint>
      <multiplier>-0.785398163398</multiplier>
      <offset>0.785398163398</offset>
    </plugin>
    <plugin filename="libroboticsgroup_gazebo_mimic_joint_plugin.so" name="mimic_RFinger11">
      <joint>RHand</joint>
      <mimicJoint>RFinger11</mimicJoint>
      <multiplier>-0.785398163398</multiplier>
      <offset>0.785398163398</offset>
    </plugin>
    <plugin filename="libroboticsgroup_gazebo_mimic_joint_plugin.so" name="mimic_RFinger12">
      <joint>RHand</joint>
      <mimicJoint>RFinger12</mimicJoint>
      <multiplier>-0.785398163398</multiplier>
      <offset>0.785398163398</offset>
    </plugin>
    <plugin filename="libroboticsgroup_gazebo_mimic_joint_plugin.so" name="mimic_RFinger13">
      <joint>RHand</joint>
      <mimicJoint>RFinger13</mimicJoint>
      <multiplier>-0.785398163398</multiplier>
      <offset>0.785398163398</offset>
    </plugin>
    <plugin filename="libroboticsgroup_gazebo_mimic_joint_plugin.so" name="mimic_RFinger21">
      <joint>RHand</joint>
      <mimicJoint>RFinger21</mimicJoint>
      <multiplier>-0.785398163398</multiplier>
      <offset>0.785398163398</offset>
    </plugin>
    <plugin filename="libroboticsgroup_gazebo_mimic_joint_plugin.so" name="mimic_RFinger22">
      <joint>RHand</joint>
      <mimicJoint>RFinger22</mimicJoint>
      <multiplier>-0.785398163398</multiplier>
      <offset>0.785398163398</offset>
    </plugin>
    <plugin filename="libroboticsgroup_gazebo_mimic_joint_plugin.so" name="mimic_RFinger23">
      <joint>RHand</joint>
      <mimicJoint>RFinger23</mimicJoint>
      <multiplier>-0.785398163398</multiplier>
      <offset>0.785398163398</offset>
    </plugin>
    <plugin filename="libroboticsgroup_gazebo_mimic_joint_plugin.so" name="mimic_RFinger31">
      <joint>RHand</joint>
      <mimicJoint>RFinger31</mimicJoint>
      <multiplier>-0.785398163398</multiplier>
      <offset>0.785398163398</offset>
    </plugin>
    <plugin filename="libroboticsgroup_gazebo_mimic_joint_plugin.so" name="mimic_RFinger32">
      <joint>RHand</joint>
      <mimicJoint>RFinger32</mimicJoint>
      <multiplier>-0.785398163398</multiplier>
      <offset>0.785398163398</offset>
    </plugin>
    <plugin filename="libroboticsgroup_gazebo_mimic_joint_plugin.so" name="mimic_RFinger33">
      <joint>RHand</joint>
      <mimicJoint>RFinger33</mimicJoint>
      <multiplier>-0.785398163398</multiplier>
      <offset>0.785398163398</offset>
    </plugin>
    <plugin filename="libroboticsgroup_gazebo_mimic_joint_plugin.so" name="LThumb1">
      <joint>LHand</joint>
      <mimicJoint>LThumb1</mimicJoint>
      <multiplier>-0.785398163398</multiplier>
      <offset>0.785398163398</offset>
    </plugin>
    <plugin filename="libroboticsgroup_gazebo_mimic_joint_plugin.so" name="LThumb2">
      <joint>LHand</joint>
      <mimicJoint>LThumb2</mimicJoint>
      <multiplier>-0.785398163398</multiplier>
      <offset>0.785398163398</offset>
    </plugin>
    <plugin filename="libroboticsgroup_gazebo_mimic_joint_plugin.so" name="RThumb1">
      <joint>RHand</joint>
      <mimicJoint>RThumb1</mimicJoint>
      <multiplier>-0.785398163398</multiplier>
      <offset>0.785398163398</offset>
    </plugin>
    <plugin filename="libroboticsgroup_gazebo_mimic_joint_plugin.so" name="RThumb2">
      <joint>RHand</joint>
      <mimicJoint>RThumb2</mimicJoint>
      <multiplier>-0.785398163398</multiplier>
      <offset>0.785398163398</offset>
    </plugin>
    <plugin filename="libroboticsgroup_gazebo_disable_link_plugin.so" name="LFinger11_link">
      <link>LFinger11_link</link>
    </plugin>
    <plugin filename="libroboticsgroup_gazebo_disable_link_plugin.so" name="LFinger12_link">
      <link>LFinger12_link</link>
    </plugin>
    <plugin filename="libroboticsgroup_gazebo_disable_link_plugin.so" name="LFinger13_link">
      <link>LFinger13_link</link>
    </plugin>
    <plugin filename="libroboticsgroup_gazebo_disable_link_plugin.so" name="LFinger21_link">
      <link>LFinger21_link</link>
    </plugin>
    <plugin filename="libroboticsgroup_gazebo_disable_link_plugin.so" name="LFinger22_link">
      <link>LFinger22_link</link>
    </plugin>
    <plugin filename="libroboticsgroup_gazebo_disable_link_plugin.so" name="LFinger23_link">
      <link>LFinger23_link</link>
    </plugin>
    <plugin filename="libroboticsgroup_gazebo_disable_link_plugin.so" name="LFinger31_link">
      <link>LFinger31_link</link>
    </plugin>
    <plugin filename="libroboticsgroup_gazebo_disable_link_plugin.so" name="LFinger32_link">
      <link>LFinger32_link</link>
    </plugin>
    <plugin filename="libroboticsgroup_gazebo_disable_link_plugin.so" name="LFinger33_link">
      <link>LFinger33_link</link>
    </plugin>
    <plugin filename="libroboticsgroup_gazebo_disable_link_plugin.so" name="LThumb1_link">
      <link>LThumb1_link</link>
    </plugin>
    <plugin filename="libroboticsgroup_gazebo_disable_link_plugin.so" name="LThumb2_link">
      <link>LThumb2_link</link>
    </plugin>
    <plugin filename="libroboticsgroup_gazebo_disable_link_plugin.so" name="l_gripper">
      <link>l_gripper</link>
    </plugin>
    <plugin filename="libroboticsgroup_gazebo_disable_link_plugin.so" name="RFinger11_link">
      <link>RFinger11_link</link>
    </plugin>
    <plugin filename="libroboticsgroup_gazebo_disable_link_plugin.so" name="RFinger12_link">
      <link>RFinger12_link</link>
    </plugin>
    <plugin filename="libroboticsgroup_gazebo_disable_link_plugin.so" name="RFinger13_link">
      <link>RFinger13_link</link>
    </plugin>
    <plugin filename="libroboticsgroup_gazebo_disable_link_plugin.so" name="RFinger21_link">
      <link>RFinger21_link</link>
    </plugin>
    <plugin filename="libroboticsgroup_gazebo_disable_link_plugin.so" name="RFinger22_link">
      <link>RFinger22_link</link>
    </plugin>
    <plugin filename="libroboticsgroup_gazebo_disable_link_plugin.so" name="RFinger23_link">
      <link>RFinger23_link</link>
    </plugin>
    <plugin filename="libroboticsgroup_gazebo_disable_link_plugin.so" name="RFinger31_link">
      <link>RFinger31_link</link>
    </plugin>
    <plugin filename="libroboticsgroup_gazebo_disable_link_plugin.so" name="RFinger32_link">
      <link>RFinger32_link</link>
    </plugin>
    <plugin filename="libroboticsgroup_gazebo_disable_link_plugin.so" name="RFinger33_link">
      <link>RFinger33_link</link>
    </plugin>
    <plugin filename="libroboticsgroup_gazebo_disable_link_plugin.so" name="RThumb1_link">
      <link>RThumb1_link</link>
    </plugin>
    <plugin filename="libroboticsgroup_gazebo_disable_link_plugin.so" name="RThumb2_link">
      <link>RThumb2_link</link>
    </plugin>
    <plugin filename="libroboticsgroup_gazebo_disable_link_plugin.so" name="r_gripper">
      <link>r_gripper</link>
    </plugin>
  </gazebo>
  <!-- END OF GAZEBO ROS CONTROL PLUGIN -->
  <!-- GAZEBO MATERIALS -->
  <gazebo reference="torso">
    <mu1>0.5</mu1>
    <mu2>0.5</mu2>
    <selfCollide>false</selfCollide>
    <turnGravityOff>false</turnGravityOff>
  </gazebo>
  <gazebo reference="body">
    <mu1>0.5</mu1>
    <mu2>0.5</mu2>
    <selfCollide>false</selfCollide>
    <turnGravityOff>false</turnGravityOff>
  </gazebo>
  <gazebo reference="Neck">
    <mu1>0.5</mu1>
    <mu2>0.5</mu2>
    <selfCollide>false</selfCollide>
    <turnGravityOff>false</turnGravityOff>
  </gazebo>
  <gazebo reference="Head">
    <mu1>0.5</mu1>
    <mu2>0.5</mu2>
    <selfCollide>false</selfCollide>
    <turnGravityOff>false</turnGravityOff>
  </gazebo>
  <gazebo reference="gaze">
    <mu1>0.5</mu1>
    <mu2>0.5</mu2>
    <selfCollide>false</selfCollide>
    <turnGravityOff>false</turnGravityOff>
  </gazebo>
  <!-- ARMS -->
  <gazebo reference="LShoulder">
    <mu1>0.5</mu1>
    <mu2>0.5</mu2>
    <selfCollide>false</selfCollide>
    <turnGravityOff>false</turnGravityOff>
  </gazebo>
  <gazebo reference="LShoulderYaw_link">
    <mu1>0.5</mu1>
    <mu2>0.5</mu2>
    <selfCollide>false</selfCollide>
    <turnGravityOff>false</turnGravityOff>
  </gazebo>
  <gazebo reference="LForeArm">
    <mu1>0.5</mu1>
    <mu2>0.5</mu2>
    <selfCollide>false</selfCollide>
    <turnGravityOff>false</turnGravityOff>
  </gazebo>
  <gazebo reference="LElbow">
    <mu1>0.5</mu1>
    <mu2>0.5</mu2>
    <selfCollide>false</selfCollide>
    <turnGravityOff>false</turnGravityOff>
  </gazebo>
  <gazebo reference="LWristRoll_link">
    <mu1>0.5</mu1>
    <mu2>0.5</mu2>
    <selfCollide>false</selfCollide>
    <turnGravityOff>false</turnGravityOff>
  </gazebo>
  <gazebo reference="LWristYaw_link">
    <mu1>0.5</mu1>
    <mu2>0.5</mu2>
    <selfCollide>false</selfCollide>
    <turnGravityOff>false</turnGravityOff>
  </gazebo>
  <gazebo reference="l_wrist">
    <mu1>0.5</mu1>
    <mu2>0.5</mu2>
    <selfCollide>false</selfCollide>
    <turnGravityOff>false</turnGravityOff>
  </gazebo>
  <gazebo reference="l_gripper">
    <mu1>0.5</mu1>
    <mu2>0.5</mu2>
    <selfCollide>false</selfCollide>
    <turnGravityOff>true</turnGravityOff>
  </gazebo>
  <gazebo reference="RShoulder">
    <mu1>0.5</mu1>
    <mu2>0.5</mu2>
    <selfCollide>false</selfCollide>
    <turnGravityOff>false</turnGravityOff>
  </gazebo>
  <gazebo reference="RShoulderYaw_link">
    <mu1>0.5</mu1>
    <mu2>0.5</mu2>
    <selfCollide>false</selfCollide>
    <turnGravityOff>false</turnGravityOff>
  </gazebo>
  <gazebo reference="RForeArm">
    <mu1>0.5</mu1>
    <mu2>0.5</mu2>
    <selfCollide>false</selfCollide>
    <turnGravityOff>false</turnGravityOff>
  </gazebo>
  <gazebo reference="RElbow">
    <mu1>0.5</mu1>
    <mu2>0.5</mu2>
    <selfCollide>false</selfCollide>
    <turnGravityOff>false</turnGravityOff>
  </gazebo>
  <gazebo reference="RWristRoll_link">
    <mu1>0.5</mu1>
    <mu2>0.5</mu2>
    <selfCollide>false</selfCollide>
    <turnGravityOff>false</turnGravityOff>
  </gazebo>
  <gazebo reference="RWristYaw_link">
    <mu1>0.5</mu1>
    <mu2>0.5</mu2>
    <selfCollide>false</selfCollide>
    <turnGravityOff>false</turnGravityOff>
  </gazebo>
  <gazebo reference="r_wrist">
    <mu1>0.5</mu1>
    <mu2>0.5</mu2>
    <selfCollide>false</selfCollide>
    <turnGravityOff>false</turnGravityOff>
  </gazebo>
  <gazebo reference="r_gripper">
    <mu1>0.5</mu1>
    <mu2>0.5</mu2>
    <selfCollide>false</selfCollide>
    <turnGravityOff>true</turnGravityOff>
  </gazebo>
  <gazebo reference="LFinger11_link">
    <mu1>0.5</mu1>
    <mu2>0.5</mu2>
    <selfCollide>false</selfCollide>
    <turnGravityOff>true</turnGravityOff>
  </gazebo>
  <gazebo reference="LFinger12_link">
    <mu1>0.5</mu1>
    <mu2>0.5</mu2>
    <selfCollide>false</selfCollide>
    <turnGravityOff>true</turnGravityOff>
  </gazebo>
  <gazebo reference="LFinger13_link">
    <mu1>0.5</mu1>
    <mu2>0.5</mu2>
    <selfCollide>false</selfCollide>
    <turnGravityOff>true</turnGravityOff>
  </gazebo>
  <gazebo reference="LFinger21_link">
    <mu1>0.5</mu1>
    <mu2>0.5</mu2>
    <selfCollide>false</selfCollide>
    <turnGravityOff>true</turnGravityOff>
  </gazebo>
  <gazebo reference="LFinger22_link">
    <mu1>0.5</mu1>
    <mu2>0.5</mu2>
    <selfCollide>false</selfCollide>
    <turnGravityOff>true</turnGravityOff>
  </gazebo>
  <gazebo reference="LFinger23_link">
    <mu1>0.5</mu1>
    <mu2>0.5</mu2>
    <selfCollide>false</selfCollide>
    <turnGravityOff>true</turnGravityOff>
  </gazebo>
  <gazebo reference="LFinger31_link">
    <mu1>0.5</mu1>
    <mu2>0.5</mu2>
    <selfCollide>false</selfCollide>
    <turnGravityOff>true</turnGravityOff>
  </gazebo>
  <gazebo reference="LFinger32_link">
    <mu1>0.5</mu1>
    <mu2>0.5</mu2>
    <selfCollide>false</selfCollide>
    <turnGravityOff>true</turnGravityOff>
  </gazebo>
  <gazebo reference="LFinger33_link">
    <mu1>0.5</mu1>
    <mu2>0.5</mu2>
    <selfCollide>false</selfCollide>
    <turnGravityOff>true</turnGravityOff>
  </gazebo>
  <gazebo reference="LThumb1_link">
    <mu1>0.5</mu1>
    <mu2>0.5</mu2>
    <selfCollide>false</selfCollide>
    <turnGravityOff>true</turnGravityOff>
  </gazebo>
  <gazebo reference="LThumb2_link">
    <mu1>0.5</mu1>
    <mu2>0.5</mu2>
    <selfCollide>false</selfCollide>
    <turnGravityOff>true</turnGravityOff>
  </gazebo>
  <gazebo reference="LHipYaw_link">
    <mu1>0.5</mu1>
    <mu2>0.5</mu2>
    <selfCollide>false</selfCollide>
    <turnGravityOff>false</turnGravityOff>
  </gazebo>
  <gazebo reference="LHip">
    <mu1>0.5</mu1>
    <mu2>0.5</mu2>
    <selfCollide>false</selfCollide>
    <turnGravityOff>false</turnGravityOff>
  </gazebo>
  <gazebo reference="LThigh">
    <mu1>0.5</mu1>
    <mu2>0.5</mu2>
    <selfCollide>false</selfCollide>
    <turnGravityOff>false</turnGravityOff>
  </gazebo>
  <gazebo reference="LTibia">
    <mu1>0.5</mu1>
    <mu2>0.5</mu2>
    <selfCollide>false</selfCollide>
    <turnGravityOff>false</turnGravityOff>
  </gazebo>
  <gazebo reference="LAnklePitch_link">
    <mu1>0.5</mu1>
    <mu2>0.5</mu2>
    <selfCollide>false</selfCollide>
    <turnGravityOff>false</turnGravityOff>
  </gazebo>
  <gazebo reference="l_ankle">
    <mu1>0.5</mu1>
    <mu2>0.5</mu2>
    <selfCollide>false</selfCollide>
    <turnGravityOff>false</turnGravityOff>
    <fdir1>1 0 0</fdir1>
    <maxVel>0.1</maxVel>
    <minDepth>0.003</minDepth>
  </gazebo>
  <gazebo reference="RHipYaw_link">
    <mu1>0.5</mu1>
    <mu2>0.5</mu2>
    <selfCollide>false</selfCollide>
    <turnGravityOff>false</turnGravityOff>
  </gazebo>
  <gazebo reference="RHip">
    <mu1>0.5</mu1>
    <mu2>0.5</mu2>
    <selfCollide>false</selfCollide>
    <turnGravityOff>false</turnGravityOff>
  </gazebo>
  <gazebo reference="RThigh">
    <mu1>0.5</mu1>
    <mu2>0.5</mu2>
    <selfCollide>false</selfCollide>
    <turnGravityOff>false</turnGravityOff>
  </gazebo>
  <gazebo reference="RTibia">
    <mu1>0.5</mu1>
    <mu2>0.5</mu2>
    <selfCollide>false</selfCollide>
    <turnGravityOff>false</turnGravityOff>
  </gazebo>
  <gazebo reference="RAnklePitch_link">
    <mu1>0.5</mu1>
    <mu2>0.5</mu2>
    <selfCollide>false</selfCollide>
    <turnGravityOff>false</turnGravityOff>
  </gazebo>
  <gazebo reference="r_ankle">
    <mu1>0.5</mu1>
    <mu2>0.5</mu2>
    <selfCollide>false</selfCollide>
    <turnGravityOff>false</turnGravityOff>
    <fdir1>1 0 0</fdir1>
    <maxVel>0.1</maxVel>
    <minDepth>0.003</minDepth>
  </gazebo>
  <gazebo reference="RFinger11_link">
    <mu1>0.5</mu1>
    <mu2>0.5</mu2>
    <selfCollide>false</selfCollide>
    <turnGravityOff>true</turnGravityOff>
  </gazebo>
  <gazebo reference="RFinger12_link">
    <mu1>0.5</mu1>
    <mu2>0.5</mu2>
    <selfCollide>false</selfCollide>
    <turnGravityOff>true</turnGravityOff>
  </gazebo>
  <gazebo reference="RFinger13_link">
    <mu1>0.5</mu1>
    <mu2>0.5</mu2>
    <selfCollide>false</selfCollide>
    <turnGravityOff>true</turnGravityOff>
  </gazebo>
  <gazebo reference="RFinger21_link">
    <mu1>0.5</mu1>
    <mu2>0.5</mu2>
    <selfCollide>false</selfCollide>
    <turnGravityOff>true</turnGravityOff>
  </gazebo>
  <gazebo reference="RFinger22_link">
    <mu1>0.5</mu1>
    <mu2>0.5</mu2>
    <selfCollide>false</selfCollide>
    <turnGravityOff>true</turnGravityOff>
  </gazebo>
  <gazebo reference="RFinger23_link">
    <mu1>0.5</mu1>
    <mu2>0.5</mu2>
    <selfCollide>false</selfCollide>
    <turnGravityOff>true</turnGravityOff>
  </gazebo>
  <gazebo reference="RFinger31_link">
    <mu1>0.5</mu1>
    <mu2>0.5</mu2>
    <selfCollide>false</selfCollide>
    <turnGravityOff>true</turnGravityOff>
  </gazebo>
  <gazebo reference="RFinger32_link">
    <mu1>0.5</mu1>
    <mu2>0.5</mu2>
    <selfCollide>false</selfCollide>
    <turnGravityOff>true</turnGravityOff>
  </gazebo>
  <gazebo reference="RFinger33_link">
    <mu1>0.5</mu1>
    <mu2>0.5</mu2>
    <selfCollide>false</selfCollide>
    <turnGravityOff>true</turnGravityOff>
  </gazebo>
  <gazebo reference="RThumb1_link">
    <mu1>0.5</mu1>
    <mu2>0.5</mu2>
    <selfCollide>false</selfCollide>
    <turnGravityOff>true</turnGravityOff>
  </gazebo>
  <gazebo reference="RThumb2_link">
    <mu1>0.5</mu1>
    <mu2>0.5</mu2>
    <selfCollide>false</selfCollide>
    <turnGravityOff>true</turnGravityOff>
  </gazebo>
  <!--

        RGB CAMERAS: Working
-->
  <gazebo reference="CameraRightEye_frame">
    <sensor name="CameraRightEye" type="camera">
      <update_rate>5.0</update_rate>
      <camera name="camera/right">
        <horizontal_fov>1.06290551</horizontal_fov>
        <image>
          <width>640</width>
          <height>480</height>
          <format>R8G8B8</format>
        </image>
        <clip>
          <near>0.3</near>
          <far>500</far>
        </clip>
        <noise>
          <type>gaussian</type>
          <mean>0.0</mean>
          <stddev>0.007</stddev>
        </noise>
      </camera>
      <plugin filename="libgazebo_ros_camera.so" name="camera_controller">
        <robotNamespace>romeo_robot</robotNamespace>
        <alwaysOn>true</alwaysOn>
        <updateRate>5.0</updateRate>
        <cameraName>camera_right</cameraName>
        <imageTopicName>image_raw</imageTopicName>
        <cameraInfoTopicName>camera_info</cameraInfoTopicName>
        <frameName>CameraRightEye_optical_frame</frameName>
        <hackBaseline>0.07</hackBaseline>
        <distortionK1>-0.0545211</distortionK1>
        <distortionK2>0.06919734</distortionK2>
        <distortionK3>-0.0241095</distortionK3>
        <distortionT1>-0.0112245</distortionT1>
        <distortionT2>0.0</distortionT2>
      </plugin>
    </sensor>
  </gazebo>
  <gazebo reference="CameraLeftEye_frame">
    <sensor name="CameraLeftEye" type="camera">
      <update_rate>5.0</update_rate>
      <camera name="camera/left">
        <horizontal_fov>1.06290551</horizontal_fov>
        <image>
          <width>640</width>
          <height>480</height>
          <format>R8G8B8</format>
        </image>
        <clip>
          <near>0.05</near>
          <far>500</far>
        </clip>
        <noise>
          <type>gaussian</type>
          <mean>0.0</mean>
          <stddev>0.007</stddev>
        </noise>
      </camera>
      <plugin filename="libgazebo_ros_camera.so" name="camera_controller">
        <robotNamespace>/romeo_robot</robotNamespace>
        <alwaysOn>true</alwaysOn>
        <updateRate>5.0</updateRate>
        <cameraName>camera_left</cameraName>
        <imageTopicName>image_raw</imageTopicName>
        <cameraInfoTopicName>camera_info</cameraInfoTopicName>
        <frameName>CameraLeftEye_optical_frame</frameName>
        <hackBaseline>0.07</hackBaseline>
        <distortionK1>-0.0648764</distortionK1>
        <distortionK2>0.06125202</distortionK2>
        <distortionK3>0.00382815</distortionK3>
        <distortionT1>-0.00551104</distortionT1>
        <distortionT2>0.0</distortionT2>
      </plugin>
    </sensor>
  </gazebo>
  <gazebo reference="CameraDepth_frame">
    <sensor name="CameraDepth_frame_sensor" type="depth">
      <always_on>true</always_on>
      <update_rate>20.0</update_rate>
      <camera>
        <horizontal_fov>1.01229096616</horizontal_fov>
        <image>
          <format>B8G8R8</format>
          <width>320</width>
          <height>240</height>
        </image>
        <clip>
          <near>0.4</near>
          <far>8.0</far>
        </clip>
      </camera>
      <plugin filename="libgazebo_ros_openni_kinect.so" name="CameraDepth_frame_controller">
        <alwaysOn>true</alwaysOn>
        <updateRate>20.0</updateRate>
        <cameraName>romeo_robot/camera</cameraName>
        <imageTopicName>ir/image_raw</imageTopicName>
        <cameraInfoTopicName>depth/camera_info</cameraInfoTopicName>
        <depthImageTopicName>depth/image_raw</depthImageTopicName>
        <pointCloudTopicName>depth/points</pointCloudTopicName>
        <frameName>CameraDepth_optical_frame</frameName>
        <pointCloudCutoff>0.4</pointCloudCutoff>
        <pointCloudCutoffMax>8.0</pointCloudCutoffMax>
      </plugin>
    </sensor>
  </gazebo>
  <!-- HEAD -->
  <transmission name="NeckYaw_Transmission">
    <type>transmission_interface/SimpleTransmission</type>
    <joint name="NeckYaw">
      <hardwareInterface>PositionJointInterface</hardwareInterface>
    </joint>
    <actuator name="NeckYaw_Motor">
      <!-- Dummy Values -->
      <hardwareInterface>PositionJointInterface</hardwareInterface>
      <mechanicalReduction>145.2</mechanicalReduction>
    </actuator>
  </transmission>
  <transmission name="NeckPitch_Transmission">
    <type>transmission_interface/SimpleTransmission</type>
    <joint name="NeckPitch">
      <hardwareInterface>PositionJointInterface</hardwareInterface>
    </joint>
    <actuator name="NeckPitch_Motor">
      <!-- Dummy Values -->
      <hardwareInterface>PositionJointInterface</hardwareInterface>
      <mechanicalReduction>118.1</mechanicalReduction>
    </actuator>
  </transmission>
  <transmission name="HeadPitch_Transmission">
    <type>transmission_interface/SimpleTransmission</type>
    <joint name="HeadPitch">
      <hardwareInterface>PositionJointInterface</hardwareInterface>
    </joint>
    <actuator name="HeadPitch_Motor">
      <!-- Dummy Values -->
      <hardwareInterface>PositionJointInterface</hardwareInterface>
      <mechanicalReduction>130.8</mechanicalReduction>
    </actuator>
  </transmission>
  <transmission name="HeadRoll_Transmission">
    <type>transmission_interface/SimpleTransmission</type>
    <joint name="HeadRoll">
      <hardwareInterface>PositionJointInterface</hardwareInterface>
    </joint>
    <actuator name="HeadRoll_Motor">
      <!-- Dummy Values -->
      <hardwareInterface>PositionJointInterface</hardwareInterface>
      <mechanicalReduction>201.3</mechanicalReduction>
    </actuator>
  </transmission>
  <!-- ARMS -->
  <!-- XACRO -->
  <transmission name="LShoulderPitch_Transmission">
    <type>transmission_interface/SimpleTransmission</type>
    <joint name="LShoulderPitch">
      <hardwareInterface>PositionJointInterface</hardwareInterface>
    </joint>
    <actuator name="LShoulderPitch_Motor">
      <hardwareInterface>PositionJointInterface</hardwareInterface>
      <mechanicalReduction>249.7</mechanicalReduction>
    </actuator>
  </transmission>
  <transmission name="LShoulderYaw_Transmission">
    <type>transmission_interface/SimpleTransmission</type>
    <joint name="LShoulderYaw">
      <hardwareInterface>PositionJointInterface</hardwareInterface>
    </joint>
    <actuator name="LShoulderYaw_Motor">
      <hardwareInterface>PositionJointInterface</hardwareInterface>
      <mechanicalReduction>118.1</mechanicalReduction>
    </actuator>
  </transmission>
  <transmission name="LElbowRoll_Transmission">
    <type>transmission_interface/SimpleTransmission</type>
    <joint name="LElbowRoll">
      <hardwareInterface>PositionJointInterface</hardwareInterface>
    </joint>
    <actuator name="LElbowRoll_Motor">
      <hardwareInterface>PositionJointInterface</hardwareInterface>
      <mechanicalReduction>145.2</mechanicalReduction>
    </actuator>
  </transmission>
  <transmission name="LElbowYaw_Transmission">
    <type>transmission_interface/SimpleTransmission</type>
    <joint name="LElbowYaw">
      <hardwareInterface>PositionJointInterface</hardwareInterface>
    </joint>
    <actuator name="LElbowYaw_Motor">
      <hardwareInterface>PositionJointInterface</hardwareInterface>
      <mechanicalReduction>118.1</mechanicalReduction>
    </actuator>
  </transmission>
  <transmission name="LWristRoll_Transmission">
    <type>transmission_interface/SimpleTransmission</type>
    <joint name="LWristRoll">
      <hardwareInterface>PositionJointInterface</hardwareInterface>
    </joint>
    <actuator name="LWristRoll_Motor">
      <hardwareInterface>PositionJointInterface</hardwareInterface>
      <mechanicalReduction>201.3</mechanicalReduction>
    </actuator>
  </transmission>
  <transmission name="LWristYaw_Transmission">
    <type>transmission_interface/SimpleTransmission</type>
    <joint name="LWristYaw">
      <hardwareInterface>PositionJointInterface</hardwareInterface>
    </joint>
    <actuator name="LWristYaw_Motor">
      <hardwareInterface>PositionJointInterface</hardwareInterface>
      <mechanicalReduction>249.9</mechanicalReduction>
    </actuator>
  </transmission>
  <transmission name="LWristPitch_Transmission">
    <type>transmission_interface/SimpleTransmission</type>
    <joint name="LWristPitch">
      <hardwareInterface>PositionJointInterface</hardwareInterface>
    </joint>
    <actuator name="LWristPitch_Motor">
      <hardwareInterface>PositionJointInterface</hardwareInterface>
      <mechanicalReduction>173.2</mechanicalReduction>
    </actuator>
  </transmission>
  <transmission name="LHand_Transmission">
    <type>transmission_interface/SimpleTransmission</type>
    <joint name="LHand">
      <hardwareInterface>PositionJointInterface</hardwareInterface>
    </joint>
    <actuator name="LHand_Motor">
      <hardwareInterface>PositionJointInterface</hardwareInterface>
      <mechanicalReduction>13.03</mechanicalReduction>
    </actuator>
  </transmission>
  <transmission name="RShoulderPitch_Transmission">
    <type>transmission_interface/SimpleTransmission</type>
    <joint name="RShoulderPitch">
      <hardwareInterface>PositionJointInterface</hardwareInterface>
    </joint>
    <actuator name="RShoulderPitch_Motor">
      <hardwareInterface>PositionJointInterface</hardwareInterface>
      <mechanicalReduction>249.7</mechanicalReduction>
    </actuator>
  </transmission>
  <transmission name="RShoulderYaw_Transmission">
    <type>transmission_interface/SimpleTransmission</type>
    <joint name="RShoulderYaw">
      <hardwareInterface>PositionJointInterface</hardwareInterface>
    </joint>
    <actuator name="RShoulderYaw_Motor">
      <hardwareInterface>PositionJointInterface</hardwareInterface>
      <mechanicalReduction>118.1</mechanicalReduction>
    </actuator>
  </transmission>
  <transmission name="RElbowRoll_Transmission">
    <type>transmission_interface/SimpleTransmission</type>
    <joint name="RElbowRoll">
      <hardwareInterface>PositionJointInterface</hardwareInterface>
    </joint>
    <actuator name="RElbowRoll_Motor">
      <hardwareInterface>PositionJointInterface</hardwareInterface>
      <mechanicalReduction>145.2</mechanicalReduction>
    </actuator>
  </transmission>
  <transmission name="RElbowYaw_Transmission">
    <type>transmission_interface/SimpleTransmission</type>
    <joint name="RElbowYaw">
      <hardwareInterface>PositionJointInterface</hardwareInterface>
    </joint>
    <actuator name="RElbowYaw_Motor">
      <hardwareInterface>PositionJointInterface</hardwareInterface>
      <mechanicalReduction>118.1</mechanicalReduction>
    </actuator>
  </transmission>
  <transmission name="RWristRoll_Transmission">
    <type>transmission_interface/SimpleTransmission</type>
    <joint name="RWristRoll">
      <hardwareInterface>PositionJointInterface</hardwareInterface>
    </joint>
    <actuator name="RWristRoll_Motor">
      <hardwareInterface>PositionJointInterface</hardwareInterface>
      <mechanicalReduction>201.3</mechanicalReduction>
    </actuator>
  </transmission>
  <transmission name="RWristYaw_Transmission">
    <type>transmission_interface/SimpleTransmission</type>
    <joint name="RWristYaw">
      <hardwareInterface>PositionJointInterface</hardwareInterface>
    </joint>
    <actuator name="RWristYaw_Motor">
      <hardwareInterface>PositionJointInterface</hardwareInterface>
      <mechanicalReduction>249.9</mechanicalReduction>
    </actuator>
  </transmission>
  <transmission name="RWristPitch_Transmission">
    <type>transmission_interface/SimpleTransmission</type>
    <joint name="RWristPitch">
      <hardwareInterface>PositionJointInterface</hardwareInterface>
    </joint>
    <actuator name="RWristPitch_Motor">
      <hardwareInterface>PositionJointInterface</hardwareInterface>
      <mechanicalReduction>173.2</mechanicalReduction>
    </actuator>
  </transmission>
  <transmission name="RHand_Transmission">
    <type>transmission_interface/SimpleTransmission</type>
    <joint name="RHand">
      <hardwareInterface>PositionJointInterface</hardwareInterface>
    </joint>
    <actuator name="RHand_Motor">
      <hardwareInterface>PositionJointInterface</hardwareInterface>
      <mechanicalReduction>13.03</mechanicalReduction>
    </actuator>
  </transmission>
  <transmission name="TrunkYaw_Transmission">
    <type>transmission_interface/SimpleTransmission</type>
    <joint name="TrunkYaw">
      <hardwareInterface>PositionJointInterface</hardwareInterface>
    </joint>
    <actuator name="TrunkYaw_Motor">
      <!-- Dummy Values -->
      <hardwareInterface>PositionJointInterface</hardwareInterface>
      <mechanicalReduction>292.47</mechanicalReduction>
    </actuator>
  </transmission>
  <!-- LEGS -->
  <transmission name="LHipYaw_Transmission">
    <type>transmission_interface/SimpleTransmission</type>
    <joint name="LHipYaw">
      <hardwareInterface>PositionJointInterface</hardwareInterface>
    </joint>
    <actuator name="LHipYaw_Motor">
      <!-- Dummy Values -->
      <hardwareInterface>PositionJointInterface</hardwareInterface>
      <mechanicalReduction>2696.58</mechanicalReduction>
    </actuator>
  </transmission>
  <transmission name="LHipRoll_Transmission">
    <type>transmission_interface/SimpleTransmission</type>
    <joint name="LHipRoll">
      <hardwareInterface>PositionJointInterface</hardwareInterface>
    </joint>
    <actuator name="LHipRoll_Motor">
      <!-- Dummy Values -->
      <hardwareInterface>PositionJointInterface</hardwareInterface>
      <mechanicalReduction>160.448</mechanicalReduction>
    </actuator>
  </transmission>
  <transmission name="LHipPitch_Transmission">
    <type>transmission_interface/SimpleTransmission</type>
    <joint name="LHipPitch">
      <hardwareInterface>PositionJointInterface</hardwareInterface>
    </joint>
    <actuator name="LHipPitch_Motor">
      <!-- Dummy Values -->
      <hardwareInterface>PositionJointInterface</hardwareInterface>
      <mechanicalReduction>243.736</mechanicalReduction>
    </actuator>
  </transmission>
  <transmission name="LKneePitch_Transmission">
    <type>transmission_interface/SimpleTransmission</type>
    <joint name="LKneePitch">
      <hardwareInterface>PositionJointInterface</hardwareInterface>
    </joint>
    <actuator name="LKneePitch_Motor">
      <!-- Dummy Values -->
      <hardwareInterface>PositionJointInterface</hardwareInterface>
      <mechanicalReduction>100.0</mechanicalReduction>
    </actuator>
  </transmission>
  <transmission name="LAnklePitch_Transmission">
    <type>transmission_interface/SimpleTransmission</type>
    <joint name="LAnklePitch">
      <hardwareInterface>PositionJointInterface</hardwareInterface>
    </joint>
    <actuator name="LAnklePitch_Motor">
      <!-- Dummy Values -->
      <hardwareInterface>PositionJointInterface</hardwareInterface>
      <mechanicalReduction>247.338</mechanicalReduction>
    </actuator>
  </transmission>
  <transmission name="LAnkleRoll_Transmission">
    <type>transmission_interface/SimpleTransmission</type>
    <joint name="LAnkleRoll">
      <hardwareInterface>PositionJointInterface</hardwareInterface>
    </joint>
    <actuator name="LAnkleRoll_Motor">
      <!-- Dummy Values -->
      <hardwareInterface>PositionJointInterface</hardwareInterface>
      <mechanicalReduction>168.65</mechanicalReduction>
    </actuator>
  </transmission>
  <transmission name="RHipYaw_Transmission">
    <type>transmission_interface/SimpleTransmission</type>
    <joint name="RHipYaw">
      <hardwareInterface>PositionJointInterface</hardwareInterface>
    </joint>
    <actuator name="RHipYaw_Motor">
      <!-- Dummy Values -->
      <hardwareInterface>PositionJointInterface</hardwareInterface>
      <mechanicalReduction>2696.58</mechanicalReduction>
    </actuator>
  </transmission>
  <transmission name="RHipRoll_Transmission">
    <type>transmission_interface/SimpleTransmission</type>
    <joint name="RHipRoll">
      <hardwareInterface>PositionJointInterface</hardwareInterface>
    </joint>
    <actuator name="RHipRoll_Motor">
      <!-- Dummy Values -->
      <hardwareInterface>PositionJointInterface</hardwareInterface>
      <mechanicalReduction>160.448</mechanicalReduction>
    </actuator>
  </transmission>
  <transmission name="RHipPitch_Transmission">
    <type>transmission_interface/SimpleTransmission</type>
    <joint name="RHipPitch">
      <hardwareInterface>PositionJointInterface</hardwareInterface>
    </joint>
    <actuator name="RHipPitch_Motor">
      <!-- Dummy Values -->
      <hardwareInterface>PositionJointInterface</hardwareInterface>
      <mechanicalReduction>243.736</mechanicalReduction>
    </actuator>
  </transmission>
  <transmission name="RKneePitch_Transmission">
    <type>transmission_interface/SimpleTransmission</type>
    <joint name="RKneePitch">
      <hardwareInterface>PositionJointInterface</hardwareInterface>
    </joint>
    <actuator name="RKneePitch_Motor">
      <!-- Dummy Values -->
      <hardwareInterface>PositionJointInterface</hardwareInterface>
      <mechanicalReduction>100.0</mechanicalReduction>
    </actuator>
  </transmission>
  <transmission name="RAnklePitch_Transmission">
    <type>transmission_interface/SimpleTransmission</type>
    <joint name="RAnklePitch">
      <hardwareInterface>PositionJointInterface</hardwareInterface>
    </joint>
    <actuator name="RAnklePitch_Motor">
      <!-- Dummy Values -->
      <hardwareInterface>PositionJointInterface</hardwareInterface>
      <mechanicalReduction>247.338</mechanicalReduction>
    </actuator>
  </transmission>
  <transmission name="RAnkleRoll_Transmission">
    <type>transmission_interface/SimpleTransmission</type>
    <joint name="RAnkleRoll">
      <hardwareInterface>PositionJointInterface</hardwareInterface>
    </joint>
    <actuator name="RAnkleRoll_Motor">
      <!-- Dummy Values -->
      <hardwareInterface>PositionJointInterface</hardwareInterface>
      <mechanicalReduction>168.65</mechanicalReduction>
    </actuator>
  </transmission>
</robot>
