<?xml version="1.0" ?>
<!-- =================================================================================== -->
<!-- |    This document was autogenerated by xacro from pepper_robot.xacro             | -->
<!-- |    EDITING THIS FILE BY HAND IS NOT RECOMMENDED                                 | -->
<!-- =================================================================================== -->
<!--******************************************************************
 ****** File automatically generated by generate_urdf.py script ******
 *********************************************************************-->
<robot name="JulietteY20MP" xmlns:xacro="http://www.ros.org/wiki/xacro">
  <joint name="HeadYaw" type="revolute">
    <parent link="torso"/>
    <child link="Neck"/>
    <origin rpy="0 0 0" xyz="-0.038 0 0.3089"/>
    <axis xyz="0 0 1.0"/>
    <limit effort="5.428" lower="-2.08567" upper="2.08567" velocity="7.33998"/>
  </joint>
  <link name="Neck">
    <inertial>
      <mass value="0.27391"/>
      <inertia ixx="0.000343501" ixy="0" ixz="-1.88563e-05" iyy="0.000493898" iyz="2.09863e-06" izz="0.000215252"/>
      <origin rpy="0 0 0" xyz="-0.00207 0 -0.02636"/>
    </inertial>
    <visual>
      <geometry>
        <mesh filename="meshes/HeadYaw.obj" scale="0.1 0.1 0.1"/>
      </geometry>
      <origin rpy="0 0 0" xyz="0 0 0"/>
    </visual>
    <collision>
      <geometry>
        <mesh filename="meshes/HeadYaw_0.10.stl" scale="0.1 0.1 0.1"/>
      </geometry>
      <origin rpy="0 0 0" xyz="0 0 0"/>
    </collision>
  </link>

  <!-- HeadPitch and additional texture links -->
  <joint name="HeadPitch" type="revolute">
    <parent link="Neck"/>
    <child link="Head"/>
    <origin rpy="0 0 0" xyz="0 0 0"/>
    <axis xyz="0 1.0 0"/>
    <limit effort="2.666" lower="-0.706858" upper="0.637045" velocity="9.22756"/>
  </joint>
  <link name="Head">
    <inertial>
      <mass value="1.51893"/>
      <inertia ixx="0.00597209" ixy="0" ixz="0.000125138" iyy="0.0059054" iyz="4.3428e-07" izz="0.00570374"/>
      <origin rpy="0 0 0" xyz="0.00312 0 0.11152"/>
    </inertial>
    <visual>
      <geometry>
        <mesh filename="meshes/HeadPitch_eyes.obj" scale="0.1 0.1 0.1"/>
      </geometry>
      <origin rpy="0 0 0" xyz="0 0 0"/>
    </visual>
    <collision>
      <geometry>
        <mesh filename="meshes/HeadPitch_0.10.stl" scale="0.1 0.1 0.1"/>
      </geometry>
      <origin rpy="0 0 0" xyz="0 0 0"/>
    </collision>
  </link>
  <joint name="HeadPitch_milky_joint" type="fixed">
    <parent link="Head"/>
    <child link="HeadPitch_milky"/>
    <origin rpy="0 0 0" xyz="0 0 0"/>
  </joint>
  <link name="HeadPitch_milky">
    <inertial>
      <mass value="0"/>
      <inertia ixx="0" ixy="0" ixz="0" iyy="0" iyz="0" izz="0"/>
      <origin rpy="0 0 0" xyz="0 0 0"/>
    </inertial>
    <visual>
      <geometry>
        <mesh filename="meshes/HeadPitch_milky.obj" scale="0.1 0.1 0.1"/>
      </geometry>
      <origin rpy="0 0 0" xyz="0 0 0"/>
    </visual>
  </link>
  <joint name="HeadPitch_ears_joint" type="fixed">
    <parent link="Head"/>
    <child link="HeadPitch_ears"/>
    <origin rpy="0 0 0" xyz="0 0 0"/>
  </joint>
  <link name="HeadPitch_ears">
    <inertial>
      <mass value="0"/>
      <inertia ixx="0" ixy="0" ixz="0" iyy="0" iyz="0" izz="0"/>
      <origin rpy="0 0 0" xyz="0 0 0"/>
    </inertial>
    <visual>
      <geometry>
        <mesh filename="meshes/HeadPitch_ears.obj" scale="0.1 0.1 0.1"/>
      </geometry>
      <origin rpy="0 0 0" xyz="0 0 0"/>
    </visual>
  </link>
  <joint name="HeadPitch_shiny_joint" type="fixed">
    <parent link="Head"/>
    <child link="HeadPitch_shiny"/>
    <origin rpy="0 0 0" xyz="0 0 0"/>
  </joint>
  <link name="HeadPitch_shiny">
    <inertial>
      <mass value="0"/>
      <inertia ixx="0" ixy="0" ixz="0" iyy="0" iyz="0" izz="0"/>
      <origin rpy="0 0 0" xyz="0 0 0"/>
    </inertial>
    <visual>
      <geometry>
        <mesh filename="meshes/HeadPitch_shiny.obj" scale="0.1 0.1 0.1"/>
      </geometry>
      <origin rpy="0 0 0" xyz="0 0 0"/>
    </visual>
  </link>
  <!-- End links for the Head -->

  <joint name="HipRoll" type="revolute">
    <origin rpy="0 0 0" xyz="-2e-05 0 0.079"/>
    <child link="torso"/>
    <parent link="Hip"/>
    <axis xyz="-1.0 0 0"/>
    <limit effort="10.1884" lower="-0.514872" upper="0.514872" velocity="2.27032"/>
  </joint>
  <link name="Hip">
    <inertial>
      <mass value="1.02338"/>
      <inertia ixx="0.00502422" ixy="0" ixz="-2.54911e-05" iyy="0.00640971" iyz="0.000159449" izz="0.00441082"/>
      <origin rpy="0 0 0" xyz="0.00032 0 -0.07068"/>
    </inertial>
    <visual>
      <geometry>
        <mesh filename="meshes/HipRoll.obj" scale="0.1 0.1 0.1"/>
      </geometry>
      <origin rpy="0 0 0" xyz="0 0 0.079"/>
    </visual>
    <collision>
      <geometry>
        <mesh filename="meshes/HipRoll_0.10.stl" scale="0.1 0.1 0.1"/>
      </geometry>
      <origin rpy="0 0 0" xyz="0 0 0.079"/>
    </collision>
  </link>

  <!-- Create Pelvis link and additional link for texture -->
  <joint name="HipPitch" type="revolute">
    <origin rpy="0 0 0" xyz="0 0 0.268"/>
    <child link="Hip"/>
    <parent link="Pelvis"/>
    <axis xyz="0 -1.0 0"/>
    <limit effort="19.787" lower="-1.03847" upper="1.03847" velocity="2.93276"/>
  </joint>
  <link name="Pelvis">
    <inertial>
      <mass value="2.45917"/>
      <inertia ixx="0.034351" ixy="0" ixz="0.000223034" iyy="0.0303122" iyz="-8.37542e-05" izz="0.0143771"/>
      <origin rpy="0 0 0" xyz="0.00237 0 -0.01754"/>
    </inertial>
    <visual>
      <geometry>
        <mesh filename="meshes/HipPitch_milky.obj" scale="0.1 0.1 0.1"/>
      </geometry>
      <origin rpy="0 0 0" xyz="0 0 0.268"/>
    </visual>
    <collision>
      <geometry>
        <mesh filename="meshes/HipPitch_0.10.stl" scale="0.1 0.1 0.1"/>
      </geometry>
      <origin rpy="0 0 0" xyz="0 0 0.268"/>
    </collision>
  </link>
  <joint name="HipPitch_shiny_joint" type="fixed">
    <origin rpy="0 0 0" xyz="0 0 0"/>
    <parent link="Pelvis"/>
    <child link="HipPitch_shiny"/>
  </joint>
  <link name="HipPitch_shiny">
    <inertial>
      <mass value="0"/>
      <inertia ixx="0" ixy="0" ixz="0" iyy="0" iyz="0" izz="0"/>
      <origin rpy="0 0 0" xyz="0 0 0.268"/>
    </inertial>
    <visual>
      <geometry>
        <mesh filename="meshes/HipPitch_shiny.obj" scale="0.1 0.1 0.1"/>
      </geometry>
      <origin rpy="0 0 0" xyz="0 0 0.268"/>
    </visual>
  </link>
  <!-- End Pelvis link -->

  <!-- KneePitch and additional texture link -->
  <joint name="KneePitch" type="revolute">
    <origin rpy="0 0 0" xyz="0 0 0"/>
    <child link="Pelvis"/>
    <parent link="Tibia"/>
    <axis xyz="0 -1.0 0"/>
    <limit effort="27.702" lower="-0.514872" upper="0.514872" velocity="2.93276"/>
  </joint>
  <link name="Tibia">
    <inertial>
      <mass value="11.6015"/>
      <inertia ixx="0.129229" ixy="-0.000401943" ixz="0.00048556" iyy="0.122839" iyz="-1.01666e-08" izz="0.108168"/>
      <origin rpy="0 0 0" xyz="0.00220451 0 0.082271"/>
    </inertial>
    <visual>
      <geometry>
        <mesh filename="meshes/KneePitch_shiny.obj" scale="0.1 0.1 0.1"/>
      </geometry>
      <origin rpy="0 0 0" xyz="0 0 0"/>
    </visual>
    <collision>
      <geometry>
        <mesh filename="meshes/KneePitch_0.10.stl" scale="0.1 0.1 0.1"/>
      </geometry>
      <origin rpy="0 0 0" xyz="0 0 0"/>
    </collision>
  </link>
  <joint name="KneePitch_milky_joint" type="fixed">
    <origin rpy="0 0 0" xyz="0 0 0"/>
    <parent link="Tibia"/>
    <child link="KneePitch_milky"/>
  </joint>
  <link name="KneePitch_milky">
    <inertial>
      <mass value="0"/>
      <inertia ixx="0" ixy="0" ixz="0" iyy="0" iyz="0" izz="0"/>
      <origin rpy="0 0 0" xyz="0 0 0"/>
    </inertial>
    <visual>
      <geometry>
        <mesh filename="meshes/KneePitch_milky.obj" scale="0.1 0.1 0.1"/>
      </geometry>
      <origin rpy="0 0 0" xyz="0 0 0"/>
    </visual>
  </link>
  <!-- End KneePitch link -->

  <joint name="base_link_joint" type="fixed">
    <origin rpy="0 0 0" xyz="0 0 0"/>
    <child link="base_footprint"/>
    <parent link="base_link"/>
  </joint>
  <link name="base_link">
    <inertial>
      <mass value="0"/>
      <inertia ixx="0" ixy="0" ixz="0" iyy="0" iyz="0" izz="0"/>
      <origin rpy="0 0 0" xyz="0 0 0"/>
    </inertial>
  </link>

  <joint name="base_footprint_joint" type="fixed">
    <origin rpy="0 0 0" xyz="0 0 0.334"/>
    <child link="Tibia"/>
    <parent link="base_footprint"/>
  </joint>
  <link name="base_footprint">
    <inertial>
      <mass value="0"/>
      <inertia ixx="0" ixy="0" ixz="0" iyy="0" iyz="0" izz="0"/>
      <origin rpy="0 0 0" xyz="0 0 0"/>
    </inertial>
  </link>

  <!-- Add the torso link and additional texture links -->
  <link name="torso">
    <inertial>
      <mass value="3.99533"/>
      <inertia ixx="0.0452761" ixy="0" ixz="0.00499091" iyy="0.0432702" iyz="-0.000266886" izz="0.0258881"/>
      <origin rpy="0 0 0" xyz="0.00322 0 0.12871"/>
    </inertial>
    <visual>
      <geometry>
        <mesh filename="meshes/Torso_milky.obj" scale="0.1 0.1 0.1"/>
      </geometry>
      <origin rpy="0 0 0" xyz="0 0 0.139"/>
    </visual>
    <collision>
      <geometry>
        <mesh filename="meshes/Torso_0.10.stl" scale="0.1 0.1 0.1"/>
      </geometry>
      <origin rpy="0 0 0" xyz="0 0 0.139"/>
    </collision>
  </link>
  <joint name="Torso_shiny_joint" type="fixed">
    <parent link="torso"/>
    <child link="Torso_shiny"/>
    <origin rpy="0 0 0" xyz="0 0 0.0695"/>
  </joint>
  <link name="Torso_shiny">
    <inertial>
      <mass value="0"/>
      <inertia ixx="0" ixy="0" ixz="0" iyy="0" iyz="0" izz="0"/>
      <origin rpy="0 0 0" xyz="0 0 0.0695"/>
    </inertial>
    <visual>
      <geometry>
        <mesh filename="meshes/Torso_shiny.obj" scale="0.1 0.1 0.1"/>
      </geometry>
      <origin rpy="0 0 0" xyz="0 0 0.0695"/>
    </visual>
  </link>
  <joint name="Torso_transparent_joint" type="fixed">
    <parent link="torso"/>
    <child link="Torso_transparent"/>
    <origin rpy="0 0 0" xyz="0 0 0.0695"/>
  </joint>
  <link name="Torso_transparent">
    <inertial>
      <mass value="0"/>
      <inertia ixx="0" ixy="0" ixz="0" iyy="0" iyz="0" izz="0"/>
      <origin rpy="0 0 0" xyz="0 0 0.0695"/>
    </inertial>
    <visual>
      <geometry>
        <mesh filename="meshes/Torso_transparent.obj" scale="0.1 0.1 0.1"/>
      </geometry>
      <origin rpy="0 0 0" xyz="0 0 0.0695"/>
    </visual>
  </link>
  <!-- End torso links -->

  <joint name="LShoulderPitch" type="revolute">
    <parent link="torso"/>
    <child link="LShoulder"/>
    <origin rpy="0 0 0" xyz="-0.057 0.14974 0.22582"/>
    <axis xyz="0 1.0 0"/>
    <limit effort="5.428" lower="-2.08567" upper="2.08567" velocity="7.33998"/>
  </joint>
  <link name="LShoulder">
    <inertial>
      <mass value="0.3125"/>
      <inertia ixx="0.000361198" ixy="-1.98347e-06" ixz="6.35907e-07" iyy="0.000137229" iyz="-5.68878e-06" izz="0.000399194"/>
      <origin rpy="0 0 0" xyz="0.00018 -0.01856 0.00099"/>
    </inertial>
    <visual>
      <geometry>
        <mesh filename="meshes/LShoulderPitch.obj" scale="0.1 0.1 0.1"/>
      </geometry>
      <origin rpy="0 0 0" xyz="0 0 0"/>
    </visual>
    <collision>
      <geometry>
        <mesh filename="meshes/LShoulderPitch_0.10.stl" scale="0.1 0.1 0.1"/>
      </geometry>
      <origin rpy="0 0 0" xyz="0 0 0"/>
    </collision>
  </link>

  <!-- LShoulderRoll and additional texture link -->
  <joint name="LShoulderRoll" type="revolute">
    <parent link="LShoulder"/>
    <child link="LBicep"/>
    <origin rpy="0 0 0" xyz="0 0 0"/>
    <axis xyz="0 0 1.0"/>
    <limit effort="2.666" lower="0.00872665" upper="1.56207" velocity="9.22756"/>
  </joint>
  <link name="LBicep">
    <inertial>
      <mass value="0.50527"/>
      <inertia ixx="0.000500872" ixy="-3.55918e-05" ixz="8.51263e-05" iyy="0.00126284" iyz="9.06813e-06" izz="0.00115718"/>
      <origin rpy="0 0 0" xyz="0.08151 0.01284 -0.01017"/>
    </inertial>
    <visual>
      <geometry>
        <mesh filename="meshes/LShoulderRoll_milky.obj" scale="0.1 0.1 0.1"/>
      </geometry>
      <origin rpy="0 0 0" xyz="0 0 0"/>
    </visual>
    <collision>
      <geometry>
        <mesh filename="meshes/LShoulderRoll_0.10.stl" scale="0.1 0.1 0.1"/>
      </geometry>
      <origin rpy="0 0 0" xyz="0 0 0"/>
    </collision>
  </link>
  <joint name="LShoulderRoll_shiny_joint" type="fixed">
    <parent link="LBicep"/>
    <child link="LShoulderRoll_shiny"/>
    <origin rpy="0 0 0" xyz="0 0 0"/>
  </joint>
  <link name="LShoulderRoll_shiny">
    <inertial>
      <mass value="0"/>
      <inertia ixx="0" ixy="0" ixz="0" iyy="0" iyz="0" izz="0"/>
      <origin rpy="0 0 0" xyz="0 0 0"/>
    </inertial>
    <visual>
      <geometry>
        <mesh filename="meshes/LShoulderRoll_shiny.obj" scale="0.1 0.1 0.1"/>
      </geometry>
      <origin rpy="0 0 0" xyz="0 0 0"/>
    </visual>
  </link>
  <!-- End LShoulderRoll -->

  <joint name="LElbowYaw" type="revolute">
    <parent link="LBicep"/>
    <child link="LElbow"/>
    <origin rpy="0 -0.157079 0" xyz="0.1812 0.015 0.00013"/>
    <axis xyz="1.0 0 0"/>
    <limit effort="5.428" lower="-2.08567" upper="2.08567" velocity="7.33998"/>
  </joint>
  <link name="LElbow">
    <inertial>
      <mass value="0.27495"/>
      <inertia ixx="0.000122971" ixy="9.86024e-07" ixz="-2.55838e-05" iyy="0.000331766" iyz="-1.98925e-06" izz="0.000303047"/>
      <origin rpy="0 0 0" xyz="-0.02297 -0.00019 0.00119"/>
    </inertial>
    <visual>
      <geometry>
        <mesh filename="meshes/LElbowYaw.obj" scale="0.1 0.1 0.1"/>
      </geometry>
      <origin rpy="0 0 0" xyz="0 0 0"/>
    </visual>
    <collision>
      <geometry>
        <mesh filename="meshes/LElbowYaw_0.10.stl" scale="0.1 0.1 0.1"/>
      </geometry>
      <origin rpy="0 0 0" xyz="0 0 0"/>
    </collision>
  </link>

  <!-- LElbowRoll link and additional texture  -->
  <joint name="LElbowRoll" type="revolute">
    <parent link="LElbow"/>
    <child link="LForeArm"/>
    <origin rpy="0 0 0" xyz="0 0 0"/>
    <axis xyz="0 0 1.0"/>
    <limit effort="2.666" lower="-1.56207" upper="-0.00872665" velocity="9.22756"/>
  </joint>
  <link name="LForeArm">
    <inertial>
      <mass value="0.16579"/>
      <inertia ixx="0.00156513" ixy="1.47517e-05" ixz="-6.05746e-05" iyy="0.00173219" iyz="-1.7619e-07" izz="0.000273081"/>
      <origin rpy="0 0 0" xyz="0.0593 0.00271 -0.01014"/>
    </inertial>
    <visual>
      <geometry>
        <mesh filename="meshes/LElbowRoll_shiny.obj" scale="0.1 0.1 0.1"/>
      </geometry>
      <origin rpy="0 0 0" xyz="0 0 0"/>
    </visual>
    <collision>
      <geometry>
        <mesh filename="meshes/LElbowRoll_0.10.stl" scale="0.1 0.1 0.1"/>
      </geometry>
      <origin rpy="0 0 0" xyz="0 0 0"/>
    </collision>
  </link>
  <joint name="LElbowRoll_milky_joint" type="fixed">
    <parent link="LForeArm"/>
    <child link="LElbowRoll_milky"/>
    <origin rpy="0 0 0" xyz="0 0 0"/>
  </joint>
  <link name="LElbowRoll_milky">
    <inertial>
      <mass value="0"/>
      <inertia ixx="0" ixy="0" ixz="0" iyy="0" iyz="0" izz="0"/>
      <origin rpy="0 0 0" xyz="0 0 0"/>
    </inertial>
    <visual>
      <geometry>
        <mesh filename="meshes/LElbowRoll_milky.obj" scale="0.1 0.1 0.1"/>
      </geometry>
      <origin rpy="0 0 0" xyz="0 0 0"/>
    </visual>
  </link>
  <!-- End definition of LElbowRoll -->

  <joint name="LWristYaw" type="revolute">
    <parent link="LForeArm"/>
    <child link="l_wrist"/>
    <origin rpy="0 0 0" xyz="0.15 0 0"/>
    <axis xyz="1.0 0 0"/>
    <limit effort="0.2014" lower="-1.82387" upper="1.82387" velocity="17.3835"/>
  </joint>
  <link name="l_wrist">
    <inertial>
      <mass value="0.27555"/>
      <inertia ixx="0.000151643" ixy="1.06629e-05" ixz="2.89509e-06" iyy="0.000431099" iyz="-3.13715e-06" izz="0.000456172"/>
      <origin rpy="0 0 0" xyz="0.03536 -0.00072 -0.00207"/>
    </inertial>
    <visual>
      <geometry>
        <mesh filename="meshes/LWristYaw.obj" scale="0.1 0.1 0.1"/>
      </geometry>
      <origin rpy="0 0 0" xyz="0 0 0"/>
    </visual>
    <collision>
      <geometry>
        <mesh filename="meshes/LWristYaw_vahcd.obj" scale="0.1 0.1 0.1"/>
      </geometry>
      <origin rpy="0 0 0" xyz="0 0 0"/>
    </collision>
  </link>
  <joint name="LGripper" type="fixed">
    <parent link="l_wrist"/>
    <child link="l_gripper"/>
    <origin rpy="-3.14 0.0 -1.57" xyz="0.07 0.0 -0.01802319018"/>
    <axis xyz="0 0 0"/>
  </joint>
  <link name="l_gripper">
    <inertial>
      <mass value="2e-03"/>
      <inertia ixx="1.1e-09" ixy="0" ixz="0" iyy="1.1e-09" iyz="0" izz="1.1e-09"/>
    </inertial>
  </link>
  <joint name="LHand" type="revolute">
    <parent link="l_wrist"/>
    <child link="l_hand"/>
    <origin rpy="0 0 0" xyz="0.025 0 0"/>
    <axis xyz="1.0 0 0"/>
    <limit effort="0.144" lower="0.02" upper="0.98" velocity="12.56"/>
  </joint>
  <link name="l_hand">
    <inertial>
      <mass value="2e-03"/>
      <inertia ixx="1.1e-09" ixy="0" ixz="0" iyy="1.1e-09" iyz="0" izz="1.1e-09"/>
    </inertial>
  </link>
  <joint name="RShoulderPitch" type="revolute">
    <parent link="torso"/>
    <child link="RShoulder"/>
    <origin rpy="0 0 0" xyz="-0.057 -0.14974 0.22582"/>
    <axis xyz="0 1.0 0"/>
    <limit effort="5.428" lower="-2.08567" upper="2.08567" velocity="7.33998"/>
  </joint>
  <link name="RShoulder">
    <inertial>
      <mass value="0.3125"/>
      <inertia ixx="0.000361198" ixy="1.98347e-06" ixz="6.35907e-07" iyy="0.000137229" iyz="5.68878e-06" izz="0.000399194"/>
      <origin rpy="0 0 0" xyz="0.00018 0.01856 0.00099"/>
    </inertial>
    <visual>
      <geometry>
        <mesh filename="meshes/RShoulderPitch.obj" scale="0.1 0.1 0.1"/>
      </geometry>
      <origin rpy="0 0 0" xyz="0 0 0"/>
    </visual>
    <collision>
      <geometry>
        <mesh filename="meshes/RShoulderPitch_0.10.stl" scale="0.1 0.1 0.1"/>
      </geometry>
      <origin rpy="0 0 0" xyz="0 0 0"/>
    </collision>
  </link>

  <!-- RShoulderRoll and additional texture link -->
  <joint name="RShoulderRoll" type="revolute">
    <parent link="RShoulder"/>
    <child link="RBicep"/>
    <origin rpy="0 0 0" xyz="0 0 0"/>
    <axis xyz="0 0 1.0"/>
    <limit effort="2.666" lower="-1.56207" upper="-0.00872665" velocity="9.22756"/>
  </joint>
  <link name="RBicep">
    <inertial>
      <mass value="0.50527"/>
      <inertia ixx="0.000500872" ixy="3.55918e-05" ixz="8.51263e-05" iyy="0.00126284" iyz="-9.06813e-06" izz="0.00115718"/>
      <origin rpy="0 0 0" xyz="0.08151 -0.01284 -0.01017"/>
    </inertial>
    <visual>
      <geometry>
        <mesh filename="meshes/RShoulderRoll_milky.obj" scale="0.1 0.1 0.1"/>
      </geometry>
      <origin rpy="0 0 0" xyz="0 0 0"/>
    </visual>
    <collision>
      <geometry>
        <mesh filename="meshes/RShoulderRoll_0.10.stl" scale="0.1 0.1 0.1"/>
      </geometry>
      <origin rpy="0 0 0" xyz="0 0 0"/>
    </collision>
  </link>
  <joint name="RShoulderRoll_shiny_joint" type="fixed">
    <parent link="RBicep"/>
    <child link="RShoulderRoll_shiny"/>
    <origin rpy="0 0 0" xyz="0 0 0"/>
  </joint>
  <link name="RShoulderRoll_shiny">
    <inertial>
      <mass value="0"/>
      <inertia ixx="0" ixy="0" ixz="0" iyy="0" iyz="0" izz="0"/>
      <origin rpy="0 0 0" xyz="0 0 0"/>
    </inertial>
    <visual>
      <geometry>
        <mesh filename="meshes/RShoulderRoll_shiny.obj" scale="0.1 0.1 0.1"/>
      </geometry>
      <origin rpy="0 0 0" xyz="0 0 0"/>
    </visual>
  </link>
  <!-- End RShoulderRoll -->

  <joint name="RElbowYaw" type="revolute">
    <parent link="RBicep"/>
    <child link="RElbow"/>
    <origin rpy="0 -0.157079 0" xyz="0.1812 -0.015 0.00013"/>
    <axis xyz="1.0 0 0"/>
    <limit effort="5.428" lower="-2.08567" upper="2.08567" velocity="7.33998"/>
  </joint>
  <link name="RElbow">
    <inertial>
      <mass value="0.27495"/>
      <inertia ixx="0.000122971" ixy="-9.86024e-07" ixz="-2.55838e-05" iyy="0.000331766" iyz="1.98925e-06" izz="0.000303047"/>
      <origin rpy="0 0 0" xyz="-0.02297 0.00019 0.00119"/>
    </inertial>
    <visual>
      <geometry>
        <mesh filename="meshes/RElbowYaw.obj" scale="0.1 0.1 0.1"/>
      </geometry>
      <origin rpy="0 0 0" xyz="0 0 0"/>
    </visual>
    <collision>
      <geometry>
        <mesh filename="meshes/RElbowYaw_0.10.stl" scale="0.1 0.1 0.1"/>
      </geometry>
      <origin rpy="0 0 0" xyz="0 0 0"/>
    </collision>
  </link>

  <!-- RElbowRoll link and additional texture link -->
  <joint name="RElbowRoll" type="revolute">
    <parent link="RElbow"/>
    <child link="RForeArm"/>
    <origin rpy="0 0 0" xyz="0 0 0"/>
    <axis xyz="0 0 1.0"/>
    <limit effort="2.666" lower="0.00872665" upper="1.56207" velocity="9.22756"/>
  </joint>
  <link name="RForeArm">
    <inertial>
      <mass value="0.16579"/>
      <inertia ixx="0.00156513" ixy="-1.47517e-05" ixz="-6.05746e-05" iyy="0.00173219" iyz="1.7619e-07" izz="0.000273081"/>
      <origin rpy="0 0 0" xyz="0.0593 -0.00271 -0.01014"/>
    </inertial>
    <visual>
      <geometry>
        <mesh filename="meshes/RElbowRoll_shiny.obj" scale="0.1 0.1 0.1"/>
      </geometry>
      <origin rpy="0 0 0" xyz="0 0 0"/>
    </visual>
    <collision>
      <geometry>
        <mesh filename="meshes/RElbowRoll_0.10.stl" scale="0.1 0.1 0.1"/>
      </geometry>
      <origin rpy="0 0 0" xyz="0 0 0"/>
    </collision>
  </link>
  <joint name="RElbowRoll_milky_joint" type="fixed">
    <parent link="RForeArm"/>
    <child link="RElbowRoll_milky"/>
    <origin rpy="0 0 0" xyz="0 0 0"/>
  </joint>
  <link name="RElbowRoll_milky">
    <inertial>
      <mass value="0"/>
      <inertia ixx="0" ixy="0" ixz="0" iyy="0" iyz="0" izz="0"/>
      <origin rpy="0 0 0" xyz="0 0 0"/>
    </inertial>
    <visual>
      <geometry>
        <mesh filename="meshes/RElbowRoll_milky.obj" scale="0.1 0.1 0.1"/>
      </geometry>
      <origin rpy="0 0 0" xyz="0 0 0"/>
    </visual>
  </link>
  <!-- End RElbowRoll -->

  <joint name="RWristYaw" type="revolute">
    <parent link="RForeArm"/>
    <child link="r_wrist"/>
    <origin rpy="0 0 0" xyz="0.15 0 0"/>
    <axis xyz="1.0 0 0"/>
    <limit effort="0.2014" lower="-1.82387" upper="1.82387" velocity="17.3835"/>
  </joint>
  <link name="r_wrist">
    <inertial>
      <mass value="0.27555"/>
      <inertia ixx="0.000151643" ixy="-1.06629e-05" ixz="2.89509e-06" iyy="0.000431099" iyz="3.13715e-06" izz="0.000456172"/>
      <origin rpy="0 0 0" xyz="0.03536 0.00072 -0.00207"/>
    </inertial>
    <visual>
      <geometry>
        <mesh filename="meshes/RWristYaw.obj" scale="0.1 0.1 0.1"/>
      </geometry>
      <origin rpy="0 0 0" xyz="0 0 0"/>
    </visual>
    <collision>
      <geometry>
        <mesh filename="meshes/RWristYaw_vahcd.obj" scale="0.1 0.1 0.1"/>
      </geometry>
      <origin rpy="0 0 0" xyz="0 0 0"/>
    </collision>
  </link>
  <joint name="RGripper" type="fixed">
    <parent link="r_wrist"/>
    <child link="r_gripper"/>
    <origin rpy="3.14 0 1.57" xyz="0.07 0.0 -0.01802319018"/>
    <axis xyz="0 0 0"/>
  </joint>
  <link name="r_gripper">
    <inertial>
      <mass value="2e-03"/>
      <inertia ixx="1.1e-09" ixy="0" ixz="0" iyy="1.1e-09" iyz="0" izz="1.1e-09"/>
    </inertial>
  </link>
  <joint name="RHand" type="revolute">
    <parent link="r_wrist"/>
    <child link="r_hand"/>
    <origin rpy="0 0 0" xyz="0.025 0 0"/>
    <axis xyz="1.0 0 0"/>
    <limit effort="0.144" lower="0.02" upper="0.98" velocity="12.56"/>
  </joint>
  <link name="r_hand">
    <inertial>
      <mass value="2e-03"/>
      <inertia ixx="1.1e-09" ixy="0" ixz="0" iyy="1.1e-09" iyz="0" izz="1.1e-09"/>
    </inertial>
  </link>
  <link name="SonarBack_frame">
    <inertial>
      <mass value="0"/>
      <inertia ixx="0" ixy="0" ixz="0" iyy="0" iyz="0" izz="0"/>
      <origin rpy="0 0 0" xyz="0 0 0"/>
    </inertial>
  </link>
  <joint name="Sonar/Back_sensor_fixedjoint" type="fixed">
    <parent link="Tibia"/>
    <child link="SonarBack_frame"/>
    <origin rpy="-1.81761e-08 -0.209438 -3.14159" xyz="-0.0718 0 -0.0534"/>
    <axis xyz="0 0 0"/>
  </joint>
  <link name="CameraBottom_optical_frame">
    <inertial>
      <mass value="0"/>
      <inertia ixx="0" ixy="0" ixz="0" iyy="0" iyz="0" izz="0"/>
      <origin rpy="0 0 0" xyz="0 0 0"/>
    </inertial>
  </link>
  <joint name="CameraBottom_optical_frame_fixedjoint" type="fixed">
    <parent link="CameraBottom_frame"/>
    <child link="CameraBottom_optical_frame"/>
    <origin rpy="-1.57079632679 0 -1.57079632679" xyz="0 0 0"/>
  </joint>
  <link name="CameraDepth_optical_frame">
    <inertial>
      <mass value="0"/>
      <inertia ixx="0" ixy="0" ixz="0" iyy="0" iyz="0" izz="0"/>
      <origin rpy="0 0 0" xyz="0 0 0"/>
    </inertial>
  </link>
  <joint name="CameraDepth_optical_frame_fixedjoint" type="fixed">
    <parent link="CameraDepth_frame"/>
    <child link="CameraDepth_optical_frame"/>
    <origin rpy="-1.57079632679 0 -1.57079632679" xyz="0 0 0"/>
  </joint>
  <link name="LHandTouchBack_frame">
    <inertial>
      <mass value="0"/>
      <inertia ixx="0" ixy="0" ixz="0" iyy="0" iyz="0" izz="0"/>
      <origin rpy="0 0 0" xyz="0 0 0"/>
    </inertial>
  </link>
  <joint name="LHand/Touch/Back_sensor_fixedjoint" type="fixed">
    <parent link="l_wrist"/>
    <child link="LHandTouchBack_frame"/>
    <origin rpy="1.5708 -1.5708 -3.14159" xyz="0.0523 0 0.0304"/>
    <axis xyz="0 0 0"/>
  </joint>
  <link name="VerticalLeftLaser_frame">
    <inertial>
      <mass value="0"/>
      <inertia ixx="0" ixy="0" ixz="0" iyy="0" iyz="0" izz="0"/>
      <origin rpy="0 0 0" xyz="0 0 0"/>
    </inertial>
  </link>
  <joint name="LaserSensor/VerticalLeft_sensor_fixedjoint" type="fixed">
    <parent link="Tibia"/>
    <child link="VerticalLeftLaser_frame"/>
    <origin rpy="0 0.349066 0" xyz="0.0562 0 -0.0692"/>
    <axis xyz="0 0 0"/>
  </joint>
  <link name="SurroundingFrontLaser_device_frame">
    <inertial>
      <mass value="0"/>
      <inertia ixx="0" ixy="0" ixz="0" iyy="0" iyz="0" izz="0"/>
      <origin rpy="0 0 0" xyz="0 0 0"/>
    </inertial>
  </link>
  <joint name="LaserSensor/Front_sensor_fixedjoint" type="fixed">
    <parent link="Tibia"/>
    <child link="SurroundingFrontLaser_device_frame"/>
    <origin rpy="0 0.349066 0" xyz="0.0562 0 -0.0692"/>
    <axis xyz="0 0 0"/>
  </joint>
  <link name="BumperB_frame">
    <inertial>
      <mass value="0"/>
      <inertia ixx="0" ixy="0" ixz="0" iyy="0" iyz="0" izz="0"/>
      <origin rpy="0 0 0" xyz="0 0 0"/>
    </inertial>
  </link>
  <joint name="Bumper/Back_sensor_fixedjoint" type="fixed">
    <parent link="Tibia"/>
    <child link="BumperB_frame"/>
    <origin rpy="0 0 -3.14159" xyz="-0.251 0 -0.264"/>
    <axis xyz="0 0 0"/>
  </joint>
  <link name="SurroundingLeftLaser_frame">
    <inertial>
      <mass value="0"/>
      <inertia ixx="0" ixy="0" ixz="0" iyy="0" iyz="0" izz="0"/>
      <origin rpy="0 0 0" xyz="0 0 0"/>
    </inertial>
  </link>
  <joint name="LaserSensor/Left_projected_sensor_fixedjoint" type="fixed">
    <parent link="Tibia"/>
    <child link="SurroundingLeftLaser_frame"/>
    <origin rpy="0 0 1.75728" xyz="-0.018 0.0899 -0.334"/>
    <axis xyz="0 0 0"/>
  </joint>
  <link name="ShovelLaser_frame">
    <inertial>
      <mass value="0"/>
      <inertia ixx="0" ixy="0" ixz="0" iyy="0" iyz="0" izz="0"/>
      <origin rpy="0 0 0" xyz="0 0 0"/>
    </inertial>
  </link>
  <joint name="LaserSensor/Shovel_sensor_fixedjoint" type="fixed">
    <parent link="Tibia"/>
    <child link="ShovelLaser_frame"/>
    <origin rpy="0 0.349066 0" xyz="0.0562 0 -0.0692"/>
    <axis xyz="0 0 0"/>
  </joint>
  <link name="ImuTorsoAccelerometer_frame">
    <inertial>
      <mass value="0"/>
      <inertia ixx="0" ixy="0" ixz="0" iyy="0" iyz="0" izz="0"/>
      <origin rpy="0 0 0" xyz="0 0 0"/>
    </inertial>
  </link>
  <joint name="Accelerometer_sensor_fixedjoint" type="fixed">
    <parent link="torso"/>
    <child link="ImuTorsoAccelerometer_frame"/>
    <origin rpy="0 0 0" xyz="0.00239 -0.03575 0.14526"/>
    <axis xyz="0 0 0"/>
  </joint>
  <link name="RSpeaker_frame">
    <inertial>
      <mass value="0"/>
      <inertia ixx="0" ixy="0" ixz="0" iyy="0" iyz="0" izz="0"/>
      <origin rpy="0 0 0" xyz="0 0 0"/>
    </inertial>
  </link>
  <joint name="SpeakerRight_sensor_fixedjoint" type="fixed">
    <parent link="Head"/>
    <child link="RSpeaker_frame"/>
    <origin rpy="0 0 0" xyz="0 0 0"/>
    <axis xyz="0 0 0"/>
  </joint>
  <link name="SurroundingRightLaser_device_frame">
    <inertial>
      <mass value="0"/>
      <inertia ixx="0" ixy="0" ixz="0" iyy="0" iyz="0" izz="0"/>
      <origin rpy="0 0 0" xyz="0 0 0"/>
    </inertial>
  </link>
  <joint name="LaserSensor/Right_sensor_fixedjoint" type="fixed">
    <parent link="Tibia"/>
    <child link="SurroundingRightLaser_device_frame"/>
    <origin rpy="0 0.349066 -1.5708" xyz="-0.018 -0.0899 -0.0759"/>
    <axis xyz="0 0 0"/>
  </joint>
  <link name="LSpeaker_frame">
    <inertial>
      <mass value="0"/>
      <inertia ixx="0" ixy="0" ixz="0" iyy="0" iyz="0" izz="0"/>
      <origin rpy="0 0 0" xyz="0 0 0"/>
    </inertial>
  </link>
  <joint name="SpeakerLeft_sensor_fixedjoint" type="fixed">
    <parent link="Head"/>
    <child link="LSpeaker_frame"/>
    <origin rpy="0 0 0" xyz="0 0 0"/>
    <axis xyz="0 0 0"/>
  </joint>
  <link name="RHandTouchBack_frame">
    <inertial>
      <mass value="0"/>
      <inertia ixx="0" ixy="0" ixz="0" iyy="0" iyz="0" izz="0"/>
      <origin rpy="0 0 0" xyz="0 0 0"/>
    </inertial>
  </link>
  <joint name="RHand/Touch/Back_sensor_fixedjoint" type="fixed">
    <parent link="r_wrist"/>
    <child link="RHandTouchBack_frame"/>
    <origin rpy="1.5708 -1.5708 -3.14159" xyz="0.0523 0 0.0304"/>
    <axis xyz="0 0 0"/>
  </joint>
  <link name="CameraTop_frame">
    <inertial>
      <mass value="0"/>
      <inertia ixx="0" ixy="0" ixz="0" iyy="0" iyz="0" izz="0"/>
      <origin rpy="0 0 0" xyz="0 0 0"/>
    </inertial>
  </link>
  <joint name="CameraTop_sensor_fixedjoint" type="fixed">
    <parent link="Head"/>
    <child link="CameraTop_frame"/>
    <origin rpy="0 0 0" xyz="0.08601 0 0.16284"/>
    <axis xyz="0 0 0"/>
  </joint>
  <link name="SurroundingLeftLaser_device_frame">
    <inertial>
      <mass value="0"/>
      <inertia ixx="0" ixy="0" ixz="0" iyy="0" iyz="0" izz="0"/>
      <origin rpy="0 0 0" xyz="0 0 0"/>
    </inertial>
  </link>
  <joint name="LaserSensor/Left_sensor_fixedjoint" type="fixed">
    <parent link="Tibia"/>
    <child link="SurroundingLeftLaser_device_frame"/>
    <origin rpy="0 0.349066 1.5708" xyz="-0.018 0.0899 -0.0759"/>
    <axis xyz="0 0 0"/>
  </joint>
  <link name="CameraDepth_frame">
    <inertial>
      <mass value="0"/>
      <inertia ixx="0" ixy="0" ixz="0" iyy="0" iyz="0" izz="0"/>
      <origin rpy="0 0 0" xyz="0 0 0"/>
    </inertial>
  </link>
  <joint name="CameraDepth_sensor_fixedjoint" type="fixed">
    <parent link="Head"/>
    <child link="CameraDepth_frame"/>
    <origin rpy="0 0 0" xyz="0.05138 0.039 0.1194"/>
    <axis xyz="0 0 0"/>
  </joint>
  <link name="SurroundingRightLaser_frame">
    <inertial>
      <mass value="0"/>
      <inertia ixx="0" ixy="0" ixz="0" iyy="0" iyz="0" izz="0"/>
      <origin rpy="0 0 0" xyz="0 0 0"/>
    </inertial>
  </link>
  <joint name="LaserSensor/Right_projected_sensor_fixedjoint" type="fixed">
    <parent link="Tibia"/>
    <child link="SurroundingRightLaser_frame"/>
    <origin rpy="0 0 -1.75728" xyz="-0.018 -0.0899 -0.334"/>
    <axis xyz="0 0 0"/>
  </joint>
  <link name="HeadTouchFront_frame">
    <inertial>
      <mass value="0"/>
      <inertia ixx="0" ixy="0" ixz="0" iyy="0" iyz="0" izz="0"/>
      <origin rpy="0 0 0" xyz="0 0 0"/>
    </inertial>
  </link>
  <joint name="Head/Touch/Front_sensor_fixedjoint" type="fixed">
    <parent link="Head"/>
    <child link="HeadTouchFront_frame"/>
    <origin rpy="0 0.20944 0" xyz="0.028175 0 0.21267"/>
    <axis xyz="0 0 0"/>
  </joint>
  <link name="VerticalRightLaser_frame">
    <inertial>
      <mass value="0"/>
      <inertia ixx="0" ixy="0" ixz="0" iyy="0" iyz="0" izz="0"/>
      <origin rpy="0 0 0" xyz="0 0 0"/>
    </inertial>
  </link>
  <joint name="LaserSensor/VerticalRight_sensor_fixedjoint" type="fixed">
    <parent link="Tibia"/>
    <child link="VerticalRightLaser_frame"/>
    <origin rpy="0 0.349066 0" xyz="0.0562 0 -0.0692"/>
    <axis xyz="0 0 0"/>
  </joint>
  <link name="SonarFront_frame">
    <inertial>
      <mass value="0"/>
      <inertia ixx="0" ixy="0" ixz="0" iyy="0" iyz="0" izz="0"/>
      <origin rpy="0 0 0" xyz="0 0 0"/>
    </inertial>
  </link>
  <joint name="Sonar/Front_sensor_fixedjoint" type="fixed">
    <parent link="Tibia"/>
    <child link="SonarFront_frame"/>
    <origin rpy="0 -0.322858 0" xyz="0.0699 0 -0.1023"/>
    <axis xyz="0 0 0"/>
  </joint>
  <link name="BumperFL_frame">
    <inertial>
      <mass value="0"/>
      <inertia ixx="0" ixy="0" ixz="0" iyy="0" iyz="0" izz="0"/>
      <origin rpy="0 0 0" xyz="0 0 0"/>
    </inertial>
  </link>
  <joint name="Bumper/FrontLeft_sensor_fixedjoint" type="fixed">
    <parent link="Tibia"/>
    <child link="BumperFL_frame"/>
    <origin rpy="0 0 0.48886" xyz="0.129 0.227 -0.264"/>
    <axis xyz="0 0 0"/>
  </joint>
  <link name="CameraBottom_frame">
    <inertial>
      <mass value="0"/>
      <inertia ixx="0" ixy="0" ixz="0" iyy="0" iyz="0" izz="0"/>
      <origin rpy="0 0 0" xyz="0 0 0"/>
    </inertial>
  </link>
  <joint name="CameraBottom_sensor_fixedjoint" type="fixed">
    <parent link="Head"/>
    <child link="CameraBottom_frame"/>
    <origin rpy="0 0.698132 0" xyz="0.09262 0 0.06177"/>
    <axis xyz="0 0 0"/>
  </joint>
  <link name="CameraTop_optical_frame">
    <inertial>
      <mass value="0"/>
      <inertia ixx="0" ixy="0" ixz="0" iyy="0" iyz="0" izz="0"/>
      <origin rpy="0 0 0" xyz="0 0 0"/>
    </inertial>
  </link>
  <joint name="CameraTop_optical_frame_fixedjoint" type="fixed">
    <parent link="CameraTop_frame"/>
    <child link="CameraTop_optical_frame"/>
    <origin rpy="-1.57079632679 0 -1.57079632679" xyz="0 0 0"/>
  </joint>
  <link name="ImuBaseAccelerometer_frame">
    <inertial>
      <mass value="0"/>
      <inertia ixx="0" ixy="0" ixz="0" iyy="0" iyz="0" izz="0"/>
      <origin rpy="0 0 0" xyz="0 0 0"/>
    </inertial>
  </link>
  <joint name="AccelerometerBase_sensor_fixedjoint" type="fixed">
    <parent link="Tibia"/>
    <child link="ImuBaseAccelerometer_frame"/>
    <origin rpy="0 0 0" xyz="0.0147 -0.0017 -0.26319"/>
    <axis xyz="0 0 0"/>
  </joint>
  <link name="ImuTorsoGyrometer_frame">
    <inertial>
      <mass value="0"/>
      <inertia ixx="0" ixy="0" ixz="0" iyy="0" iyz="0" izz="0"/>
      <origin rpy="0 0 0" xyz="0 0 0"/>
    </inertial>
  </link>
  <joint name="Gyrometer_sensor_fixedjoint" type="fixed">
    <parent link="torso"/>
    <child link="ImuTorsoGyrometer_frame"/>
    <origin rpy="0 0 0" xyz="0.00204 -0.03491 0.12941"/>
    <axis xyz="0 0 0"/>
  </joint>
  <link name="Tablet_frame">
    <inertial>
      <mass value="0"/>
      <inertia ixx="0" ixy="0" ixz="0" iyy="0" iyz="0" izz="0"/>
      <origin rpy="0 0 0" xyz="0 0 0"/>
    </inertial>
  </link>
  <joint name="Tablet_sensor_fixedjoint" type="fixed">
    <parent link="torso"/>
    <child link="Tablet_frame"/>
    <origin rpy="0 -0.523599 0" xyz="0.0839249 0 0.20151"/>
    <axis xyz="0 0 0"/>
  </joint>
  <link name="HeadTouchRear_frame">
    <inertial>
      <mass value="0"/>
      <inertia ixx="0" ixy="0" ixz="0" iyy="0" iyz="0" izz="0"/>
      <origin rpy="0 0 0" xyz="0 0 0"/>
    </inertial>
  </link>
  <joint name="Head/Touch/Rear_sensor_fixedjoint" type="fixed">
    <parent link="Head"/>
    <child link="HeadTouchRear_frame"/>
    <origin rpy="0 -0.314159 0" xyz="-0.03376 0 0.21052"/>
    <axis xyz="0 0 0"/>
  </joint>
  <link name="BumperFR_frame">
    <inertial>
      <mass value="0"/>
      <inertia ixx="0" ixy="0" ixz="0" iyy="0" iyz="0" izz="0"/>
      <origin rpy="0 0 0" xyz="0 0 0"/>
    </inertial>
  </link>
  <joint name="Bumper/FrontRight_sensor_fixedjoint" type="fixed">
    <parent link="Tibia"/>
    <child link="BumperFR_frame"/>
    <origin rpy="0 0 -0.48886" xyz="0.129 -0.227 -0.264"/>
    <axis xyz="0 0 0"/>
  </joint>
  <link name="SurroundingFrontLaser_frame">
    <inertial>
      <mass value="0"/>
      <inertia ixx="0" ixy="0" ixz="0" iyy="0" iyz="0" izz="0"/>
      <origin rpy="0 0 0" xyz="0 0 0"/>
    </inertial>
  </link>
  <joint name="LaserSensor/Front_projected_sensor_fixedjoint" type="fixed">
    <parent link="Tibia"/>
    <child link="SurroundingFrontLaser_frame"/>
    <origin rpy="0 0 0" xyz="0.0562 0 -0.334"/>
    <axis xyz="0 0 0"/>
  </joint>
  <link name="ChestButton_frame">
    <inertial>
      <mass value="0"/>
      <inertia ixx="0" ixy="0" ixz="0" iyy="0" iyz="0" izz="0"/>
      <origin rpy="0 0 0" xyz="0 0 0"/>
    </inertial>
  </link>
  <joint name="ChestBoard/Button_sensor_fixedjoint" type="fixed">
    <parent link="torso"/>
    <child link="ChestButton_frame"/>
    <origin rpy="0 0 0" xyz="0.049871 0.001588 0.194163"/>
    <axis xyz="0 0 0"/>
  </joint>
  <link name="HeadTouchMiddle_frame">
    <inertial>
      <mass value="0"/>
      <inertia ixx="0" ixy="0" ixz="0" iyy="0" iyz="0" izz="0"/>
      <origin rpy="0 0 0" xyz="0 0 0"/>
    </inertial>
  </link>
  <joint name="Head/Touch/Middle_sensor_fixedjoint" type="fixed">
    <parent link="Head"/>
    <child link="HeadTouchMiddle_frame"/>
    <origin rpy="0 -0.0349066 0" xyz="0.0041 0 0.2159"/>
    <axis xyz="0 0 0"/>
  </joint>
  <link name="RFinger41_link">
    <inertial>
      <mass value="2e-03"/>
      <inertia ixx="1.1e-09" ixy="0" ixz="0" iyy="1.1e-09" iyz="0" izz="1.1e-09"/>
      <origin rpy="-1.57 0 0" xyz="0 0 0"/>
    </inertial>
    <visual>
      <geometry>
        <mesh filename="meshes/RFinger41.obj" scale="0.1 0.1 0.1"/>
      </geometry>
      <origin rpy="-1.57 0 0" xyz="0 0 0"/>
    </visual>
    <collision>
      <geometry>
        <mesh filename="meshes/RFinger41.dae" scale="0.1 0.1 0.1"/>
      </geometry>
      <origin rpy="-1.57 0 0" xyz="0 0 0"/>
    </collision>
  </link>
  <joint name="RFinger41" type="revolute">
    <parent link="r_wrist"/>
    <child link="RFinger41_link"/>
    <origin rpy="1.74402 1.04064 -0.0683394" xyz="0.074 -0.0309 0"/>
    <axis xyz="0 0 1.0"/>
    <mimic joint="RHand" multiplier="0.872665" offset="0"/>
    <limit effort="0.144" lower="0.0" upper="0.872665" velocity="12.56"/>
  </joint>
  <link name="LFinger42_link">
    <inertial>
      <mass value="2e-03"/>
      <inertia ixx="1.1e-09" ixy="0" ixz="0" iyy="1.1e-09" iyz="0" izz="1.1e-09"/>
      <origin rpy="-1.57 0 0" xyz="0 0 0"/>
    </inertial>
    <visual>
      <geometry>
        <mesh filename="meshes/LFinger42.obj" scale="0.1 0.1 0.1"/>
      </geometry>
      <origin rpy="-1.57 0 0" xyz="0 0 0"/>
    </visual>
    <collision>
      <geometry>
        <mesh filename="meshes/LFinger42.dae" scale="0.1 0.1 0.1"/>
      </geometry>
      <origin rpy="-1.57 0 0" xyz="0 0 0"/>
    </collision>
  </link>
  <joint name="LFinger42" type="revolute">
    <parent link="LFinger41_link"/>
    <child link="LFinger42_link"/>
    <origin rpy="0 0 -1.0472" xyz="0.018 0 0"/>
    <axis xyz="0 0 1.0"/>
    <mimic joint="LHand" multiplier="0.872665" offset="0"/>
    <limit effort="0.144" lower="0.0" upper="0.872665" velocity="12.56"/>
  </joint>
  <link name="RFinger12_link">
    <inertial>
      <mass value="2e-03"/>
      <inertia ixx="1.1e-09" ixy="0" ixz="0" iyy="1.1e-09" iyz="0" izz="1.1e-09"/>
      <origin rpy="-1.57 0 0" xyz="0 0 0"/>
    </inertial>
    <visual>
      <geometry>
        <mesh filename="meshes/RFinger12.obj" scale="0.1 0.1 0.1"/>
      </geometry>
      <origin rpy="-1.57 0 0" xyz="0 0 0"/>
    </visual>
    <collision>
      <geometry>
        <mesh filename="meshes/RFinger12.dae" scale="0.1 0.1 0.1"/>
      </geometry>
      <origin rpy="-1.57 0 0" xyz="0 0 0"/>
    </collision>
  </link>
  <joint name="RFinger12" type="revolute">
    <parent link="RFinger11_link"/>
    <child link="RFinger12_link"/>
    <origin rpy="0 0 -1.0472" xyz="0.018 0 0"/>
    <axis xyz="0 0 1.0"/>
    <mimic joint="RHand" multiplier="0.872665" offset="0"/>
    <limit effort="0.144" lower="0.0" upper="0.872665" velocity="12.56"/>
  </joint>
  <link name="LFinger33_link">
    <inertial>
      <mass value="2e-03"/>
      <inertia ixx="1.1e-09" ixy="0" ixz="0" iyy="1.1e-09" iyz="0" izz="1.1e-09"/>
      <origin rpy="-1.57 0 0" xyz="0 0 0"/>
    </inertial>
    <visual>
      <geometry>
        <mesh filename="meshes/LFinger33.obj" scale="0.1 0.1 0.1"/>
      </geometry>
      <origin rpy="-1.57 0 0" xyz="0 0 0"/>
    </visual>
    <collision>
      <geometry>
        <mesh filename="meshes/LFinger33.dae" scale="0.1 0.1 0.1"/>
      </geometry>
      <origin rpy="-1.57 0 0" xyz="0 0 0"/>
    </collision>
  </link>
  <joint name="LFinger33" type="revolute">
    <parent link="LFinger32_link"/>
    <child link="LFinger33_link"/>
    <origin rpy="0 0 -1.0472" xyz="0.018 0 0"/>
    <axis xyz="0 0 1.0"/>
    <mimic joint="LHand" multiplier="0.872665" offset="0"/>
    <limit effort="0.144" lower="0.0" upper="0.872665" velocity="12.56"/>
  </joint>
  <link name="RFinger31_link">
    <inertial>
      <mass value="2e-03"/>
      <inertia ixx="1.1e-09" ixy="0" ixz="0" iyy="1.1e-09" iyz="0" izz="1.1e-09"/>
      <origin rpy="-1.57 0 0" xyz="0 0 0"/>
    </inertial>
    <visual>
      <geometry>
        <mesh filename="meshes/RFinger31.obj" scale="0.1 0.1 0.1"/>
      </geometry>
      <origin rpy="-1.57 0 0" xyz="0 0 0"/>
    </visual>
    <collision>
      <geometry>
        <mesh filename="meshes/RFinger31.dae" scale="0.1 0.1 0.1"/>
      </geometry>
      <origin rpy="-1.57 0 0" xyz="0 0 0"/>
    </collision>
  </link>
  <joint name="RFinger31" type="revolute">
    <parent link="r_wrist"/>
    <child link="RFinger31_link"/>
    <origin rpy="1.67523 1.04483 0.029316" xyz="0.0833 -0.0123 0.004"/>
    <axis xyz="0 0 1.0"/>
    <mimic joint="RHand" multiplier="0.872665" offset="0"/>
    <limit effort="0.144" lower="0.0" upper="0.872665" velocity="12.56"/>
  </joint>
  <link name="LFinger21_link">
    <inertial>
      <mass value="2e-03"/>
      <inertia ixx="1.1e-09" ixy="0" ixz="0" iyy="1.1e-09" iyz="0" izz="1.1e-09"/>
      <origin rpy="-1.57 0 0" xyz="0 0 0"/>
    </inertial>
    <visual>
      <geometry>
        <mesh filename="meshes/LFinger21.obj" scale="0.1 0.1 0.1"/>
      </geometry>
      <origin rpy="-1.57 0 0" xyz="0 0 0"/>
    </visual>
    <collision>
      <geometry>
        <mesh filename="meshes/LFinger21.dae" scale="0.1 0.1 0.1"/>
      </geometry>
      <origin rpy="-1.57 0 0" xyz="0 0 0"/>
    </collision>
  </link>
  <joint name="LFinger21" type="revolute">
    <parent link="l_wrist"/>
    <child link="LFinger21_link"/>
    <origin rpy="1.5708 1.0472 -0.061086" xyz="0.0873 -0.0073 0.006"/>
    <axis xyz="0 0 1.0"/>
    <mimic joint="LHand" multiplier="0.872665" offset="0"/>
    <limit effort="0.144" lower="0.0" upper="0.872665" velocity="12.56"/>
  </joint>
  <link name="RFinger32_link">
    <inertial>
      <mass value="2e-03"/>
      <inertia ixx="1.1e-09" ixy="0" ixz="0" iyy="1.1e-09" iyz="0" izz="1.1e-09"/>
      <origin rpy="-1.57 0 0" xyz="0 0 0"/>
    </inertial>
    <visual>
      <geometry>
        <mesh filename="meshes/RFinger32.obj" scale="0.1 0.1 0.1"/>
      </geometry>
      <origin rpy="-1.57 0 0" xyz="0 0 0"/>
    </visual>
    <collision>
      <geometry>
        <mesh filename="meshes/RFinger32.dae" scale="0.1 0.1 0.1"/>
      </geometry>
      <origin rpy="-1.57 0 0" xyz="0 0 0"/>
    </collision>
  </link>
  <joint name="RFinger32" type="revolute">
    <parent link="RFinger31_link"/>
    <child link="RFinger32_link"/>
    <origin rpy="0 0 -1.0472" xyz="0.018 0 0"/>
    <axis xyz="0 0 1.0"/>
    <mimic joint="RHand" multiplier="0.872665" offset="0"/>
    <limit effort="0.144" lower="0.0" upper="0.872665" velocity="12.56"/>
  </joint>
  <link name="LFinger13_link">
    <inertial>
      <mass value="2e-03"/>
      <inertia ixx="1.1e-09" ixy="0" ixz="0" iyy="1.1e-09" iyz="0" izz="1.1e-09"/>
      <origin rpy="-1.57 0 0" xyz="0 0 0"/>
    </inertial>
    <visual>
      <geometry>
        <mesh filename="meshes/LFinger13.obj" scale="0.1 0.1 0.1"/>
      </geometry>
      <origin rpy="-1.57 0 0" xyz="0 0 0"/>
    </visual>
    <collision>
      <geometry>
        <mesh filename="meshes/LFinger13.dae" scale="0.1 0.1 0.1"/>
      </geometry>
      <origin rpy="-1.57 0 0" xyz="0 0 0"/>
    </collision>
  </link>
  <joint name="LFinger13" type="revolute">
    <parent link="LFinger12_link"/>
    <child link="LFinger13_link"/>
    <origin rpy="0 0 -1.0472" xyz="0.018 0 0"/>
    <axis xyz="0 0 1.0"/>
    <mimic joint="LHand" multiplier="0.872665" offset="0"/>
    <limit effort="0.144" lower="0.0" upper="0.872665" velocity="12.56"/>
  </joint>
  <link name="LFinger32_link">
    <inertial>
      <mass value="2e-03"/>
      <inertia ixx="1.1e-09" ixy="0" ixz="0" iyy="1.1e-09" iyz="0" izz="1.1e-09"/>
      <origin rpy="-1.57 0 0" xyz="0 0 0"/>
    </inertial>
    <visual>
      <geometry>
        <mesh filename="meshes/LFinger32.obj" scale="0.1 0.1 0.1"/>
      </geometry>
      <origin rpy="-1.57 0 0" xyz="0 0 0"/>
    </visual>
    <collision>
      <geometry>
        <mesh filename="meshes/LFinger32.dae" scale="0.1 0.1 0.1"/>
      </geometry>
      <origin rpy="-1.57 0 0" xyz="0 0 0"/>
    </collision>
  </link>
  <joint name="LFinger32" type="revolute">
    <parent link="LFinger31_link"/>
    <child link="LFinger32_link"/>
    <origin rpy="0 0 -1.0472" xyz="0.018 0 0"/>
    <axis xyz="0 0 1.0"/>
    <mimic joint="LHand" multiplier="0.872665" offset="0"/>
    <limit effort="0.144" lower="0.0" upper="0.872665" velocity="12.56"/>
  </joint>
  <link name="LFinger11_link">
    <inertial>
      <mass value="2e-03"/>
      <inertia ixx="1.1e-09" ixy="0" ixz="0" iyy="1.1e-09" iyz="0" izz="1.1e-09"/>
      <origin rpy="-1.57 0 0" xyz="0 0 0"/>
    </inertial>
    <visual>
      <geometry>
        <mesh filename="meshes/LFinger11.obj" scale="0.1 0.1 0.1"/>
      </geometry>
      <origin rpy="-1.57 0 0" xyz="0 0 0"/>
    </visual>
    <collision>
      <geometry>
        <mesh filename="meshes/LFinger11.dae" scale="0.1 0.1 0.1"/>
      </geometry>
      <origin rpy="-1.57 0 0" xyz="0 0 0"/>
    </collision>
  </link>
  <joint name="LFinger11" type="revolute">
    <parent link="l_wrist"/>
    <child link="LFinger11_link"/>
    <origin rpy="1.74402 1.04064 -0.0334335" xyz="0.0821 -0.0268 0.004"/>
    <axis xyz="0 0 1.0"/>
    <mimic joint="LHand" multiplier="0.872665" offset="0"/>
    <limit effort="0.144" lower="0.0" upper="0.872665" velocity="12.56"/>
  </joint>
  <link name="RFinger22_link">
    <inertial>
      <mass value="2e-03"/>
      <inertia ixx="1.1e-09" ixy="0" ixz="0" iyy="1.1e-09" iyz="0" izz="1.1e-09"/>
      <origin rpy="-1.57 0 0" xyz="0 0 0"/>
    </inertial>
    <visual>
      <geometry>
        <mesh filename="meshes/RFinger22.obj" scale="0.1 0.1 0.1"/>
      </geometry>
      <origin rpy="-1.57 0 0" xyz="0 0 0"/>
    </visual>
    <collision>
      <geometry>
        <mesh filename="meshes/RFinger22.dae" scale="0.1 0.1 0.1"/>
      </geometry>
      <origin rpy="-1.57 0 0" xyz="0 0 0"/>
    </collision>
  </link>
  <joint name="RFinger22" type="revolute">
    <parent link="RFinger21_link"/>
    <child link="RFinger22_link"/>
    <origin rpy="0 0 -1.0472" xyz="0.018 0 0"/>
    <axis xyz="0 0 1.0"/>
    <mimic joint="RHand" multiplier="0.872665" offset="0"/>
    <limit effort="0.144" lower="0.0" upper="0.872665" velocity="12.56"/>
  </joint>
  <link name="RFinger13_link">
    <inertial>
      <mass value="2e-03"/>
      <inertia ixx="1.1e-09" ixy="0" ixz="0" iyy="1.1e-09" iyz="0" izz="1.1e-09"/>
      <origin rpy="-1.57 0 0" xyz="0 0 0"/>
    </inertial>
    <visual>
      <geometry>
        <mesh filename="meshes/RFinger13.obj" scale="0.1 0.1 0.1"/>
      </geometry>
      <origin rpy="-1.57 0 0" xyz="0 0 0"/>
    </visual>
    <collision>
      <geometry>
        <mesh filename="meshes/RFinger13.dae" scale="0.1 0.1 0.1"/>
      </geometry>
      <origin rpy="-1.57 0 0" xyz="0 0 0"/>
    </collision>
  </link>
  <joint name="RFinger13" type="revolute">
    <parent link="RFinger12_link"/>
    <child link="RFinger13_link"/>
    <origin rpy="0 0 -1.0472" xyz="0.018 0 0"/>
    <axis xyz="0 0 1.0"/>
    <mimic joint="RHand" multiplier="0.872665" offset="0"/>
    <limit effort="0.144" lower="0.0" upper="0.872665" velocity="12.56"/>
  </joint>
  <link name="LFinger22_link">
    <inertial>
      <mass value="2e-03"/>
      <inertia ixx="1.1e-09" ixy="0" ixz="0" iyy="1.1e-09" iyz="0" izz="1.1e-09"/>
      <origin rpy="-1.57 0 0" xyz="0 0 0"/>
    </inertial>
    <visual>
      <geometry>
        <mesh filename="meshes/LFinger22.obj" scale="0.1 0.1 0.1"/>
      </geometry>
      <origin rpy="-1.57 0 0" xyz="0 0 0"/>
    </visual>
    <collision>
      <geometry>
        <mesh filename="meshes/LFinger22.dae" scale="0.1 0.1 0.1"/>
      </geometry>
      <origin rpy="-1.57 0 0" xyz="0 0 0"/>
    </collision>
  </link>
  <joint name="LFinger22" type="revolute">
    <parent link="LFinger21_link"/>
    <child link="LFinger22_link"/>
    <origin rpy="0 0 -1.0472" xyz="0.018 0 0"/>
    <axis xyz="0 0 1.0"/>
    <mimic joint="LHand" multiplier="0.872665" offset="0"/>
    <limit effort="0.144" lower="0.0" upper="0.872665" velocity="12.56"/>
  </joint>
  <link name="RFinger21_link">
    <inertial>
      <mass value="2e-03"/>
      <inertia ixx="1.1e-09" ixy="0" ixz="0" iyy="1.1e-09" iyz="0" izz="1.1e-09"/>
      <origin rpy="-1.57 0 0" xyz="0 0 0"/>
    </inertial>
    <visual>
      <geometry>
        <mesh filename="meshes/RFinger21.obj" scale="0.1 0.1 0.1"/>
      </geometry>
      <origin rpy="-1.57 0 0" xyz="0 0 0"/>
    </visual>
    <collision>
      <geometry>
        <mesh filename="meshes/RFinger21.dae" scale="0.1 0.1 0.1"/>
      </geometry>
      <origin rpy="-1.57 0 0" xyz="0 0 0"/>
    </collision>
  </link>
  <joint name="RFinger21" type="revolute">
    <parent link="r_wrist"/>
    <child link="RFinger21_link"/>
    <origin rpy="1.5708 1.0472 0.061086" xyz="0.0873 0.0073 0.006"/>
    <axis xyz="0 0 1.0"/>
    <mimic joint="RHand" multiplier="0.872665" offset="0"/>
    <limit effort="0.144" lower="0.0" upper="0.872665" velocity="12.56"/>
  </joint>
  <link name="LFinger41_link">
    <inertial>
      <mass value="2e-03"/>
      <inertia ixx="1.1e-09" ixy="0" ixz="0" iyy="1.1e-09" iyz="0" izz="1.1e-09"/>
      <origin rpy="-1.57 0 0" xyz="0 0 0"/>
    </inertial>
    <visual>
      <geometry>
        <mesh filename="meshes/LFinger41.obj" scale="0.1 0.1 0.1"/>
      </geometry>
      <origin rpy="-1.57 0 0" xyz="0 0 0"/>
    </visual>
    <collision>
      <geometry>
        <mesh filename="meshes/LFinger41.dae" scale="0.1 0.1 0.1"/>
      </geometry>
      <origin rpy="-1.57 0 0" xyz="0 0 0"/>
    </collision>
  </link>
  <joint name="LFinger41" type="revolute">
    <parent link="l_wrist"/>
    <child link="LFinger41_link"/>
    <origin rpy="1.39757 1.04064 0.0683394" xyz="0.074 0.0309 0"/>
    <axis xyz="0 0 1.0"/>
    <mimic joint="LHand" multiplier="0.872665" offset="0"/>
    <limit effort="0.144" lower="0.0" upper="0.872665" velocity="12.56"/>
  </joint>
  <link name="LFinger12_link">
    <inertial>
      <mass value="2e-03"/>
      <inertia ixx="1.1e-09" ixy="0" ixz="0" iyy="1.1e-09" iyz="0" izz="1.1e-09"/>
      <origin rpy="-1.57 0 0" xyz="0 0 0"/>
    </inertial>
    <visual>
      <geometry>
        <mesh filename="meshes/LFinger12.obj" scale="0.1 0.1 0.1"/>
      </geometry>
      <origin rpy="-1.57 0 0" xyz="0 0 0"/>
    </visual>
    <collision>
      <geometry>
        <mesh filename="meshes/LFinger12.dae" scale="0.1 0.1 0.1"/>
      </geometry>
      <origin rpy="-1.57 0 0" xyz="0 0 0"/>
    </collision>
  </link>
  <joint name="LFinger12" type="revolute">
    <parent link="LFinger11_link"/>
    <child link="LFinger12_link"/>
    <origin rpy="0 0 -1.0472" xyz="0.018 0 0"/>
    <axis xyz="0 0 1.0"/>
    <mimic joint="LHand" multiplier="0.872665" offset="0"/>
    <limit effort="0.144" lower="0.0" upper="0.872665" velocity="12.56"/>
  </joint>
  <link name="RFinger23_link">
    <inertial>
      <mass value="2e-03"/>
      <inertia ixx="1.1e-09" ixy="0" ixz="0" iyy="1.1e-09" iyz="0" izz="1.1e-09"/>
      <origin rpy="-1.57 0 0" xyz="0 0 0"/>
    </inertial>
    <visual>
      <geometry>
        <mesh filename="meshes/RFinger23.obj" scale="0.1 0.1 0.1"/>
      </geometry>
      <origin rpy="-1.57 0 0" xyz="0 0 0"/>
    </visual>
    <collision>
      <geometry>
        <mesh filename="meshes/RFinger23.dae" scale="0.1 0.1 0.1"/>
      </geometry>
      <origin rpy="-1.57 0 0" xyz="0 0 0"/>
    </collision>
  </link>
  <joint name="RFinger23" type="revolute">
    <parent link="RFinger22_link"/>
    <child link="RFinger23_link"/>
    <origin rpy="0 0 -1.0472" xyz="0.018 0 0"/>
    <axis xyz="0 0 1.0"/>
    <mimic joint="RHand" multiplier="0.872665" offset="0"/>
    <limit effort="0.144" lower="0.0" upper="0.872665" velocity="12.56"/>
  </joint>
  <link name="RFinger11_link">
    <inertial>
      <mass value="2e-03"/>
      <inertia ixx="1.1e-09" ixy="0" ixz="0" iyy="1.1e-09" iyz="0" izz="1.1e-09"/>
      <origin rpy="-1.57 0 0" xyz="0 0 0"/>
    </inertial>
    <visual>
      <geometry>
        <mesh filename="meshes/RFinger11.obj" scale="0.1 0.1 0.1"/>
      </geometry>
      <origin rpy="-1.57 0 0" xyz="0 0 0"/>
    </visual>
    <collision>
      <geometry>
        <mesh filename="meshes/RFinger11.dae" scale="0.1 0.1 0.1"/>
      </geometry>
      <origin rpy="-1.57 0 0" xyz="0 0 0"/>
    </collision>
  </link>
  <joint name="RFinger11" type="revolute">
    <parent link="r_wrist"/>
    <child link="RFinger11_link"/>
    <origin rpy="1.39757 1.04064 0.0334335" xyz="0.0821 0.0268 0.004"/>
    <axis xyz="0 0 1.0"/>
    <mimic joint="RHand" multiplier="0.872665" offset="0"/>
    <limit effort="0.144" lower="0.0" upper="0.872665" velocity="12.56"/>
  </joint>
  <link name="LFinger23_link">
    <inertial>
      <mass value="2e-03"/>
      <inertia ixx="1.1e-09" ixy="0" ixz="0" iyy="1.1e-09" iyz="0" izz="1.1e-09"/>
      <origin rpy="-1.57 0 0" xyz="0 0 0"/>
    </inertial>
    <visual>
      <geometry>
        <mesh filename="meshes/LFinger23.obj" scale="0.1 0.1 0.1"/>
      </geometry>
      <origin rpy="-1.57 0 0" xyz="0 0 0"/>
    </visual>
    <collision>
      <geometry>
        <mesh filename="meshes/LFinger23.dae" scale="0.1 0.1 0.1"/>
      </geometry>
      <origin rpy="-1.57 0 0" xyz="0 0 0"/>
    </collision>
  </link>
  <joint name="LFinger23" type="revolute">
    <parent link="LFinger22_link"/>
    <child link="LFinger23_link"/>
    <origin rpy="0 0 -1.0472" xyz="0.018 0 0"/>
    <axis xyz="0 0 1.0"/>
    <mimic joint="LHand" multiplier="0.872665" offset="0"/>
    <limit effort="0.144" lower="0.0" upper="0.872665" velocity="12.56"/>
  </joint>
  <link name="LFinger43_link">
    <inertial>
      <mass value="2e-03"/>
      <inertia ixx="1.1e-09" ixy="0" ixz="0" iyy="1.1e-09" iyz="0" izz="1.1e-09"/>
      <origin rpy="-1.57 0 0" xyz="0 0 0"/>
    </inertial>
    <visual>
      <geometry>
        <mesh filename="meshes/LFinger43.obj" scale="0.1 0.1 0.1"/>
      </geometry>
      <origin rpy="-1.57 0 0" xyz="0 0 0"/>
    </visual>
    <collision>
      <geometry>
        <mesh filename="meshes/LFinger43.dae" scale="0.1 0.1 0.1"/>
      </geometry>
      <origin rpy="-1.57 0 0" xyz="0 0 0"/>
    </collision>
  </link>
  <joint name="LFinger43" type="revolute">
    <parent link="LFinger42_link"/>
    <child link="LFinger43_link"/>
    <origin rpy="0 0 -1.0472" xyz="0.018 0 0"/>
    <axis xyz="0 0 1.0"/>
    <mimic joint="LHand" multiplier="0.872665" offset="0"/>
    <limit effort="0.144" lower="0.0" upper="0.872665" velocity="12.56"/>
  </joint>
  <link name="RFinger43_link">
    <inertial>
      <mass value="2e-03"/>
      <inertia ixx="1.1e-09" ixy="0" ixz="0" iyy="1.1e-09" iyz="0" izz="1.1e-09"/>
      <origin rpy="-1.57 0 0" xyz="0 0 0"/>
    </inertial>
    <visual>
      <geometry>
        <mesh filename="meshes/RFinger43.obj" scale="0.1 0.1 0.1"/>
      </geometry>
      <origin rpy="-1.57 0 0" xyz="0 0 0"/>
    </visual>
    <collision>
      <geometry>
        <mesh filename="meshes/RFinger43.dae" scale="0.1 0.1 0.1"/>
      </geometry>
      <origin rpy="-1.57 0 0" xyz="0 0 0"/>
    </collision>
  </link>
  <joint name="RFinger43" type="revolute">
    <parent link="RFinger42_link"/>
    <child link="RFinger43_link"/>
    <origin rpy="0 0 -1.0472" xyz="0.018 0 0"/>
    <axis xyz="0 0 1.0"/>
    <mimic joint="RHand" multiplier="0.872665" offset="0"/>
    <limit effort="0.144" lower="0.0" upper="0.872665" velocity="12.56"/>
  </joint>
  <link name="RFinger42_link">
    <inertial>
      <mass value="2e-03"/>
      <inertia ixx="1.1e-09" ixy="0" ixz="0" iyy="1.1e-09" iyz="0" izz="1.1e-09"/>
      <origin rpy="-1.57 0 0" xyz="0 0 0"/>
    </inertial>
    <visual>
      <geometry>
        <mesh filename="meshes/RFinger42.obj" scale="0.1 0.1 0.1"/>
      </geometry>
      <origin rpy="-1.57 0 0" xyz="0 0 0"/>
    </visual>
    <collision>
      <geometry>
        <mesh filename="meshes/RFinger42.dae" scale="0.1 0.1 0.1"/>
      </geometry>
      <origin rpy="-1.57 0 0" xyz="0 0 0"/>
    </collision>
  </link>
  <joint name="RFinger42" type="revolute">
    <parent link="RFinger41_link"/>
    <child link="RFinger42_link"/>
    <origin rpy="0 0 -1.0472" xyz="0.018 0 0"/>
    <axis xyz="0 0 1.0"/>
    <mimic joint="RHand" multiplier="0.872665" offset="0"/>
    <limit effort="0.144" lower="0.0" upper="0.872665" velocity="12.56"/>
  </joint>
  <link name="LFinger31_link">
    <inertial>
      <mass value="2e-03"/>
      <inertia ixx="1.1e-09" ixy="0" ixz="0" iyy="1.1e-09" iyz="0" izz="1.1e-09"/>
      <origin rpy="-1.57 0 0" xyz="0 0 0"/>
    </inertial>
    <visual>
      <geometry>
        <mesh filename="meshes/LFinger31.obj" scale="0.1 0.1 0.1"/>
      </geometry>
      <origin rpy="-1.57 0 0" xyz="0 0 0"/>
    </visual>
    <collision>
      <geometry>
        <mesh filename="meshes/LFinger31.dae" scale="0.1 0.1 0.1"/>
      </geometry>
      <origin rpy="-1.57 0 0" xyz="0 0 0"/>
    </collision>
  </link>
  <joint name="LFinger31" type="revolute">
    <parent link="l_wrist"/>
    <child link="LFinger31_link"/>
    <origin rpy="1.46636 1.04483 -0.029314" xyz="0.0833 0.0123 0.004"/>
    <axis xyz="0 0 1.0"/>
    <mimic joint="LHand" multiplier="0.872665" offset="0"/>
    <limit effort="0.144" lower="0.0" upper="0.872665" velocity="12.56"/>
  </joint>
  <link name="RFinger33_link">
    <inertial>
      <mass value="2e-03"/>
      <inertia ixx="1.1e-09" ixy="0" ixz="0" iyy="1.1e-09" iyz="0" izz="1.1e-09"/>
      <origin rpy="-1.57 0 0" xyz="0 0 0"/>
    </inertial>
    <visual>
      <geometry>
        <mesh filename="meshes/RFinger33.obj" scale="0.1 0.1 0.1"/>
      </geometry>
      <origin rpy="-1.57 0 0" xyz="0 0 0"/>
    </visual>
    <collision>
      <geometry>
        <mesh filename="meshes/RFinger33.dae" scale="0.1 0.1 0.1"/>
      </geometry>
      <origin rpy="-1.57 0 0" xyz="0 0 0"/>
    </collision>
  </link>
  <joint name="RFinger33" type="revolute">
    <parent link="RFinger32_link"/>
    <child link="RFinger33_link"/>
    <origin rpy="0 0 -1.0472" xyz="0.018 0 0"/>
    <axis xyz="0 0 1.0"/>
    <mimic joint="RHand" multiplier="0.872665" offset="0"/>
    <limit effort="0.144" lower="0.0" upper="0.872665" velocity="12.56"/>
  </joint>
  <link name="LThumb1_link">
    <inertial>
      <mass value="2e-03"/>
      <inertia ixx="1.1e-09" ixy="0" ixz="0" iyy="1.1e-09" iyz="0" izz="1.1e-09"/>
      <origin rpy="-1.57 0 0" xyz="0 0 0"/>
    </inertial>
    <visual>
      <geometry>
        <mesh filename="meshes/LThumb1.obj" scale="0.1 0.1 0.1"/>
      </geometry>
      <origin rpy="-1.57 0 0" xyz="0 0 0"/>
    </visual>
    <collision>
      <geometry>
        <mesh filename="meshes/LThumb1.dae" scale="0.1 0.1 0.1"/>
      </geometry>
      <origin rpy="-1.57 0 0" xyz="0 0 0"/>
    </collision>
  </link>
  <joint name="LThumb1" type="revolute">
    <parent link="l_wrist"/>
    <child link="LThumb1_link"/>
    <!-- <origin rpy="-1.95836 0.60626 0.533978" xyz="0.0482 -0.0357 -0.0199"/> -->
    <origin rpy="-2.55836 0.80626 0.533978" xyz="0.0482 -0.0357 -0.0199"/>
    <axis xyz="0 0 1.0"/>
    <mimic joint="LHand" multiplier="0.872665" offset="0"/>
    <limit effort="0.144" lower="0.0" upper="0.872665" velocity="12.56"/>
  </joint>
  <link name="RThumb2_link">
    <inertial>
      <mass value="2e-03"/>
      <inertia ixx="1.1e-09" ixy="0" ixz="0" iyy="1.1e-09" iyz="0" izz="1.1e-09"/>
      <origin rpy="-1.57 0 0" xyz="0 0 0"/>
    </inertial>
    <visual>
      <geometry>
        <mesh filename="meshes/RThumb2.obj" scale="0.1 0.1 0.1"/>
      </geometry>
      <origin rpy="-1.57 0 0" xyz="0 0 0"/>
    </visual>
    <collision>
      <geometry>
        <mesh filename="meshes/RThumb2.dae" scale="0.1 0.1 0.1"/>
      </geometry>
      <origin rpy="-1.57 0 0" xyz="0 0 0"/>
    </collision>
  </link>
  <joint name="RThumb2" type="revolute">
    <parent link="RThumb1_link"/>
    <child link="RThumb2_link"/>
    <origin rpy="0 0 -1.0472" xyz="0.022 0 0"/>
    <axis xyz="0 0 1.0"/>
    <mimic joint="RHand" multiplier="0.872665" offset="0"/>
    <limit effort="0.144" lower="0.0" upper="0.872665" velocity="12.56"/>
  </joint>
  <link name="RThumb1_link">
    <inertial>
      <mass value="2e-03"/>
      <inertia ixx="1.1e-09" ixy="0" ixz="0" iyy="1.1e-09" iyz="0" izz="1.1e-09"/>
      <origin rpy="-1.57 0 0" xyz="0 0 0"/>
    </inertial>
    <visual>
      <geometry>
        <mesh filename="meshes/RThumb1.obj" scale="0.1 0.1 0.1"/>
      </geometry>
      <origin rpy="-1.57 0 0" xyz="0 0 0"/>
    </visual>
    <collision>
      <geometry>
        <mesh filename="meshes/RThumb1.dae" scale="0.1 0.1 0.1"/>
      </geometry>
      <origin rpy="-1.57 0 0" xyz="0 0 0"/>
    </collision>
  </link>
  <joint name="RThumb1" type="revolute">
    <parent link="r_wrist"/>
    <child link="RThumb1_link"/>
    <!-- <origin rpy="-1.18323 0.60626 -0.533978" xyz="0.0482 0.0357 -0.0199"/> -->
    <origin rpy="-0.58323 0.80626 -0.533978" xyz="0.0482 0.0357 -0.0199"/>
    <axis xyz="0 0 1.0"/>
    <mimic joint="RHand" multiplier="0.872665" offset="0"/>
    <limit effort="0.144" lower="0.0" upper="0.872665" velocity="12.56"/>
  </joint>
  <link name="LThumb2_link">
    <inertial>
      <mass value="2e-03"/>
      <inertia ixx="1.1e-09" ixy="0" ixz="0" iyy="1.1e-09" iyz="0" izz="1.1e-09"/>
      <origin rpy="-1.57 0 0" xyz="0 0 0"/>
    </inertial>
    <visual>
      <geometry>
        <mesh filename="meshes/LThumb2.obj" scale="0.1 0.1 0.1"/>
      </geometry>
      <origin rpy="-1.57 0 0" xyz="0 0 0"/>
    </visual>
    <collision>
      <geometry>
        <mesh filename="meshes/LThumb2.dae" scale="0.1 0.1 0.1"/>
      </geometry>
      <origin rpy="-1.57 0 0" xyz="0 0 0"/>
    </collision>
  </link>
  <joint name="LThumb2" type="revolute">
    <parent link="LThumb1_link"/>
    <child link="LThumb2_link"/>
    <origin rpy="0 0 -1.0472" xyz="0.022 0 0"/>
    <axis xyz="0 0 1.0"/>
    <mimic joint="LHand" multiplier="0.872665" offset="0"/>
    <limit effort="0.144" lower="0.0" upper="0.872665" velocity="12.56"/>
  </joint>
  <link name="WheelFL_link">
    <inertial>
      <mass value="1.58028"/>
      <inertia ixx="0.00299756" ixy="6.3068e-07" ixz="5.56903e-06" iyy="0.00303229" iyz="-9.0408e-07" izz="0.00296585"/>
      <origin rpy="0 0 0" xyz="0 0 0"/>
    </inertial>
    <visual>
      <geometry>
        <mesh filename="meshes/WheelFL.obj" scale="0.1 0.1 0.1"/>
      </geometry>
      <origin rpy="0 0 0" xyz="0 0 0"/>
    </visual>
    <collision>
      <geometry>
        <mesh filename="meshes/WheelFL_0.10.stl" scale="0.1 0.1 0.1"/>
      </geometry>
      <origin rpy="0 0 0" xyz="0 0 0"/>
    </collision>
  </link>
  <joint name="WheelFL" type="continuous">
    <parent link="Tibia"/>
    <child link="WheelFL_link"/>
    <origin rpy="0 0 1.07517" xyz="0.09 0.155 -0.264"/>
    <axis xyz="1.0 0.0 0.0"/>
    <limit effort="3.25" lower="0" upper="0" velocity="6.28319"/>
  </joint>
  <link name="WheelB_link">
    <inertial>
      <mass value="1.58028"/>
      <inertia ixx="0.00299756" ixy="6.3068e-07" ixz="5.56903e-06" iyy="0.00303229" iyz="-9.0408e-07" izz="0.00296585"/>
      <origin rpy="0 0 0" xyz="0 0 0"/>
    </inertial>
    <visual>
      <geometry>
        <mesh filename="meshes/WheelB.obj" scale="0.1 0.1 0.1"/>
      </geometry>
      <origin rpy="0 0 0" xyz="0 0 0"/>
    </visual>
    <collision>
      <geometry>
        <mesh filename="meshes/WheelB_0.10.stl" scale="0.1 0.1 0.1"/>
      </geometry>
      <origin rpy="0 0 0" xyz="0 0 0"/>
    </collision>
  </link>
  <joint name="WheelB" type="continuous">
    <parent link="Tibia"/>
    <child link="WheelB_link"/>
    <origin rpy="0 0 -3.14159" xyz="-0.17 0 -0.264"/>
    <axis xyz="1.0 0 0"/>
    <limit effort="3.25" lower="0" upper="0" velocity="6.28319"/>
  </joint>
  <link name="WheelFR_link">
    <inertial>
      <mass value="1.58028"/>
      <inertia ixx="0.00299756" ixy="6.3068e-07" ixz="5.56903e-06" iyy="0.00303229" iyz="-9.0408e-07" izz="0.00296585"/>
      <origin rpy="0 0 0" xyz="0 0 0"/>
    </inertial>
    <visual>
      <geometry>
        <mesh filename="meshes/WheelFR.obj" scale="0.1 0.1 0.1"/>
      </geometry>
      <origin rpy="0 0 0" xyz="0 0 0"/>
    </visual>
    <collision>
      <geometry>
        <mesh filename="meshes/WheelFR_0.10.stl" scale="0.1 0.1 0.1"/>
      </geometry>
      <origin rpy="0 0 0" xyz="0 0 0"/>
    </collision>
  </link>
  <joint name="WheelFR" type="continuous">
    <parent link="Tibia"/>
    <child link="WheelFR_link"/>
    <origin rpy="0 0 -1.07517" xyz="0.09 -0.155 -0.264"/>
    <axis xyz="1.0 0.0 0.0"/>
    <limit effort="3.25" lower="0" upper="0" velocity="6.28319"/>
  </joint>

  <!-- HEAD -->
  <transmission name="HeadYaw_Transmission">
    <type>transmission_interface/SimpleTransmission</type>
    <joint name="HeadYaw">
      <hardwareInterface>hardware_interface/PositionJointInterface</hardwareInterface>
    </joint>
    <actuator name="HeadYaw_Motor">
      <!-- Dummy Values -->
      <hardwareInterface>PositionJointInterface</hardwareInterface>
      <mechanicalReduction>101.3</mechanicalReduction>
    </actuator>
  </transmission>
  <transmission name="HeadPitch_Transmission">
    <type>transmission_interface/SimpleTransmission</type>
    <joint name="HeadPitch">
      <hardwareInterface>hardware_interface/PositionJointInterface</hardwareInterface>
    </joint>
    <actuator name="HeadPitch_Motor">
      <!-- Dummy Values -->
      <hardwareInterface>PositionJointInterface</hardwareInterface>
      <mechanicalReduction>118.1</mechanicalReduction>
    </actuator>
  </transmission>
  <transmission name="LShoulderPitch_Transmission">
    <type>transmission_interface/SimpleTransmission</type>
    <joint name="LShoulderPitch">
      <hardwareInterface>hardware_interface/PositionJointInterface</hardwareInterface>
    </joint>
    <actuator name="LShoulderPitch_Motor">
      <hardwareInterface>PositionJointInterface</hardwareInterface>
      <mechanicalReduction>101.3</mechanicalReduction>
    </actuator>
  </transmission>
  <transmission name="LShoulderRoll_Transmission">
    <type>transmission_interface/SimpleTransmission</type>
    <joint name="LShoulderRoll">
      <hardwareInterface>hardware_interface/PositionJointInterface</hardwareInterface>
    </joint>
    <actuator name="LShoulderRoll_Motor">
      <hardwareInterface>PositionJointInterface</hardwareInterface>
      <mechanicalReduction>118.1</mechanicalReduction>
    </actuator>
  </transmission>
  <transmission name="LElbowYaw_Transmission">
    <type>transmission_interface/SimpleTransmission</type>
    <joint name="LElbowYaw">
      <hardwareInterface>hardware_interface/PositionJointInterface</hardwareInterface>
    </joint>
    <actuator name="LElbowYaw_Motor">
      <hardwareInterface>PositionJointInterface</hardwareInterface>
      <mechanicalReduction>101.3</mechanicalReduction>
    </actuator>
  </transmission>
  <transmission name="LElbowRoll_Transmission">
    <type>transmission_interface/SimpleTransmission</type>
    <joint name="LElbowRoll">
      <hardwareInterface>hardware_interface/PositionJointInterface</hardwareInterface>
    </joint>
    <actuator name="LElbowRoll_Motor">
      <hardwareInterface>PositionJointInterface</hardwareInterface>
      <mechanicalReduction>118.1</mechanicalReduction>
    </actuator>
  </transmission>
  <transmission name="LWristYaw_Transmission">
    <type>transmission_interface/SimpleTransmission</type>
    <joint name="LWristYaw">
      <hardwareInterface>hardware_interface/PositionJointInterface</hardwareInterface>
    </joint>
    <actuator name="LWristYaw_Motor">
      <hardwareInterface>PositionJointInterface</hardwareInterface>
      <mechanicalReduction>118.1</mechanicalReduction>
    </actuator>
  </transmission>
  <transmission name="LHand_Transmission">
    <type>transmission_interface/SimpleTransmission</type>
    <joint name="LHand">
      <hardwareInterface>hardware_interface/PositionJointInterface</hardwareInterface>
    </joint>
    <actuator name="LHand_Motor">
      <hardwareInterface>PositionJointInterface</hardwareInterface>
      <mechanicalReduction>36.24</mechanicalReduction>
    </actuator>
  </transmission>
  <transmission name="RShoulderPitch_Transmission">
    <type>transmission_interface/SimpleTransmission</type>
    <joint name="RShoulderPitch">
      <hardwareInterface>hardware_interface/PositionJointInterface</hardwareInterface>
    </joint>
    <actuator name="RShoulderPitch_Motor">
      <hardwareInterface>PositionJointInterface</hardwareInterface>
      <mechanicalReduction>101.3</mechanicalReduction>
    </actuator>
  </transmission>
  <transmission name="RShoulderRoll_Transmission">
    <type>transmission_interface/SimpleTransmission</type>
    <joint name="RShoulderRoll">
      <hardwareInterface>hardware_interface/PositionJointInterface</hardwareInterface>
    </joint>
    <actuator name="RShoulderRoll_Motor">
      <hardwareInterface>PositionJointInterface</hardwareInterface>
      <mechanicalReduction>118.1</mechanicalReduction>
    </actuator>
  </transmission>
  <transmission name="RElbowYaw_Transmission">
    <type>transmission_interface/SimpleTransmission</type>
    <joint name="RElbowYaw">
      <hardwareInterface>hardware_interface/PositionJointInterface</hardwareInterface>
    </joint>
    <actuator name="RElbowYaw_Motor">
      <hardwareInterface>PositionJointInterface</hardwareInterface>
      <mechanicalReduction>101.3</mechanicalReduction>
    </actuator>
  </transmission>
  <transmission name="RElbowRoll_Transmission">
    <type>transmission_interface/SimpleTransmission</type>
    <joint name="RElbowRoll">
      <hardwareInterface>hardware_interface/PositionJointInterface</hardwareInterface>
    </joint>
    <actuator name="RElbowRoll_Motor">
      <hardwareInterface>PositionJointInterface</hardwareInterface>
      <mechanicalReduction>118.1</mechanicalReduction>
    </actuator>
  </transmission>
  <transmission name="RWristYaw_Transmission">
    <type>transmission_interface/SimpleTransmission</type>
    <joint name="RWristYaw">
      <hardwareInterface>hardware_interface/PositionJointInterface</hardwareInterface>
    </joint>
    <actuator name="RWristYaw_Motor">
      <hardwareInterface>PositionJointInterface</hardwareInterface>
      <mechanicalReduction>118.1</mechanicalReduction>
    </actuator>
  </transmission>
  <transmission name="RHand_Transmission">
    <type>transmission_interface/SimpleTransmission</type>
    <joint name="RHand">
      <hardwareInterface>hardware_interface/PositionJointInterface</hardwareInterface>
    </joint>
    <actuator name="RHand_Motor">
      <hardwareInterface>PositionJointInterface</hardwareInterface>
      <mechanicalReduction>36.24</mechanicalReduction>
    </actuator>
  </transmission>
  <!-- LEGS -->
  <transmission name="HipRoll_Transmission">
    <type>transmission_interface/SimpleTransmission</type>
    <joint name="HipRoll">
      <hardwareInterface>hardware_interface/PositionJointInterface</hardwareInterface>
    </joint>
    <actuator name="HipRoll_Motor">
      <!-- Dummy Values -->
      <hardwareInterface>PositionJointInterface</hardwareInterface>
      <mechanicalReduction>108.33</mechanicalReduction>
    </actuator>
  </transmission>
  <transmission name="HipPitch_Transmission">
    <type>transmission_interface/SimpleTransmission</type>
    <joint name="HipPitch">
      <hardwareInterface>hardware_interface/PositionJointInterface</hardwareInterface>
    </joint>
    <actuator name="HipPitch_Motor">
      <!-- Dummy Values -->
      <hardwareInterface>PositionJointInterface</hardwareInterface>
      <mechanicalReduction>108.33</mechanicalReduction>
    </actuator>
  </transmission>
  <transmission name="KneePitch_Transmission">
    <type>transmission_interface/SimpleTransmission</type>
    <joint name="KneePitch">
      <hardwareInterface>hardware_interface/PositionJointInterface</hardwareInterface>
    </joint>
    <actuator name="KneePitch_Motor">
      <!-- Dummy Values -->
      <hardwareInterface>PositionJointInterface</hardwareInterface>
      <mechanicalReduction>108.33</mechanicalReduction>
    </actuator>
  </transmission>
  <transmission name="WheelFL_Transmission">
    <type>transmission_interface/SimpleTransmission</type>
    <joint name="WheelFL">
      <hardwareInterface>hardware_interface/EffortJointInterface</hardwareInterface>
    </joint>
    <actuator name="WheelFL_Motor">
      <!-- Dummy Values -->
      <hardwareInterface>EffortJointInterface</hardwareInterface>
      <mechanicalReduction>25.0</mechanicalReduction>
    </actuator>
  </transmission>
  <transmission name="WheelB_Transmission">
    <type>transmission_interface/SimpleTransmission</type>
    <joint name="WheelB">
      <hardwareInterface>hardware_interface/EffortJointInterface</hardwareInterface>
    </joint>
    <actuator name="WheelB_Motor">
      <!-- Dummy Values -->
      <hardwareInterface>EffortJointInterface</hardwareInterface>
      <mechanicalReduction>25.0</mechanicalReduction>
    </actuator>
  </transmission>
  <transmission name="WheelFR_Transmission">
    <type>transmission_interface/SimpleTransmission</type>
    <joint name="WheelFR">
      <hardwareInterface>hardware_interface/EffortJointInterface</hardwareInterface>
    </joint>
    <actuator name="WheelFR_Motor">
      <!-- Dummy Values -->
      <hardwareInterface>EffortJointInterface</hardwareInterface>
      <mechanicalReduction>25.0</mechanicalReduction>
    </actuator>
  </transmission>
</robot>
